Workbook

Sheet 0102
A1: 품번 | B1: 01/02(금) | C1: 01/03(토) | D1: 01/04(일) | E1: 01/05(월) | F1: 01/06(화) | G1: 01/07(수) | H1: 01/08(목) | I1: 01/09(금) | J1: 01/10(토) | K1: 01/11(일) | L1: 01/12(월) | M1: 01/13(화) | N1: 01/14(수) | O1: 01/15(목) | P1: 01/16(금) | Q1: 01/17(토) | R1: 01/18(일)
A2: 1221154 | B2: 0 | C2: 0 | D2: 0 | E2: 0 | F2: 0 | G2: 0 | H2: 0 | I2: 0 | J2: 0 | K2: 0 | L2: 0 | M2: 0 | N2: 50 | O2: 0 | P2: 0 | Q2: 0 | R2: 0
A3: 1234614 | B3: 182 | C3: 0 | D3: 0 | E3: 396 | F3: 0 | G3: 0 | H3: 0 | I3: 0 | J3: 0 | K3: 0 | L3: 0 | M3: 0 | N3: 352 | O3: 50 | P3: 0 | Q3: 0 | R3: 0
A4: 1226384 | B4: 0 | C4: 0 | D4: 0 | E4: 0 | F4: 0 | G4: 0 | H4: 0 | I4: 0 | J4: 0 | K4: 0 | L4: 360 | M4: 100 | N4: 400 | O4: 0 | P4: 0 | Q4: 0 | R4: 0
A5: 1226388 | B5: 0 | C5: 0 | D5: 0 | E5: 0 | F5: 0 | G5: 0 | H5: 0 | I5: 0 | J5: 0 | K5: 0 | L5: 360 | M5: 100 | N5: 400 | O5: 0 | P5: 0 | Q5: 0 | R5: 0
A6: 1229673 | B6: 374 | C6: 0 | D6: 0 | E6: 200 | F6: 200 | G6: 200 | H6: 200 | I6: 242 | J6: 0 | K6: 0 | L6: 250 | M6: 250 | N6: 250 | O6: 250 | P6: 200 | Q6: 0 | R6: 0
A7: 1230854 | B7: 0 | C7: 0 | D7: 0 | E7: 0 | F7: 0 | G7: 0 | H7: 0 | I7: 0 | J7: 0 | K7: 0 | L7: 200 | M7: 0 | N7: 0 | O7: 0 | P7: 0 | Q7: 0 | R7: 0
A8: 1233632 | B8: 0 | C8: 0 | D8: 0 | E8: 0 | F8: 0 | G8: 0 | H8: 346 | I8: 330 | J8: 0 | K8: 0 | L8: 406 | M8: 0 | N8: 0 | O8: 0 | P8: 0 | Q8: 0 | R8: 0
A9: 1232693 | B9: 342 | C9: 0 | D9: 0 | E9: 141 | F9: 0 | G9: 0 | H9: 0 | I9: 0 | J9: 0 | K9: 0 | L9: 0 | M9: 0 | N9: 0 | O9: 0 | P9: 0 | Q9: 0 | R9: 0
A10: 1233025 | B10: 342 | C10: 0 | D10: 0 | E10: 141 | F10: 0 | G10: 0 | H10: 0 | I10: 0 | J10: 0 | K10: 0 | L10: 0 | M10: 0 | N10: 0 | O10: 0 | P10: 0 | Q10: 0 | R10: 0
A11: 1237088 | B11: 278 | C11: 0 | D11: 0 | E11: 764 | F11: 1022 | G11: 694 | H11: 1286 | I11: 1570 | J11: 0 | K11: 0 | L11: 1276 | M11: 906 | N11: 1006 | O11: 942 | P11: 1496 | Q11: 0 | R11: 0
A12: 1237748 | B12: 0 | C12: 0 | D12: 0 | E12: 0 | F12: 0 | G12: 0 | H12: 260 | I12: 0 | J12: 0 | K12: 0 | L12: 0 | M12: 0 | N12: 0 | O12: 0 | P12: 0 | Q12: 0 | R12: 0
A13: 1231898 | B13: 0 | C13: 0 | D13: 0 | E13: 0 | F13: 500 | G13: 0 | H13: 0 | I13: 0 | J13: 0 | K13: 0 | L13: 0 | M13: 0 | N13: 0 | O13: 0 | P13: 0 | Q13: 0 | R13: 0
... A24: 1240308 | B24: 0 | C24: 0 | D24: 0 | E24: 250 | F24: 0 | G24: 500 | H24: 250 | I24: 0 | J24: 0 | K24: 0 | L24: 0 | M24: 200 | N24: 0 | O24: 350 | P24: 200 | Q24: 0 | R24: 0
A28: 품번 | B28: 01/02(금) | C28: 01/03(토) | D28: 01/04(일) | E28: 01/05(월) | F28: 01/06(화) | G28: 01/07(수) | H28: 01/08(목) | I28: 01/09(금) | J28: 01/10(토) | K28: 01/11(일) | L28: 01/12(월) | M28: 01/13(화) | N28: 01/14(수) | O28: 01/15(목) | P28: 01/16(금) | Q28: 01/17(토) | R28: 01/18(일)
A29: 1237608 | B29: 0 | C29: 0 | D29: 0 | E29: 0 | F29: 0 | G29: 0 | H29: 0 | I29: 0 | J29: 0 | K29: 0 | L29: 0 | M29: 350 | N29: 250 | O29: 0 | P29: 0 | Q29: 0 | R29: 0
A30: 1232846 | B30: 0 | C30: 0 | D30: 0 | E30: 0 | F30: 0 | G30: 0 | H30: 0 | I30: 0 | J30: 0 | K30: 0 | L30: 0 | M30: 327 | N30: 352 | O30: 21 | P30: 0 | Q30: 0 | R30: 0
A31: 1232895 | B31: 0 | C31: 0 | D31: 0 | E31: 0 | F31: 0 | G31: 0 | H31: 0 | I31: 0 | J31: 0 | K31: 0 | L31: 0 | M31: 327 | N31: 352 | O31: 21 | P31: 0 | Q31: 0 | R31: 0
A32: 1233384 | B32: 0 | C32: 0 | D32: 0 | E32: 0 | F32: 0 | G32: 0 | H32: 0 | I32: 0 | J32: 0 | K32: 0 | L32: 0 | M32: 327 | N32: 352 | O32: 21 | P32: 0 | Q32: 0 | R32: 0
A33: 1236110 | B33: 150 | C33: 0 | D33: 0 | E33: 0 | F33: 0 | G33: 0 | H33: 0 | I33: 0 | J33: 0 | K33: 0 | L33: 0 | M33: 0 | N33: 0 | O33: 300 | P33: 0 | Q33: 0 | R33: 0
A34: 1236387 | B34: 0 | C34: 0 | D34: 0 | E34: 0 | F34: 0 | G34: 265 | H34: 395 | I34: 0 | J34: 0 | K34: 0 | L34: 0 | M34: 0 | N34: 0 | O34: 0 | P34: 0 | Q34: 0 | R34: 0
A35: 1232775 | B35: 226 | C35: 0 | D35: 0 | E35: 575 | F35: 616 | G35: 277 | H35: 311 | I35: 14 | J35: 0 | K35: 0 | L35: 0 | M35: 288 | N35: 243 | O35: 309 | P35: 309 | Q35: 0 | R35: 0
A36: 1238605 | B36: 0 | C36: 0 | D36: 0 | E36: 0 | F36: 0 | G36: 0 | H36: 0 | I36: 189 | J36: 0 | K36: 0 | L36: 238 | M36: 6 | N36: 0 | O36: 0 | P36: 0 | Q36: 0 | R36: 0
A40: 품번 | B40: 01/02(금) | C40: 01/03(토) | D40: 01/04(일) | E40: 01/05(월) | F40: 01/06(화) | G40: 01/07(수) | H40: 01/08(목) | I40: 01/09(금) | J40: 01/10(토) | K40: 01/11(일) | L40: 01/12(월) | M40: 01/13(화) | N40: 01/14(수) | O40: 01/15(목) | P40: 01/16(금) | Q40: 01/17(토) | R40: 01/18(일)
A41: 1221967 | B41: 0 | C41: 0 | D41: 0 | E41: 0 | F41: 0 | G41: 0 | H41: 0 | I41: 0 | J41: 0 | K41: 0 | L41: 0 | M41: 0 | N41: 176 | O41: 0 | P41: 0 | Q41: 0 | R41: 0
A42: 1227306 | B42: 0 | C42: 0 | D42: 0 | E42: 452 | F42: 45 | G42: 277 | H42: 123 | I42: 0 | J42: 0 | K42: 0 | L42: 0 | M42: 510 | N42: 400 | O42: 0 | P42: 0 | Q42: 0 | R42: 0
A43: 1227359 | B43: 0 | C43: 0 | D43: 0 | E43: 0 | F43: 0 | G43: 0 | H43: 86 | I43: 0 | J43: 0 | K43: 0 | L43: 0 | M43: 0 | N43: 0 | O43: 0 | P43: 0 | Q43: 0 | R43: 0
A44: 1229088 | B44: 0 | C44: 0 | D44: 0 | E44: 0 | F44: 0 | G44: 0 | H44: 0 | I44: 0 | J44: 0 | K44: 0 | L44: 0 | M44: 0 | N44: 500 | O44: 0 | P44: 0 | Q44: 0 | R44: 0
A45: 1231090 | B45: 0 | C45: 0 | D45: 0 | E45: 0 | F45: 0 | G45: 0 | H45: 0 | I45: 0 | J45: 0 | K45: 0 | L45: 0 | M45: 0 | N45: 0 | O45: 0 | P45: 200 | Q45: 0 | R45: 0
A46: 1229776 | B46: 0 | C46: 0 | D46: 0 | E46: 0 | F46: 0 | G46: 0 | H46: 0 | I46: 0 | J46: 0 | K46: 0 | L46: 0 | M46: 0 | N46: 0 | O46: 0 | P46: 200 | Q46: 0 | R46: 0
A47: 1231797 | B47: 0 | C47: 0 | D47: 0 | E47: 0 | F47: 0 | G47: 0 | H47: 0 | I47: 0 | J47: 0 | K47: 0 | L47: 0 | M47: 0 | N47: 113 | O47: 0 | P47: 0 | Q47: 0 | R47: 0
A48: 1232528 | B48: 0 | C48: 0 | D48: 0 | E48: 0 | F48: 0 | G48: 0 | H48: 0 | I48: 0 | J48: 0 | K48: 0 | L48: 163 | M48: 686 | N48: 539 | O48: 649 | P48: 0 | Q48: 0 | R48: 0
A49: 1233587 | B49: 0 | C49: 0 | D49: 0 | E49: 0 | F49: 0 | G49: 0 | H49: 0 | I49: 0 | J49: 0 | K49: 0 | L49: 0 | M49: 0 | N49: 10 | O49: 0 | P49: 0 | Q49: 0 | R49: 0
A50: 1232846 | B50: 0 | C50: 0 | D50: 0 | E50: 0 | F50: 0 | G50: 0 | H50: 0 | I50: 0 | J50: 0 | K50: 0 | L50: 0 | M50: 0 | N50: 176 | O50: 0 | P50: 0 | Q50: 0 | R50: 0
A51: 1232693 | B51: 0 | C51: 0 | D51: 0 | E51: 0 | F51: 0 | G51: 0 | H51: 0 | I51: 0 | J51: 0 | K51: 0 | L51: 54 | M51: 0 | N51: 0 | O51: 0 | P51: 0 | Q51: 0 | R51: 0
A52: 1233025 | B52: 0 | C52: 0 | D52: 0 | E52: 0 | F52: 0 | G52: 0 | H52: 0 | I52: 0 | J52: 0 | K52: 0 | L52: 54 | M52: 0 | N52: 0 | O52: 0 | P52: 0 | Q52: 0 | R52: 0
... A54: 1235958 | B54: 0 | C54: 0 | D54: 0 | E54: 0 | F54: 0 | G54: 0 | H54: 12 | I54: 0 | J54: 0 | K54: 0 | L54: 0 | M54: 0 | N54: 0 | O54: 0 | P54: 0 | Q54: 0 | R54: 0
A55: 1235845 | B55: 0 | C55: 0 | D55: 0 | E55: 0 | F55: 0 | G55: 461 | I55: 0 | J55: 0 | K55: 0 | L55: 0 | M55: 0 | N55: 0 | O55: 0 | P55: 0 | Q55: 0 | R55: 0
A56: 1236600 | B56: 0 | C56: 0 | D56: 0 | E56: 0 | F56: 0 | G56: 0 | H56: 30 | I56: 419 | J56: 0 | K56: 0 | L56: 299 | M56: 0 | N56: 0 | O56: 0 | P56: 0 | Q56: 0 | R56: 0
A57: 1236601 | B57: 0 | C57: 0 | D57: 0 | E57: 0 | F57: 0 | G57: 0 | H57: 0 | I57: 0 | J57: 0 | K57: 0 | L57: 74 | M57: 0 | N57: 0 | O57: 0 | P57: 0 | Q57: 0 | R57: 0
...

Sheet 0105
A1: 품번 | B1: 01/05(월) | C1: 01/06(화) | D1: 01/07(수) | E1: 01/08(목) | F1: 01/09(금) | G1: 01/10(토) | H1: 01/11(일) | I1: 01/12(월) | J1: 01/13(화) | K1: 01/14(수) | L1: 01/15(목) | M1: 01/16(금) | N1: 01/17(토) | O1: 01/18(일)
A2: 1221154 | B2: 0 | C2: 0 | D2: 0 | E2: 0 | F2: 0 | G2: 0 | H2: 0 | I2: 0 | J2: 0 | K2: 50 | L2: 0 | M2: 0 | N2: 0 | O2: 0
A3: 1234614 | B3: 396 | C3: 0 | D3: 0 | E3: 0 | F3: 0 | G3: 0 | H3: 0 | I3: 0 | J3: 0 | K3: 352 | L3: 50 | M3: 0 | N3: 0 | O3: 0
A4: 1226384 | B4: 0 | C4: 0 | D4: 0 | E4: 0 | F4: 0 | G4: 0 | H4: 0 | I4: 360 | J4: 100 | K4: 400 | L4: 0 | M4: 0 | N4: 0 | O4: 0
A5: 1226388 | B5: 0 | C5: 0 | D5: 0 | E5: 0 | F5: 0 | G5: 0 | H5: 0 | I5: 360 | J5: 100 | K5: 400 | L5: 0 | M5: 0 | N5: 0 | O5: 0
A6: 1229673 | B6: 200 | C6: 200 | D6: 200 | E6: 200 | F6: 242 | G6: 0 | H6: 0 | I6: 250 | J6: 250 | K6: 250 | L6: 250 | M6: 200 | N6: 0 | O6: 0
A7: 1230854 | B7: 0 | C7: 0 | D7: 0 | E7: 0 | F7: 0 | G7: 0 | H7: 0 | I7: 200 | J7: 0 | K7: 0 | L7: 0 | M7: 0 | N7: 0 | O7: 0
A8: 1233632 | B8: 0 | C8: 0 | D8: 0 | E8: 346 | F8: 330 | G8: 0 | H8: 0 | I8: 406 | J8: 0 | K8: 0 | L8: 0 | M8: 0 | N8: 0 | O8: 0
A9: 1232693 | B9: 141 | C9: 0 | D9: 0 | E9: 0 | F9: 0 | G9: 0 | H9: 0 | I9: 0 | J9: 0 | K9: 0 | L9: 0 | M9: 0 | N9: 0 | O9: 0
A10: 1233025 | B10: 141 | C10: 0 | D10: 0 | E10: 0 | F10: 0 | G10: 0 | H10: 0 | I10: 0 | J10: 0 | K10: 0 | L10: 0 | M10: 0 | N10: 0 | O10: 0
A11: 1237088 | B11: 764 | C11: 1022 | D11: 694 | E11: 1286 | F11: 1570 | G11: 0 | H11: 0 | I11: 1276 | J11: 906 | K11: 1006 | L11: 942 | M11: 1496 | N11: 0 | O11: 0
A12: 1237748 | B12: 0 | C12: 0 | D12: 0 | E12: 260 | F12: 0 | G12: 0 | H12: 0 | I12: 0 | J12: 0 | K12: 0 | L12: 0 | M12: 0 | N12: 0 | O12: 0
A13: 1231898 | B13: 0 | C13: 500 | D13: 0 | E13: 0 | F13: 0 | G13: 0 | H13: 0 | I13: 0 | J13: 0 | K13: 0 | L13: 0 | M13: 0 | N13: 0 | O13: 0
... A24: 1240308 | B24: 250 | C24: 0 | D24: 500 | E24: 250 | F24: 0 | G24: 0 | H24: 0 | I24: 0 | J24: 200 | K24: 0 | L24: 350 | M24: 200 | N24: 0 | O24: 0
A29: 품번 | B29: 01/05(월) | C29: 01/06(화) | D29: 01/07(수) | E29: 01/08(목) | F29: 01/09(금) | G29: 01/10(토) | H29: 01/11(일) | I29: 01/12(월) | J29: 01/13(화) | K29: 01/14(수) | L29: 01/15(목) | M29: 01/16(금) | N29: 01/17(토) | O29: 01/18(일)
A30: 1237608 | B30: 0 | C30: 0 | D30: 0 | E30: 0 | F30: 0 | G30: 0 | H30: 0 | I30: 0 | J30: 350 | K30: 250 | L30: 0 | M30: 0 | N30: 0 | O30: 0
A31: 1232846 | B31: 0 | C31: 0 | D31: 0 | E31: 0 | F31: 0 | G31: 0 | H31: 0 | I31: 0 | J31: 327 | K31: 352 | L31: 21 | M31: 0 | N31: 0 | O31: 0
A32: 1232895 | B32: 0 | C32: 0 | D32: 0 | E32: 0 | F32: 0 | G32: 0 | H32: 0 | I32: 0 | J32: 327 | K32: 352 | L32: 21 | M32: 0 | N32: 0 | O32: 0
A33: 1233384 | B33: 0 | C33: 0 | D33: 0 | E33: 0 | F33: 0 | G33: 0 | H33: 0 | I33: 0 | J33: 327 | K33: 352 | L33: 21 | M33: 0 | N33: 0 | O33: 0
A34: 1236110 | B34: 0 | C34: 0 | D34: 0 | E34: 0 | F34: 0 | G34: 0 | H34: 0 | I34: 0 | J34: 0 | K34: 0 | L34: 300 | M34: 0 | N34: 0 | O34: 0
A35: 1236387 | B35: 0 | C35: 0 | D35: 265 | E35: 395 | F35: 0 | G35: 0 | H35: 0 | I35: 0 | J35: 0 | K35: 0 | L35: 0 | M35: 0 | N35: 0 | O35: 0
A36: 1232775 | B36: 575 | C36: 616 | D36: 277 | E36: 311 | F36: 14 | G36: 0 | H36: 0 | I36: 0 | J36: 288 | K36: 243 | L36: 309 | M36: 309 | N36: 0 | O36: 0
A37: 1238605 | B37: 0 | C37: 0 | D37: 0 | E37: 0 | F37: 189 | G37: 0 | H37: 0 | I37: 238 | J37: 6 | K37: 0 | L37: 0 | M37: 0 | N37: 0 | O37: 0
A42: 품번 | B42: 01/05(월) | C42: 01/06(화) | D42: 01/07(수) | E42: 01/08(목) | F42: 01/09(금) | G42: 01/10(토) | H42: 01/11(일) | I42: 01/12(월) | J42: 01/13(화) | K42: 01/14(수) | L42: 01/15(목) | M42: 01/16(금) | N42: 01/17(토) | O42: 01/18(일)
A43: 1221967 | B43: 0 | C43: 0 | D43: 0 | E43: 0 | F43: 0 | G43: 0 | H43: 0 | I43: 0 | J43: 0 | K43: 176 | L43: 0 | M43: 0 | N43: 0 | O43: 0
A44: 1227306 | B44: 452 | C44: 45 | D44: 277 | E44: 123 | F44: 0 | G44: 0 | H44: 0 | I44: 0 | J44: 510 | K44: 400 | L44: 0 | M44: 0 | N44: 0 | O44: 0
A45: 1227359 | B45: 0 | C45: 0 | D45: 0 | E45: 86 | F45: 0 | G45: 0 | H45: 0 | I45: 0 | J45: 0 | K45: 0 | L45: 0 | M45: 0 | N45: 0 | O45: 0
A46: 1229088 | B46: 0 | C46: 0 | D46: 0 | E46: 0 | F46: 0 | G46: 0 | H46: 0 | I46: 0 | J46: 0 | K46: 500 | L46: 0 | M46: 0 | N46: 0 | O46: 0
A47: 1231090 | B47: 0 | C47: 0 | D47: 0 | E47: 0 | F47: 0 | G47: 0 | H47: 0 | I47: 0 | J47: 0 | K47: 0 | L47: 0 | M47: 200 | N47: 0 | O47: 0
A48: 1229776 | B48: 0 | C48: 0 | D48: 0 | E48: 0 | F48: 0 | G48: 0 | H48: 0 | I48: 0 | J48: 0 | K48: 0 | L48: 0 | M48: 200 | N48: 0 | O48: 0
A49: 1231797 | B49: 0 | C49: 0 | D49: 0 | E49: 0 | F49: 0 | G49: 0 | H49: 0 | I49: 0 | J49: 0 | K49: 113 | L49: 0 | M49: 0 | N49: 0 | O49: 0
A50: 1232528 | B50: 0 | C50: 0 | D50: 0 | E50: 0 | F50: 0 | G50: 0 | H50: 0 | I50: 163 | J50: 686 | K50: 539 | L50: 649 | M50: 0 | N50: 0 | O50: 0
A51: 1233587 | B51: 0 | C51: 0 | D51: 0 | E51: 0 | F51: 0 | G51: 0 | H51: 0 | I51: 0 | J51: 0 | K51: 10 | L51: 0 | M51: 0 | N51: 0 | O51: 0
A52: 1232846 | B52: 0 | C52: 0 | D52: 0 | E52: 0 | F52: 0 | G52: 0 | H52: 0 | I52: 0 | J52: 0 | K52: 176 | L52: 0 | M52: 0 | N52: 0 | O52: 0
A53: 1232693 | B53: 0 | C53: 0 | D53: 0 | E53: 0 | F53: 0 | G53: 0 | H53: 0 | I53: 54 | J53: 0 | K53: 0 | L53: 0 | M53: 0 | N53: 0 | O53: 0
A54: 1233025 | B54: 0 | C54: 0 | D54: 0 | E54: 0 | F54: 0 | G54: 0 | H54: 0 | I54: 54 | J54: 0 | K54: 0 | L54: 0 | M54: 0 | N54: 0 | O54: 0
... A77: 1232922 | B77: 0 | C77: 0 | D77: 0 | E77: 0 | F77: 0 | G77: 0 | H77: 0 | I77: 0 | J77: 0 | K77: 176 | L77: 0 | M77: 0 | N77: 0 | O77: 0

Sheet 0106
A1: 품번 | B1: 01/06(화) | C1: 01/07(수) | D1: 01/08(목) | E1: 01/09(금) | F1: 01/10(토) | G1: 01/11(일) | H1: 01/12(월) | I1: 01/13(화) | J1: 01/14(수) | K1: 01/15(목) | L1: 01/16(금) | M1: 01/17(토) | N1: 01/18(일) | O1: 01/19(월) | P1: 01/20(화) | Q1: 01/21(수) | R1: 01/22(목) | S1: 01/23(금) | T1: 01/24(토) | U1: 01/25(일)
A2: 1221154 | B2: 0 | C2: 0 | D2: 0 | E2: 0 | F2: 0 | G2: 0 | H2: 0 | I2: 0 | J2: 50 | K2: 0 | L2: 0 | M2: 0 | N2: 0 | O2: 0 | P2: 0 | Q2: 0 | R2: 0 | S2: 0 | T2: 0 | U2: 0 | V2: =SUM(B2:U2) -> 50
A3: 1234614 | B3: 0 | C3: 0 | D3: 0 | E3: 0 | F3: 0 | G3: 0 | H3: 0 | I3: 0 | J3: 352 | K3: 50 | L3: 0 | M3: 0 | N3: 0 | O3: 0 | P3: 0 | Q3: 354 | R3: 516 | S3: 0 | T3: 0 | U3: 0 | V3: =SUM(B3:U3) -> 1272
A4: 1226384 | B4: 0 | C4: 0 | D4: 0 | E4: 0 | F4: 0 | G4: 0 | H4: 360 | I4: 100 | J4: 400 | K4: 0 | L4: 0 | M4: 0 | N4: 0 | O4: 0 | P4: 0 | Q4: 0 | R4: 0 | S4: 0 | T4: 0 | U4: 0 | V4: =SUM(B4:U4) -> 860
A5: 1226388 | B5: 0 | C5: 0 | D5: 0 | E5: 0 | F5: 0 | G5: 0 | H5: 360 | I5: 100 | J5: 400 | K5: 0 | L5: 0 | M5: 0 | N5: 0 | O5: 0 | P5: 0 | Q5: 0 | R5: 0 | S5: 0 | T5: 0 | U5: 0 | V5: =SUM(B5:U5) -> 860
A6: 1229673 | B6: 200 | C6: 200 | D6: 200 | E6: 242 | F6: 0 | G6: 0 | H6: 250 | I6: 250 | J6: 250 | K6: 250 | L6: 200 | M6: 0 | N6: 0 | O6: 300 | P6: 200 | Q6: 200 | R6: 200 | S6: 300 | T6: 0 | U6: 0 | V6: =SUM(B6:U6) -> 3242
A7: 1230854 | B7: 0 | C7: 0 | D7: 0 | E7: 0 | F7: 0 | G7: 0 | H7: 200 | I7: 0 | J7: 0 | K7: 0 | L7: 0 | M7: 0 | N7: 0 | O7: 0 | P7: 0 | Q7: 0 | R7: 0 | S7: 0 | T7: 0 | U7: 0 | V7: =SUM(B7:U7) -> 200
A8: 1233632 | B8: 0 | C8: 0 | D8: 346 | E8: 330 | F8: 0 | G8: 0 | H8: 406 | I8: 0 | J8: 0 | K8: 0 | L8: 0 | M8: 0 | N8: 0 | O8: 0 | P8: 248 | Q8: 153 | R8: 0 | S8: 0 | T8: 0 | U8: 0 | V8: =SUM(B8:U8) -> 1483
A9: 1237088 | B9: 1022 | C9: 694 | D9: 1286 | E9: 1570 | F9: 0 | G9: 0 | H9: 1276 | I9: 906 | J9: 1006 | K9: 942 | L9: 1496 | M9: 0 | N9: 0 | O9: 1388 | P9: 724 | Q9: 928 | R9: 524 | S9: 1129 | T9: 0 | U9: 0 | V9: =SUM(B9:U9) -> 14891
A10: 1237748 | B10: 0 | C10: 0 | D10: 260 | E10: 0 | F10: 0 | G10: 0 | H10: 0 | I10: 0 | J10: 0 | K10: 0 | L10: 0 | M10: 0 | N10: 0 | O10: 0 | P10: 0 | Q10: 0 | R10: 0 | S10: 0 | T10: 0 | U10: 0 | V10: =SUM(B10:U10) -> 260
A11: 1231898 | B11: 500 | C11: 0 | D11: 0 | E11: 0 | F11: 0 | G11: 0 | H11: 0 | I11: 0 | J11: 0 | K11: 0 | L11: 0 | M11: 0 | N11: 0 | O11: 0 | P11: 0 | Q11: 0 | R11: 0 | S11: 0 | T11: 0 | U11: 0 | V11: =SUM(B11:U11) -> 500
A12: 1237586 | B12: 500 | C12: 0 | D12: 0 | E12: 0 | F12: 0 | G12: 0 | H12: 0 | I12: 0 | J12: 0 | K12: 0 | L12: 0 | M12: 0 | N12: 0 | O12: 0 | P12: 0 | Q12: 0 | R12: 0 | S12: 0 | T12: 0 | U12: 0 | V12: =SUM(B12:U12) -> 500
A13: 1236091 | B13: 100 | C13: 0 | D13: 0 | E13: 0 | F13: 0 | G13: 0 | H13: 0 | I13: 0 | J13: 200 | K13: 0 | L13: 0 | M13: 0 | N13: 0 | O13: 0 | P13: 0 | Q13: 0 | R13: 0 | S13: 0 | T13: 0 | U13: 0 | V13: =SUM(B13:U13) -> 300
... A22: 1240308 | B22: 0 | C22: 500 | D22: 250 | E22: 0 | F22: 0 | G22: 0 | H22: 0 | I22: 200 | J22: 0 | K22: 350 | L22: 200 | M22: 0 | N22: 0 | O22: 0 | P22: 450 | Q22: 300 | R22: 0 | S22: 0 | T22: 0 | U22: 0 | V22: =SUM(B22:U22) -> 2250
A26: 품번 | B26: 01/06(화) | C26: 01/07(수) | D26: 01/08(목) | E26: 01/09(금) | F26: 01/10(토) | G26: 01/11(일) | H26: 01/12(월) | I26: 01/13(화) | J26: 01/14(수) | K26: 01/15(목) | L26: 01/16(금) | M26: 01/17(토) | N26: 01/18(일) | O26: 01/19(월) | P26: 01/20(화) | Q26: 01/21(수) | R26: 01/22(목) | S26: 01/23(금) | T26: 01/24(토) | U26: 01/25(일)
A27: 1237608 | B27: 0 | C27: 0 | D27: 0 | E27: 0 | F27: 0 | G27: 0 | H27: 0 | I27: 350 | J27: 250 | K27: 0 | L27: 0 | M27: 0 | N27: 0 | O27: 0 | P27: 0 | Q27: 0 | R27: 0 | S27: 0 | T27: 0 | U27: 0
A28: 1233384 | B28: 0 | C28: 0 | D28: 0 | E28: 0 | F28: 0 | G28: 0 | H28: 0 | I28: 327 | J28: 352 | K28: 21 | L28: 0 | M28: 0 | N28: 0 | O28: 0 | P28: 72 | Q28: 352 | R28: 449 | S28: 7 | T28: 0 | U28: 0
A29: 1232895 | B29: 0 | C29: 0 | D29: 0 | E29: 0 | F29: 0 | G29: 0 | H29: 0 | I29: 327 | J29: 352 | K29: 21 | L29: 0 | M29: 0 | N29: 0 | O29: 0 | P29: 72 | Q29: 352 | R29: 449 | S29: 7 | T29: 0 | U29: 0
A30: 1232846 | B30: 0 | C30: 0 | D30: 0 | E30: 0 | F30: 0 | G30: 0 | H30: 0 | I30: 327 | J30: 352 | K30: 21 | L30: 0 | M30: 0 | N30: 0 | O30: 0 | P30: 72 | Q30: 352 | R30: 449 | S30: 7 | T30: 0 | U30: 0
A31: 1233165 | B31: 0 | C31: 0 | D31: 0 | E31: 0 | F31: 0 | G31: 0 | H31: 0 | I31: 0 | J31: 0 | K31: 0 | L31: 0 | M31: 0 | N31: 0 | O31: 0 | P31: 0 | Q31: 0 | R31: 0 | S31: 250 | T31: 0 | U31: 0
A32: 1236110 | B32: 0 | C32: 0 | D32: 0 | E32: 0 | F32: 0 | G32: 0 | H32: 0 | I32: 0 | J32: 0 | K32: 300 | L32: 0 | M32: 0 | N32: 0 | O32: 0 | P32: 0 | Q32: 0 | R32: 0 | S32: 0 | T32: 0 | U32: 0
A33: 1236387 | B33: 0 | C33: 265 | D33: 395 | E33: 0 | F33: 0 | G33: 0 | H33: 0 | I33: 0 | J33: 0 | K33: 0 | L33: 0 | M33: 0 | N33: 0 | O33: 411 | P33: 325 | Q33: 0 | R33: 0 | S33: 0 | T33: 0 | U33: 0
A34: 1232775 | B34: 616 | C34: 277 | D34: 311 | E34: 14 | F34: 0 | G34: 0 | H34: 0 | I34: 288 | J34: 243 | K34: 309 | L34: 309 | M34: 0 | N34: 0 | O34: 298 | P34: 8 | Q34: 0 | R34: 0 | S34: 0 | T34: 0 | U34: 0
A35: 1238605 | B35: 0 | C35: 0 | D35: 0 | E35: 189 | F35: 0 | G35: 0 | H35: 238 | I35: 6 | J35: 0 | K35: 0 | L35: 0 | M35: 0 | N35: 0 | O35: 0 | P35: 42 | Q35: 187 | R35: 182 | S35: 4 | T35: 0 | U35: 0
A38: 품번 | B38: 01/06(화) | C38: 01/07(수) | D38: 01/08(목) | E38: 01/09(금) | F38: 01/10(토) | G38: 01/11(일) | H38: 01/12(월) | I38: 01/13(화) | J38: 01/14(수) | K38: 01/15(목) | L38: 01/16(금) | M38: 01/17(토) | N38: 01/18(일) | O38: 01/19(월) | P38: 01/20(화) | Q38: 01/21(수) | R38: 01/22(목) | S38: 01/23(금) | T38: 01/24(토) | U38: 01/25(일)
A39: 1230692 | B39: 0 | C39: 0 | D39: 0 | E39: 0 | F39: 0 | G39: 0 | H39: 0 | I39: 0 | J39: 0 | K39: 0 | L39: 0 | M39: 0 | N39: 0 | O39: 0 | P39: 0 | Q39: 100 | R39: 0 | S39: 0 | T39: 0 | U39: 0
A40: 1221967 | B40: 0 | C40: 0 | D40: 0 | E40: 0 | F40: 0 | G40: 0 | H40: 0 | I40: 0 | J40: 176 | K40: 0 | L40: 0 | M40: 0 | N40: 0 | O40: 0 | P40: 0 | Q40: 0 | R40: 0 | S40: 0 | T40: 0 | U40: 0
A41: 1227306 | B41: 45 | C41: 277 | D41: 123 | E41: 0 | F41: 0 | G41: 0 | H41: 0 | I41: 200 | J41: 400 | K41: 310 | L41: 0 | M41: 0 | N41: 0 | O41: 0 | P41: 0 | Q41: 0 | R41: 200 | S41: 400 | T41: 0 | U41: 0
A42: 1227359 | B42: 0 | C42: 0 | D42: 86 | E42: 0 | F42: 0 | G42: 0 | H42: 0 | I42: 0 | J42: 0 | K42: 0 | L42: 0 | M42: 0 | N42: 0 | O42: 0 | P42: 0 | Q42: 0 | R42: 0 | S42: 0 | T42: 0 | U42: 0
A43: 1229088 | B43: 0 | C43: 0 | D43: 0 | E43: 0 | F43: 0 | G43: 0 | H43: 0 | I43: 250 | J43: 250 | K43: 0 | L43: 0 | M43: 0 | N43: 0 | O43: 0 | P43: 0 | Q43: 0 | R43: 0 | S43: 0 | T43: 0 | U43: 0
A44: 1231090 | B44: 0 | C44: 0 | D44: 0 | E44: 0 | F44: 0 | G44: 0 | H44: 0 | I44: 0 | J44: 0 | K44: 0 | L44: 200 | M44: 0 | N44: 0 | O44: 100 | P44: 0 | Q44: 0 | R44: 0 | S44: 0 | T44: 0 | U44: 0
A45: 1229776 | B45: 0 | C45: 0 | D45: 0 | E45: 0 | F45: 0 | G45: 0 | H45: 0 | I45: 0 | J45: 0 | K45: 0 | L45: 200 | M45: 0 | N45: 0 | O45: 100 | P45: 0 | Q45: 0 | R45: 0 | S45: 0 | T45: 0 | U45: 0
A46: 1231797 | B46: 0 | C46: 0 | D46: 0 | E46: 0 | F46: 0 | G46: 0 | H46: 0 | I46: 0 | J46: 113 | K46: 0 | L46: 0 | M46: 0 | N46: 0 | O46: 0 | P46: 0 | Q46: 0 | R46: 0 | S46: 0 | T46: 0 | U46: 0
A47: 1225464 | B47: 0 | C47: 0 | D47: 0 | E47: 0 | F47: 0 | G47: 0 | H47: 0 | I47: 0 | J47: 0 | K47: 0 | L47: 0 | M47: 0 | N47: 0 | O47: 0 | P47: 0 | Q47: 0 | R47: 0 | S47: 28 | T47: 0 | U47: 0
A48: 1234222 | B48: 0 | C48: 0 | D48: 0 | E48: 0 | F48: 0 | G48: 0 | H48: 0 | I48: 0 | J48: 0 | K48: 0 | L48: 0 | M48: 0 | N48: 0 | O48: 0 | P48: 120 | Q48: 126 | R48: 0 | S48: 0 | T48: 0 | U48: 0
A49: 1232528 | B49: 0 | C49: 0 | D49: 0 | E49: 0 | F49: 0 | G49: 0 | H49: 163 | I49: 686 | J49: 539 | K49: 649 | L49: 0 | M49: 0 | N49: 0 | O49: 0 | P49: 0 | Q49: 0 | R49: 0 | S49: 147 | T49: 0 | U49: 0
A50: 1233587 | B50: 0 | C50: 0 | D50: 0 | E50: 0 | F50: 0 | G50: 0 | H50: 0 | I50: 0 | J50: 10 | K50: 0 | L50: 0 | M50: 0 | N50: 0 | O50: 0 | P50: 0 | Q50: 0 | R50: 0 | S50: 0 | T50: 0 | U50: 0
... A86: 1233580 | B86: 0 | C86: 0 | D86: 0 | E86: 0 | F86: 0 | G86: 0 | H86: 0 | I86: 0 | J86: 0 | K86: 0 | L86: 0 | M86: 0 | N86: 0 | O86: 130 | P86: 0 | Q86: 0 | R86: 0 | S86: 0 | T86: 0 | U86: 0

Sheet 0107
A1: 품번 | B1: 01/07(수) | C1: 01/08(목) | D1: 01/09(금) | E1: 01/10(토) | F1: 01/11(일) | G1: 01/12(월) | H1: 01/13(화) | I1: 01/14(수) | J1: 01/15(목) | K1: 01/16(금) | L1: 01/17(토) | M1: 01/18(일) | N1: 01/19(월) | O1: 01/20(화) | P1: 01/21(수) | Q1: 01/22(목) | R1: 01/23(금) | S1: 01/24(토) | T1: 01/25(일)
A2: 1221154 | B2: 0 | C2: 0 | D2: 0 | E2: 0 | F2: 0 | G2: 0 | H2: 0 | I2: 50 | J2: 0 | K2: 0 | L2: 0 | M2: 0 | N2: 0 | O2: 0 | P2: 0 | Q2: 0 | R2: 0 | S2: 0 | T2: 0
A3: 1234614 | B3: 0 | C3: 0 | D3: 0 | E3: 0 | F3: 0 | G3: 0 | H3: 0 | I3: 352 | J3: 50 | K3: 0 | L3: 0 | M3: 0 | N3: 0 | O3: 0 | P3: 354 | Q3: 516 | R3: 0 | S3: 0 | T3: 0
A4: 1226384 | B4: 0 | C4: 0 | D4: 0 | E4: 0 | F4: 0 | G4: 360 | H4: 100 | I4: 400 | J4: 0 | K4: 0 | L4: 0 | M4: 0 | N4: 0 | O4: 0 | P4: 0 | Q4: 0 | R4: 0 | S4: 0 | T4: 0
A5: 1226388 | B5: 0 | C5: 0 | D5: 0 | E5: 0 | F5: 0 | G5: 360 | H5: 100 | I5: 400 | J5: 0 | K5: 0 | L5: 0 | M5: 0 | N5: 0 | O5: 0 | P5: 0 | Q5: 0 | R5: 0 | S5: 0 | T5: 0
A6: 1229673 | B6: 200 | C6: 200 | D6: 242 | E6: 0 | F6: 0 | G6: 250 | H6: 250 | I6: 250 | J6: 250 | K6: 200 | L6: 0 | M6: 0 | N6: 300 | O6: 200 | P6: 200 | Q6: 200 | R6: 300 | S6: 0 | T6: 0
A7: 1230854 | B7: 0 | C7: 0 | D7: 0 | E7: 0 | F7: 0 | G7: 200 | H7: 0 | I7: 0 | J7: 0 | K7: 0 | L7: 0 | M7: 0 | N7: 0 | O7: 0 | P7: 0 | Q7: 0 | R7: 0 | S7: 0 | T7: 0
A8: 1233632 | B8: 0 | C8: 346 | D8: 330 | E8: 0 | F8: 0 | G8: 406 | H8: 0 | I8: 0 | J8: 0 | K8: 0 | L8: 0 | M8: 0 | N8: 0 | O8: 0 | P8: 0 | Q8: 0 | R8: 0 | S8: 0 | T8: 0
A9: 1237088 | B9: 694 | C9: 1286 | D9: 1570 | E9: 0 | F9: 0 | G9: 1276 | H9: 906 | I9: 1006 | J9: 942 | K9: 1496 | L9: 0 | M9: 0 | N9: 1388 | O9: 724 | P9: 928 | Q9: 524 | R9: 1129 | S9: 0 | T9: 0
A10: 1237748 | B10: 0 | C10: 260 | D10: 0 | E10: 0 | F10: 0 | G10: 0 | H10: 0 | I10: 0 | J10: 0 | K10: 0 | L10: 0 | M10: 0 | N10: 0 | O10: 0 | P10: 0 | Q10: 0 | R10: 0 | S10: 0 | T10: 0
A11: 1236091 | B11: 0 | C11: 0 | D11: 0 | E11: 0 | F11: 0 | G11: 0 | H11: 0 | I11: 200 | J11: 0 | K11: 0 | L11: 0 | M11: 0 | N11: 0 | O11: 0 | P11: 0 | Q11: 0 | R11: 0 | S11: 0 | T11: 0
A12: 1238128 | B12: 0 | C12: 404 | D12: 377 | E12: 0 | F12: 0 | G12: 480 | H12: 480 | I12: 378 | J12: 912 | K12: 960 | L12: 0 | M12: 0 | N12: 546 | O12: 480 | P12: 50 | Q12: 294 | R12: 378 | S12: 0 | T12: 0
A13: 1236962 | B13: 200 | C13: 400 | D13: 400 | E13: 0 | F13: 0 | G13: 250 | H13: 250 | I13: 0 | J13: 250 | K13: 250 | L13: 0 | M13: 0 | N13: 200 | O13: 400 | P13: 200 | Q13: 200 | R13: 300 | S13: 0 | T13: 0
... A19: 1240308 | B19: 500 | C19: 250 | D19: 0 | E19: 0 | F19: 0 | G19: 0 | H19: 200 | I19: 0 | J19: 350 | K19: 200 | L19: 0 | M19: 0 | N19: 0 | O19: 450 | P19: 300 | Q19: 0 | R19: 0 | S19: 0 | T19: 0
A22: 품번 | B22: 01/07(수) | C22: 01/08(목) | D22: 01/09(금) | E22: 01/10(토) | F22: 01/11(일) | G22: 01/12(월) | H22: 01/13(화) | I22: 01/14(수) | J22: 01/15(목) | K22: 01/16(금) | L22: 01/17(토) | M22: 01/18(일) | N22: 01/19(월) | O22: 01/20(화) | P22: 01/21(수) | Q22: 01/22(목) | R22: 01/23(금) | S22: 01/24(토) | T22: 01/25(일)
A23: 1237608 | B23: 0 | C23: 0 | D23: 0 | E23: 0 | F23: 0 | G23: 0 | H23: 350 | I23: 250 | J23: 0 | K23: 0 | L23: 0 | M23: 0 | N23: 0 | O23: 0 | P23: 0 | Q23: 0 | R23: 0 | S23: 0 | T23: 0
A24: 1232846 | B24: 0 | C24: 0 | D24: 0 | E24: 0 | F24: 0 | G24: 0 | H24: 327 | I24: 352 | J24: 21 | K24: 0 | L24: 0 | M24: 0 | N24: 0 | O24: 403 | P24: 352 | Q24: 449 | R24: 7 | S24: 0 | T24: 0
A25: 1232895 | B25: 0 | C25: 0 | D25: 0 | E25: 0 | F25: 0 | G25: 0 | H25: 327 | I25: 352 | J25: 21 | K25: 0 | L25: 0 | M25: 0 | N25: 0 | O25: 403 | P25: 352 | Q25: 449 | R25: 7 | S25: 0 | T25: 0
A26: 1233384 | B26: 0 | C26: 0 | D26: 0 | E26: 0 | F26: 0 | G26: 0 | H26: 327 | I26: 352 | J26: 21 | K26: 0 | L26: 0 | M26: 0 | N26: 0 | O26: 403 | P26: 352 | Q26: 449 | R26: 7 | S26: 0 | T26: 0
A27: 1233165 | B27: 0 | C27: 0 | D27: 0 | E27: 0 | F27: 0 | G27: 0 | H27: 0 | I27: 0 | J27: 0 | K27: 0 | L27: 0 | M27: 0 | N27: 0 | O27: 0 | P27: 0 | Q27: 0 | R27: 250 | S27: 0 | T27: 0
A28: 1236387 | B28: 265 | C28: 395 | D28: 0 | E28: 0 | F28: 0 | G28: 0 | H28: 0 | I28: 0 | J28: 0 | K28: 0 | L28: 0 | M28: 0 | N28: 411 | O28: 325 | P28: 0 | Q28: 0 | R28: 0 | S28: 0 | T28: 0
A29: 1232775 | B29: 277 | C29: 311 | D29: 14 | E29: 0 | F29: 0 | G29: 0 | H29: 288 | I29: 243 | J29: 309 | K29: 309 | L29: 0 | M29: 0 | N29: 298 | O29: 8 | P29: 0 | Q29: 0 | R29: 0 | S29: 0 | T29: 0
A30: 1238605 | B30: 0 | C30: 0 | D30: 189 | E30: 0 | F30: 0 | G30: 238 | H30: 6 | I30: 0 | J30: 0 | K30: 0 | L30: 0 | M30: 0 | N30: 0 | O30: 42 | P30: 187 | Q30: 182 | R30: 4 | S30: 0 | T30: 0
A35: 품번 | B35: 01/07(수) | C35: 01/08(목) | D35: 01/09(금) | E35: 01/10(토) | F35: 01/11(일) | G35: 01/12(월) | H35: 01/13(화) | I35: 01/14(수) | J35: 01/15(목) | K35: 01/16(금) | L35: 01/17(토) | M35: 01/18(일) | N35: 01/19(월) | O35: 01/20(화) | P35: 01/21(수) | Q35: 01/22(목) | R35: 01/23(금) | S35: 01/24(토) | T35: 01/25(일)
A36: 1230692 | B36: 0 | C36: 0 | D36: 0 | E36: 0 | F36: 0 | G36: 0 | H36: 0 | I36: 0 | J36: 0 | K36: 0 | L36: 0 | M36: 0 | N36: 0 | O36: 0 | P36: 0 | Q36: 100 | R36: 0 | S36: 0 | T36: 0
A37: 1221967 | B37: 0 | C37: 0 | D37: 0 | E37: 0 | F37: 0 | G37: 0 | H37: 0 | I37: 176 | J37: 0 | K37: 0 | L37: 0 | M37: 0 | N37: 0 | O37: 0 | P37: 0 | Q37: 0 | R37: 0 | S37: 0 | T37: 0
A38: 1227306 | B38: 277 | C38: 123 | D38: 0 | E38: 0 | F38: 0 | G38: 0 | H38: 0 | I38: 0 | J38: 0 | K38: 0 | L38: 0 | M38: 0 | N38: 150 | O38: 500 | P38: 400 | Q38: 110 | R38: 0 | S38: 0 | T38: 0
A39: 1227359 | B39: 0 | C39: 86 | D39: 0 | E39: 0 | F39: 0 | G39: 0 | H39: 0 | I39: 0 | J39: 0 | K39: 0 | L39: 0 | M39: 0 | N39: 0 | O39: 0 | P39: 0 | Q39: 0 | R39: 0 | S39: 0 | T39: 0
A40: 1229088 | B40: 0 | C40: 0 | D40: 0 | E40: 0 | F40: 0 | G40: 0 | H40: 492 | I40: 0 | J40: 0 | K40: 0 | L40: 0 | M40: 0 | N40: 0 | O40: 0 | P40: 0 | Q40: 0 | R40: 0 | S40: 0 | T40: 0
A41: 1231090 | B41: 0 | C41: 0 | D41: 0 | E41: 0 | F41: 0 | G41: 0 | H41: 0 | I41: 0 | J41: 0 | K41: 0 | L41: 0 | M41: 0 | N41: 200 | O41: 0 | P41: 0 | Q41: 0 | R41: 0 | S41: 0 | T41: 0
A42: 1229776 | B42: 0 | C42: 0 | D42: 0 | E42: 0 | F42: 0 | G42: 0 | H42: 0 | I42: 0 | J42: 0 | K42: 0 | L42: 0 | M42: 0 | N42: 200 | O42: 0 | P42: 0 | Q42: 0 | R42: 0 | S42: 0 | T42: 0
A43: 1231797 | B43: 0 | C43: 0 | D43: 0 | E43: 0 | F43: 0 | G43: 0 | H43: 113 | I43: 0 | J43: 0 | K43: 0 | L43: 0 | M43: 0 | N43: 0 | O43: 0 | P43: 0 | Q43: 0 | R43: 0 | S43: 0 | T43: 0
A44: 1225464 | B44: 0 | C44: 0 | D44: 0 | E44: 0 | F44: 0 | G44: 0 | H44: 0 | I44: 0 | J44: 0 | K44: 0 | L44: 0 | M44: 0 | N44: 0 | O44: 0 | P44: 0 | Q44: 0 | R44: 28 | S44: 0 | T44: 0
A45: 1234222 | B45: 0 | C45: 0 | D45: 0 | E45: 0 | F45: 0 | G45: 0 | H45: 0 | I45: 0 | J45: 0 | K45: 0 | L45: 0 | M45: 0 | N45: 0 | O45: 220 | P45: 258 | Q45: 0 | R45: 0 | S45: 0 | T45: 0
A46: 1232528 | B46: 0 | C46: 0 | D46: 0 | E46: 0 | F46: 0 | G46: 161 | H46: 686 | I46: 539 | J46: 651 | K46: 0 | L46: 0 | M46: 0 | N46: 0 | O46: 0 | P46: 0 | Q46: 0 | R46: 147 | S46: 0 | T46: 0
A47: 1233587 | B47: 0 | C47: 0 | D47: 0 | E47: 0 | F47: 0 | G47: 0 | H47: 0 | I47: 10 | J47: 0 | K47: 0 | L47: 0 | M47: 0 | N47: 0 | O47: 0 | P47: 0 | Q47: 0 | R47: 0 | S47: 0 | T47: 0
... A80: 1233580 | B80: 0 | C80: 0 | D80: 0 | E80: 0 | F80: 0 | G80: 0 | H80: 0 | I80: 0 | J80: 0 | K80: 0 | L80: 0 | M80: 0 | N80: 130 | O80: 0 | P80: 0 | Q80: 0 | R80: 0 | S80: 0 | T80: 0

Sheet 0107 W12
A1: 차이 | C1: =+C2-C3 -> 0 | D1: =+D2-D3 -> 0 | E1: =+E2-E3 -> 0 | F1: =+F2-F3 -> 0 | G1: =+G2-G3 -> 0 | H1: =+H2-H3 -> 0 | I1: =+I2-I3 -> 0 | J1: =+J2-J3 -> 0 | ... L1: =+L2-L3 -> 0
A2: 영판 | C2: 44885 | D2: 48523 | E2: 47685 | F2: 19838 | G2: 33925 | H2: 33056 | I2: 47301 | J2: 41621 | K2: 42446 | L2: 49771 | M2: 0 | N2: 0
A3: 합계 | C3: =C4+C5 -> 44885 | D3: =D4+D5 -> 48523 | E3: =E4+E5 -> 47685 | F3: =F4+F5 -> 19838 | G3: =G4+G5 -> 33925 | H3: =H4+H5 -> 33056 | I3: =I4+I5 -> 47301 | J3: =J4+J5 -> 41621 | ... L3: =L4+L5 -> 49771
A4: 인천 | C4: =SUM(C9:C46) -> 28544 | D4: =SUM(D9:D46) -> 22850 | E4: =SUM(E9:E46) -> 28486 | F4: =SUM(F9:F46) -> 13100 | G4: =SUM(G9:G46) -> 21520 | H4: =SUM(H9:H46) -> 21430 | I4: =SUM(I9:I46) -> 23026 | J4: =SUM(J9:J46) -> 27392 | ... L4: =SUM(L9:L46) -> 35072
A5: 유구 | C5: =SUM(C70:C131) -> 16341 | D5: =SUM(D70:D131) -> 25673 | E5: =SUM(E70:E131) -> 19199 | F5: =SUM(F70:F131) -> 6738 | G5: =SUM(G70:G131) -> 12405 | H5: =SUM(H70:H131) -> 11626 | I5: =SUM(I70:I131) -> 24275 | J5: =SUM(J70:J131) -> 14229 | ... L5: =SUM(L70:L131) -> 14699
B7: 품번 | C7: 05W | D7: 06W | E7: 07W | F7: 08W | G7: 09W | H7: 10W | I7: 11W | J7: 12W | K7: 13W | L7: 14W
C8: 01/26 ~ 02/01 | D8: 02/02 ~ 02/08 | E8: 02/09 ~ 02/15 | F8: 02/16 ~ 02/22 | G8: 02/23 ~ 03/01 | H8: 03/02 ~ 03/08 | I8: 03/09 ~ 03/15 | J8: 03/16 ~ 03/22 | K8: 03/23 ~ 03/29 | L8: 03/30 ~ 04/05
B9: 1226384 | C9: 0 | D9: 1160 | E9: 200 | F9: 0 | G9: 300 | H9: 300 | I9: 0 | J9: 0 | K9: 400 | L9: 200 | N9: =SUM(D9:L9) -> 2560 | O9: =IFERROR(VLOOKUP(B9,'[1]26.02W (1월생판)'!$G$7:$AP$298,36,0),0) -> 2560 | P9: =+N9-O9 -> 0 | R9: =SUM(D9:L9) -> 2560
B10: 1226388 | C10: 0 | D10: 1160 | E10: 200 | F10: 0 | G10: 300 | H10: 300 | I10: 0 | J10: 0 | K10: 400 | L10: 200 | N10: =SUM(D10:L10) -> 2560 | O10: =IFERROR(VLOOKUP(B10,'[1]26.02W (1월생판)'!$G$7:$AP$298,36,0),0) -> 2560 | P10: =+N10-O10 -> 0 | R10: =SUM(D10:L10) -> 2560
B11: 1227431 | C11: 0 | D11: 0 | E11: 96 | F11: 0 | G11: 0 | H11: 0 | I11: 0 | J11: 0 | K11: 0 | L11: 0 | N11: =SUM(D11:L11) -> 96 | O11: =IFERROR(VLOOKUP(B11,'[1]26.02W (1월생판)'!$G$7:$AP$298,36,0),0) -> 96 | P11: =+N11-O11 -> 0 | R11: =SUM(D11:L11) -> 96
B12: 1227433 | C12: 0 | D12: 0 | E12: 96 | F12: 0 | G12: 0 | H12: 0 | I12: 0 | J12: 0 | K12: 0 | L12: 0 | N12: =SUM(D12:L12) -> 96 | O12: =IFERROR(VLOOKUP(B12,'[1]26.02W (1월생판)'!$G$7:$AP$298,36,0),0) -> 96 | P12: =+N12-O12 -> 0 | R12: =SUM(D12:L12) -> 96
B13: 1229673 | C13: 800 | D13: 900 | E13: 900 | F13: 400 | G13: 600 | H13: 900 | I13: 1000 | J13: 1000 | K13: 900 | L13: 1300 | N13: =SUM(D13:L13) -> 7900 | O13: =IFERROR(VLOOKUP(B13,'[1]26.02W (1월생판)'!$G$7:$AP$298,36,0),0) -> 8700 | P13: =+N13-O13 -> -800 | R13: =SUM(D13:L13) -> 7900
B14: 1230692 | C14: 688 | D14: 1000 | E14: 1000 | F14: 0 | G14: 1000 | H14: 700 | I14: 600 | J14: 700 | K14: 600 | L14: 1400 | N14: =SUM(D14:L14) -> 7000 | O14: =IFERROR(VLOOKUP(B14,'[1]26.02W (1월생판)'!$G$7:$AP$298,36,0),0) -> 7988 | P14: =+N14-O14 -> -988 | Q14: 유구 | R14: =SUM(D14:L14) -> 7000
B15: 1230696 | C15: 24 | D15: 200 | E15: 200 | F15: 200 | G15: 0 | H15: 0 | I15: 200 | J15: 200 | K15: 0 | L15: 0 | N15: =SUM(D15:L15) -> 1000 | O15: =IFERROR(VLOOKUP(B15,'[1]26.02W (1월생판)'!$G$7:$AP$298,36,0),0) -> 1024 | P15: =+N15-O15 -> -24 | R15: =SUM(D15:L15) -> 1000
B16: 1230854 | C16: 0 | D16: 0 | E16: 200 | F16: 0 | G16: 0 | H16: 0 | I16: 0 | J16: 200 | K16: 0 | L16: 0 | N16: =SUM(D16:L16) -> 400 | O16: =IFERROR(VLOOKUP(B16,'[1]26.02W (1월생판)'!$G$7:$AP$298,36,0),0) -> 400 | P16: =+N16-O16 -> 0 | R16: =SUM(D16:L16) -> 400
B17: 1231202 | C17: 0 | D17: 0 | E17: 0 | F17: 0 | G17: 0 | H17: 150 | I17: 0 | J17: 0 | K17: 0 | L17: 0 | N17: =SUM(D17:L17) -> 150 | O17: =IFERROR(VLOOKUP(B17,'[1]26.02W (1월생판)'!$G$7:$AP$298,36,0),0) -> 150 | P17: =+N17-O17 -> 0 | R17: =SUM(D17:L17) -> 150
B18: 1231898 | C18: 2240 | D18: 1792 | E18: 2240 | F18: 1912 | G18: 1344 | H18: 1344 | I18: 1792 | J18: 1792 | K18: 1792 | L18: 2240 | N18: =SUM(D18:L18) -> 16248 | O18: =IFERROR(VLOOKUP(B18,'[1]26.02W (1월생판)'!$G$7:$AP$298,36,0),0) -> 18488 | P18: =+N18-O18 -> -2240 | R18: =SUM(D18:L18) -> 16248
B19: 1232693 | C19: 1396 | D19: 0 | E19: 1397 | F19: 0 | G19: 0 | H19: 1407 | I19: 0 | J19: 0 | K19: 1407 | L19: 2793 | N19: =SUM(D19:L19) -> 7004 | O19: =IFERROR(VLOOKUP(B19,'[1]26.02W (1월생판)'!$G$7:$AP$298,36,0),0) -> 8456 | P19: =+N19-O19 -> -1452 | Q19: 유구 | R19: =SUM(D19:L19) -> 7004
B20: 1233025 | C20: 1396 | D20: 0 | E20: 1397 | F20: 0 | G20: 0 | H20: 1407 | I20: 0 | J20: 0 | K20: 1407 | L20: 2793 | N20: =SUM(D20:L20) -> 7004 | O20: =IFERROR(VLOOKUP(B20,'[1]26.02W (1월생판)'!$G$7:$AP$298,36,0),0) -> 8456 | P20: =+N20-O20 -> -1452 | Q20: 유구 | R20: =SUM(D20:L20) -> 7004
B21: 1233492 | C21: 0 | D21: 0 | E21: 0 | F21: 0 | G21: 0 | H21: 0 | I21: 0 | J21: 500 | K21: 0 | L21: 300 | N21: =SUM(D21:L21) -> 800 | O21: =IFERROR(VLOOKUP(B21,'[1]26.02W (1월생판)'!$G$7:$AP$298,36,0),0) -> 800 | P21: =+N21-O21 -> 0 | R21: =SUM(D21:L21) -> 800
B22: 1233498 | C22: 0 | D22: 0 | E22: 0 | F22: 0 | G22: 0 | H22: 0 | I22: 0 | J22: 500 | K22: 0 | L22: 300 | N22: =SUM(D22:L22) -> 800 | O22: =IFERROR(VLOOKUP(B22,'[1]26.02W (1월생판)'!$G$7:$AP$298,36,0),0) -> 800 | P22: =+N22-O22 -> 0 | R22: =SUM(D22:L22) -> 800
B23: 1233623 | C23: 0 | D23: 0 | E23: 0 | F23: 0 | G23: 0 | H23: 0 | I23: 0 | J23: 500 | K23: 0 | L23: 300 | N23: =SUM(D23:L23) -> 800 | O23: =IFERROR(VLOOKUP(B23,'[1]26.02W (1월생판)'!$G$7:$AP$298,36,0),0) -> 800 | P23: =+N23-O23 -> 0 | R23: =SUM(D23:L23) -> 800
B24: 1233632 | C24: 401 | D24: 0 | E24: 0 | F24: 0 | G24: 0 | H24: 0 | I24: 0 | J24: 0 | K24: 0 | L24: 0 | N24: =SUM(D24:L24) -> 0 | O24: =IFERROR(VLOOKUP(B24,'[1]26.02W (1월생판)'!$G$7:$AP$298,36,0),0) -> 401 | P24: =+N24-O24 -> -401 | R24: =SUM(D24:L24) -> 0
B25: 1233761 | C25: 0 | D25: 200 | E25: 350 | F25: 0 | G25: 200 | H25: 0 | I25: 200 | J25: 0 | K25: 250 | L25: 200 | N25: =SUM(D25:L25) -> 1400 | O25: =IFERROR(VLOOKUP(B25,'[1]26.02W (1월생판)'!$G$7:$AP$298,36,0),0) -> 1400 | P25: =+N25-O25 -> 0 | R25: =SUM(D25:L25) -> 1400
B26: 1233877 | C26: 0 | D26: 0 | E26: 0 | F26: 0 | G26: 0 | H26: 120 | I26: 0 | J26: 0 | K26: 0 | L26: 0 | N26: =SUM(D26:L26) -> 120 | O26: =IFERROR(VLOOKUP(B26,'[1]26.02W (1월생판)'!$G$7:$AP$298,36,0),0) -> 120 | P26: =+N26-O26 -> 0 | R26: =SUM(D26:L26) -> 120
B27: 1234614 | C27: 0 | D27: 0 | E27: 0 | F27: 0 | G27: 0 | H27: 0 | I27: 400 | J27: 400 | K27: 0 | L27: 300 | N27: =SUM(D27:L27) -> 1100 | O27: =IFERROR(VLOOKUP(B27,'[1]26.02W (1월생판)'!$G$7:$AP$298,36,0),0) -> 1100 | P27: =+N27-O27 -> 0 | R27: =SUM(D27:L27) -> 1100
B28: 1235003 | C28: 2068 | D28: 900 | E28: 1350 | F28: 550 | G28: 650 | H28: 600 | I28: 1300 | J28: 1350 | K28: 950 | L28: 1150 | N28: =SUM(D28:L28) -> 8800 | O28: =IFERROR(VLOOKUP(B28,'[1]26.02W (1월생판)'!$G$7:$AP$298,36,0),0) -> 10868 | P28: =+N28-O28 -> -2068 | R28: =SUM(D28:L28) -> 8800
B29: 1235058 | C29: 320 | D29: 150 | E29: 200 | F29: 100 | G29: 100 | H29: 0 | I29: 250 | J29: 250 | K29: 250 | L29: 150 | N29: =SUM(D29:L29) -> 1450 | O29: =IFERROR(VLOOKUP(B29,'[1]26.02W (1월생판)'!$G$7:$AP$298,36,0),0) -> 1770 | P29: =+N29-O29 -> -320 | R29: =SUM(D29:L29) -> 1450
B30: 1235623 | C30: 0 | D30: 936 | E30: 936 | F30: 0 | G30: 0 | H30: 0 | I30: 0 | J30: 2808 | K30: 0 | L30: 0 | N30: =SUM(D30:L30) -> 4680 | O30: =IFERROR(VLOOKUP(B30,'[1]26.02W (1월생판)'!$G$7:$AP$298,36,0),0) -> 4680 | P30: =+N30-O30 -> 0 | R30: =SUM(D30:L30) -> 4680
B31: 1236091 | C31: 0 | D31: 200 | E31: 250 | F31: 0 | G31: 200 | H31: 0 | I31: 300 | J31: 350 | K31: 0 | L31: 0 | N31: =SUM(D31:L31) -> 1300 | O31: =IFERROR(VLOOKUP(B31,'[1]26.02W (1월생판)'!$G$7:$AP$298,36,0),0) -> 1300 | P31: =+N31-O31 -> 0 | R31: =SUM(D31:L31) -> 1300
B32: 1236488 | C32: 112 | D32: 800 | E32: 800 | F32: 500 | G32: 800 | H32: 1200 | I32: 1300 | J32: 1200 | K32: 1300 | L32: 900 | N32: =SUM(D32:L32) -> 8800 | O32: =IFERROR(VLOOKUP(B32,'[1]26.02W (1월생판)'!$G$7:$AP$298,36,0),0) -> 8912 | P32: =+N32-O32 -> -112 | R32: =SUM(D32:L32) -> 8800
... B41: 1239988 | C41: 1600 | D41: 750 | E41: 742 | F41: 300 | G41: 450 | H41: 400 | I41: 600 | J41: 1200 | K41: 1000 | L41: 800 | N41: =SUM(D41:L41) -> 6242 | O41: =IFERROR(VLOOKUP(B41,'[1]26.02W (1월생판)'!$G$7:$AP$298,36,0),0) -> 7842 | P41: =+N41-O41 -> -1600 | R41: =SUM(D41:L41) -> 6242
B42: 1240180 | C42: 1504 | D42: 286 | E42: 746 | F42: 738 | G42: 0 | H42: 1312 | I42: 1684 | J42: 2050 | K42: 1584 | L42: 1000 | N42: =SUM(D42:L42) -> 9400 | O42: =IFERROR(VLOOKUP(B42,'[1]26.02W (1월생판)'!$G$7:$AP$298,36,0),0) -> 12674 | P42: =+N42-O42 -> -3274 | Q42: 유구 | R42: =SUM(D42:L42) -> 9400
B43: 1240184 | C43: 1504 | D43: 286 | E43: 596 | F43: 438 | G43: 0 | H43: 1312 | I43: 1534 | J43: 1750 | K43: 1584 | L43: 900 | N43: =SUM(D43:L43) -> 8400 | O43: =IFERROR(VLOOKUP(B43,'[1]26.02W (1월생판)'!$G$7:$AP$298,36,0),0) -> 11674 | P43: =+N43-O43 -> -3274 | Q43: 유구 | R43: =SUM(D43:L43) -> 8400
B44: 1240308 | C44: 750 | D44: 750 | E44: 850 | F44: 200 | G44: 600 | H44: 350 | I44: 750 | J44: 650 | K44: 550 | L44: 450 | N44: =SUM(D44:L44) -> 5150 | O44: =IFERROR(VLOOKUP(B44,'[1]26.02W (1월생판)'!$G$7:$AP$298,36,0),0) -> 5900 | P44: =+N44-O44 -> -750 | R44: =SUM(D44:L44) -> 5150
B45: 1241134 | C45: 0 | D45: 0 | E45: 0 | F45: 0 | G45: 0 | H45: 0 | I45: 0 | J45: 0 | K45: 0 | L45: 1900 | N45: =SUM(D45:L45) -> 1900 | O45: =IFERROR(VLOOKUP(B45,'[1]26.02W (1월생판)'!$G$7:$AP$298,36,0),0) -> 1900 | P45: =+N45-O45 -> 0 | R45: =SUM(D45:L45) -> 1900
B46: 1241601 | C46: 0 | D46: 4900 | E46: 5000 | F46: 2400 | G46: 4400 | H46: 3800 | I46: 4100 | J46: 3100 | K46: 4000 | L46: 4700 | N46: =SUM(D46:L46) -> 36400 | O46: =IFERROR(VLOOKUP(B46,'[1]26.02W (1월생판)'!$G$7:$AP$298,36,0),0) -> 36400 | P46: =+N46-O46 -> 0 | R46: =SUM(D46:L46) -> 36400
B47: 3104649 | C47: 24 | D47: 0 | E47: 0 | F47: 0 | G47: 0 | H47: 24 | I47: 0 | J47: 0 | K47: 24 | L47: 0 | N47: =SUM(C47:L47) -> 72 | O47: =IFERROR(VLOOKUP(B47,'[1]26.02W (1월생판)'!$G$7:$AP$298,36,0),0) -> 0 | P47: =+N47-O47 -> 72 | R47: =SUM(D47:L47) -> 48
B48: 3105058 | C48: 0 | D48: 0 | E48: 0 | F48: 0 | G48: 0 | H48: 24 | I48: 48 | J48: 72 | K48: 48 | L48: 72 | N48: =SUM(C48:L48) -> 264 | O48: =IFERROR(VLOOKUP(B48,'[1]26.02W (1월생판)'!$G$7:$AP$298,36,0),0) -> 0 | P48: =+N48-O48 -> 264 | R48: =SUM(D48:L48) -> 264
B49: 3106127 | C49: 0 | D49: 24 | E49: 0 | F49: 0 | G49: 0 | H49: 0 | I49: 12 | J49: 0 | K49: 0 | L49: 0 | N49: =SUM(C49:L49) -> 36 | O49: =IFERROR(VLOOKUP(B49,'[1]26.02W (1월생판)'!$G$7:$AP$298,36,0),0) -> 0 | P49: =+N49-O49 -> 36 | R49: =SUM(D49:L49) -> 36
...

Sheet 0108
A1: 품번 | B1: 01/08(목) | C1: 01/09(금) | D1: 01/10(토) | E1: 01/11(일) | F1: 01/12(월) | G1: 01/13(화) | H1: 01/14(수) | I1: 01/15(목) | J1: 01/16(금) | K1: 01/17(토) | L1: 01/18(일) | M1: 01/19(월) | N1: 01/20(화) | O1: 01/21(수) | P1: 01/22(목) | Q1: 01/23(금) | R1: 01/24(토) | S1: 01/25(일)
A2: 1221154 | B2: 0 | C2: 0 | D2: 0 | E2: 0 | F2: 0 | G2: 0 | H2: 50 | I2: 0 | J2: 0 | K2: 0 | L2: 0 | M2: 0 | N2: 0 | O2: 0 | P2: 0 | Q2: 0 | R2: 0 | S2: 0
A3: 1234614 | B3: 0 | C3: 0 | D3: 0 | E3: 0 | F3: 0 | G3: 0 | H3: 352 | I3: 50 | J3: 0 | K3: 0 | L3: 0 | M3: 0 | N3: 0 | O3: 354 | P3: 516 | Q3: 0 | R3: 0 | S3: 0
A4: 1226384 | B4: 0 | C4: 0 | D4: 0 | E4: 0 | F4: 360 | G4: 100 | H4: 400 | I4: 0 | J4: 0 | K4: 0 | L4: 0 | M4: 0 | N4: 0 | O4: 0 | P4: 0 | Q4: 0 | R4: 0 | S4: 0
A5: 1226388 | B5: 0 | C5: 0 | D5: 0 | E5: 0 | F5: 360 | G5: 100 | H5: 400 | I5: 0 | J5: 0 | K5: 0 | L5: 0 | M5: 0 | N5: 0 | O5: 0 | P5: 0 | Q5: 0 | R5: 0 | S5: 0
A6: 1229673 | B6: 200 | C6: 242 | D6: 0 | E6: 0 | F6: 250 | G6: 250 | H6: 250 | I6: 250 | J6: 200 | K6: 0 | L6: 0 | M6: 300 | N6: 200 | O6: 200 | P6: 200 | Q6: 300 | R6: 0 | S6: 0
A7: 1230854 | B7: 0 | C7: 0 | D7: 0 | E7: 0 | F7: 200 | G7: 0 | H7: 0 | I7: 0 | J7: 0 | K7: 0 | L7: 0 | M7: 0 | N7: 0 | O7: 0 | P7: 0 | Q7: 0 | R7: 0 | S7: 0
A8: 1233632 | B8: 346 | C8: 330 | D8: 0 | E8: 0 | F8: 406 | G8: 0 | H8: 0 | I8: 0 | J8: 0 | K8: 0 | L8: 0 | M8: 0 | N8: 0 | O8: 0 | P8: 0 | Q8: 0 | R8: 0 | S8: 0
A9: 1237088 | B9: 1286 | C9: 1570 | D9: 0 | E9: 0 | F9: 1276 | G9: 906 | H9: 1006 | I9: 942 | J9: 1496 | K9: 0 | L9: 0 | M9: 1388 | N9: 724 | O9: 928 | P9: 524 | Q9: 1129 | R9: 0 | S9: 0
A10: 1237748 | B10: 260 | C10: 0 | D10: 0 | E10: 0 | F10: 0 | G10: 0 | H10: 0 | I10: 0 | J10: 0 | K10: 0 | L10: 0 | M10: 0 | N10: 0 | O10: 0 | P10: 0 | Q10: 0 | R10: 0 | S10: 0
A11: 1236091 | B11: 0 | C11: 0 | D11: 0 | E11: 0 | F11: 0 | G11: 0 | H11: 200 | I11: 0 | J11: 0 | K11: 0 | L11: 0 | M11: 0 | N11: 0 | O11: 0 | P11: 0 | Q11: 0 | R11: 0 | S11: 0
A12: 1238128 | B12: 404 | C12: 377 | D12: 0 | E12: 0 | F12: 480 | G12: 480 | H12: 378 | I12: 912 | J12: 960 | K12: 0 | L12: 0 | M12: 546 | N12: 480 | O12: 378 | P12: 480 | Q12: 378 | R12: 0 | S12: 0
A13: 1236962 | B13: 400 | C13: 400 | D13: 0 | E13: 0 | F13: 250 | G13: 250 | H13: 0 | I13: 250 | J13: 250 | K13: 0 | L13: 0 | M13: 200 | N13: 400 | O13: 200 | P13: 200 | Q13: 300 | R13: 0 | S13: 0
... A19: 1240308 | B19: 250 | C19: 0 | D19: 0 | E19: 0 | F19: 0 | G19: 200 | H19: 0 | I19: 350 | J19: 200 | K19: 0 | L19: 0 | M19: 0 | N19: 450 | O19: 300 | P19: 0 | Q19: 0 | R19: 0 | S19: 0
A22: 품번 | B22: 01/08(목) | C22: 01/09(금) | D22: 01/10(토) | E22: 01/11(일) | F22: 01/12(월) | G22: 01/13(화) | H22: 01/14(수) | I22: 01/15(목) | J22: 01/16(금) | K22: 01/17(토) | L22: 01/18(일) | M22: 01/19(월) | N22: 01/20(화) | O22: 01/21(수) | P22: 01/22(목) | Q22: 01/23(금) | R22: 01/24(토) | S22: 01/25(일)
A23: 1237608 | B23: 0 | C23: 0 | D23: 0 | E23: 0 | F23: 0 | G23: 350 | H23: 250 | I23: 0 | J23: 0 | K23: 0 | L23: 0 | M23: 0 | N23: 0 | O23: 0 | P23: 0 | Q23: 0 | R23: 0 | S23: 0
A24: 1232846 | B24: 0 | C24: 0 | D24: 0 | E24: 0 | F24: 0 | G24: 327 | H24: 352 | I24: 21 | J24: 0 | K24: 0 | L24: 0 | M24: 0 | N24: 403 | O24: 352 | P24: 449 | Q24: 7 | R24: 0 | S24: 0
A25: 1232895 | B25: 0 | C25: 0 | D25: 0 | E25: 0 | F25: 0 | G25: 327 | H25: 352 | I25: 21 | J25: 0 | K25: 0 | L25: 0 | M25: 0 | N25: 403 | O25: 352 | P25: 449 | Q25: 7 | R25: 0 | S25: 0
A26: 1233384 | B26: 0 | C26: 0 | D26: 0 | E26: 0 | F26: 0 | G26: 327 | H26: 352 | I26: 21 | J26: 0 | K26: 0 | L26: 0 | M26: 0 | N26: 403 | O26: 352 | P26: 449 | Q26: 7 | R26: 0 | S26: 0
A27: 1233165 | B27: 0 | C27: 0 | D27: 0 | E27: 0 | F27: 0 | G27: 0 | H27: 0 | I27: 0 | J27: 0 | K27: 0 | L27: 0 | M27: 0 | N27: 0 | O27: 0 | P27: 0 | Q27: 250 | R27: 0 | S27: 0
A28: 1236387 | B28: 395 | C28: 0 | D28: 0 | E28: 0 | F28: 0 | G28: 0 | H28: 0 | I28: 0 | J28: 0 | K28: 0 | L28: 0 | M28: 411 | N28: 325 | O28: 0 | P28: 0 | Q28: 0 | R28: 0 | S28: 0
A29: 1232775 | B29: 311 | C29: 14 | D29: 0 | E29: 0 | F29: 0 | G29: 288 | H29: 243 | I29: 309 | J29: 309 | K29: 0 | L29: 0 | M29: 298 | N29: 8 | O29: 0 | P29: 0 | Q29: 0 | R29: 0 | S29: 0
A30: 1238605 | B30: 0 | C30: 189 | D30: 0 | E30: 0 | F30: 238 | G30: 6 | H30: 0 | I30: 0 | J30: 0 | K30: 0 | L30: 0 | M30: 0 | N30: 42 | O30: 187 | P30: 182 | Q30: 4 | R30: 0 | S30: 0
A34: 품번 | B34: 01/08(목) | C34: 01/09(금) | D34: 01/10(토) | E34: 01/11(일) | F34: 01/12(월) | G34: 01/13(화) | H34: 01/14(수) | I34: 01/15(목) | J34: 01/16(금) | K34: 01/17(토) | L34: 01/18(일) | M34: 01/19(월) | N34: 01/20(화) | O34: 01/21(수) | P34: 01/22(목) | Q34: 01/23(금) | R34: 01/24(토) | S34: 01/25(일)
A35: 1230692 | B35: 0 | C35: 0 | D35: 0 | E35: 0 | F35: 0 | G35: 0 | H35: 0 | I35: 0 | J35: 0 | K35: 0 | L35: 0 | M35: 0 | N35: 0 | O35: 0 | P35: 100 | Q35: 0 | R35: 0 | S35: 0
A36: 1221967 | B36: 0 | C36: 0 | D36: 0 | E36: 0 | F36: 0 | G36: 0 | H36: 176 | I36: 0 | J36: 0 | K36: 0 | L36: 0 | M36: 0 | N36: 0 | O36: 0 | P36: 0 | Q36: 0 | R36: 0 | S36: 0
A37: 1227306 | B37: 123 | C37: 0 | D37: 0 | E37: 0 | F37: 0 | G37: 0 | H37: 0 | I37: 0 | J37: 0 | K37: 0 | L37: 0 | M37: 150 | N37: 500 | O37: 600 | P37: 0 | Q37: 0 | R37: 0 | S37: 0
A38: 1227359 | B38: 86 | C38: 0 | D38: 0 | E38: 0 | F38: 0 | G38: 0 | H38: 0 | I38: 0 | J38: 0 | K38: 0 | L38: 0 | M38: 0 | N38: 0 | O38: 0 | P38: 0 | Q38: 0 | R38: 0 | S38: 0
A39: 1229088 | B39: 0 | C39: 0 | D39: 0 | E39: 0 | F39: 0 | G39: 490 | H39: 0 | I39: 0 | J39: 0 | K39: 0 | L39: 0 | M39: 0 | N39: 0 | O39: 0 | P39: 0 | Q39: 0 | R39: 0 | S39: 0
A40: 1231090 | B40: 0 | C40: 0 | D40: 0 | E40: 0 | F40: 0 | G40: 0 | H40: 0 | I40: 0 | J40: 0 | K40: 0 | L40: 0 | M40: 200 | N40: 0 | O40: 0 | P40: 0 | Q40: 0 | R40: 0 | S40: 0
A41: 1229776 | B41: 0 | C41: 0 | D41: 0 | E41: 0 | F41: 0 | G41: 0 | H41: 0 | I41: 0 | J41: 0 | K41: 0 | L41: 0 | M41: 200 | N41: 0 | O41: 0 | P41: 0 | Q41: 0 | R41: 0 | S41: 0
A42: 1231797 | B42: 0 | C42: 0 | D42: 0 | E42: 0 | F42: 0 | G42: 113 | H42: 0 | I42: 0 | J42: 0 | K42: 0 | L42: 0 | M42: 0 | N42: 0 | O42: 0 | P42: 0 | Q42: 0 | R42: 0 | S42: 0
A43: 1225464 | B43: 0 | C43: 0 | D43: 0 | E43: 0 | F43: 0 | G43: 0 | H43: 0 | I43: 0 | J43: 0 | K43: 0 | L43: 0 | M43: 0 | N43: 0 | O43: 0 | P43: 0 | Q43: 28 | R43: 0 | S43: 0
A44: 1234222 | B44: 0 | C44: 0 | D44: 0 | E44: 0 | F44: 0 | G44: 0 | H44: 0 | I44: 0 | J44: 0 | K44: 0 | L44: 0 | M44: 0 | N44: 220 | O44: 258 | P44: 0 | Q44: 0 | R44: 0 | S44: 0
A45: 1232528 | B45: 0 | C45: 0 | D45: 0 | E45: 0 | F45: 161 | G45: 686 | H45: 539 | I45: 651 | J45: 0 | K45: 0 | L45: 0 | M45: 0 | N45: 0 | O45: 0 | P45: 0 | Q45: 147 | R45: 0 | S45: 0
A46: 1233587 | B46: 0 | C46: 0 | D46: 0 | E46: 0 | F46: 0 | G46: 0 | H46: 10 | I46: 0 | J46: 0 | K46: 0 | L46: 0 | M46: 0 | N46: 0 | O46: 0 | P46: 0 | Q46: 0 | R46: 0 | S46: 0
... A79: 1233580 | B79: 0 | C79: 0 | D79: 0 | E79: 0 | F79: 0 | G79: 0 | H79: 0 | I79: 0 | J79: 0 | K79: 0 | L79: 0 | M79: 130 | N79: 0 | O79: 0 | P79: 0 | Q79: 0 | R79: 0 | S79: 0

Sheet 0109
A1: 품번 | B1: 01/09(금) | C1: 01/10(토) | D1: 01/11(일) | E1: 01/12(월) | F1: 01/13(화) | G1: 01/14(수) | H1: 01/15(목) | I1: 01/16(금) | J1: 01/17(토) | K1: 01/18(일) | L1: 01/19(월) | M1: 01/20(화) | N1: 01/21(수) | O1: 01/22(목) | P1: 01/23(금) | Q1: 01/24(토) | R1: 01/25(일)
A2: 1221154 | B2: 0 | C2: 0 | D2: 0 | E2: 0 | F2: 0 | G2: 50 | H2: 0 | I2: 0 | J2: 0 | K2: 0 | L2: 0 | M2: 0 | N2: 0 | O2: 0 | P2: 0 | Q2: 0 | R2: 0
A3: 1234614 | B3: 0 | C3: 0 | D3: 0 | E3: 0 | F3: 0 | G3: 352 | H3: 50 | I3: 0 | J3: 0 | K3: 0 | L3: 0 | M3: 0 | N3: 354 | O3: 516 | P3: 0 | Q3: 0 | R3: 0
A4: 1226384 | B4: 0 | C4: 0 | D4: 0 | E4: 360 | F4: 100 | G4: 400 | H4: 0 | I4: 0 | J4: 0 | K4: 0 | L4: 0 | M4: 0 | N4: 0 | O4: 0 | P4: 0 | Q4: 0 | R4: 0
A5: 1226388 | B5: 0 | C5: 0 | D5: 0 | E5: 360 | F5: 100 | G5: 400 | H5: 0 | I5: 0 | J5: 0 | K5: 0 | L5: 0 | M5: 0 | N5: 0 | O5: 0 | P5: 0 | Q5: 0 | R5: 0
A6: 1229673 | B6: 242 | C6: 0 | D6: 0 | E6: 250 | F6: 250 | G6: 250 | H6: 250 | I6: 200 | J6: 0 | K6: 0 | L6: 300 | M6: 200 | N6: 200 | O6: 200 | P6: 300 | Q6: 0 | R6: 0
A7: 1230854 | B7: 0 | C7: 0 | D7: 0 | E7: 200 | F7: 0 | G7: 0 | H7: 0 | I7: 0 | J7: 0 | K7: 0 | L7: 0 | M7: 0 | N7: 0 | O7: 0 | P7: 0 | Q7: 0 | R7: 0
A8: 1233632 | B8: 330 | C8: 0 | D8: 0 | E8: 406 | F8: 0 | G8: 0 | H8: 0 | I8: 0 | J8: 0 | K8: 0 | L8: 0 | M8: 0 | N8: 0 | O8: 0 | P8: 0 | Q8: 0 | R8: 0
A9: 1237088 | B9: 1570 | C9: 0 | D9: 0 | E9: 1276 | F9: 906 | G9: 1006 | H9: 942 | I9: 1496 | J9: 0 | K9: 0 | L9: 1388 | M9: 724 | N9: 928 | O9: 524 | P9: 1129 | Q9: 0 | R9: 0
A10: 1236091 | B10: 0 | C10: 0 | D10: 0 | E10: 0 | F10: 0 | G10: 200 | H10: 0 | I10: 0 | J10: 0 | K10: 0 | L10: 0 | M10: 0 | N10: 0 | O10: 0 | P10: 0 | Q10: 0 | R10: 0
A11: 1238128 | B11: 377 | C11: 0 | D11: 0 | E11: 480 | F11: 480 | G11: 378 | H11: 912 | I11: 960 | J11: 0 | K11: 0 | L11: 546 | M11: 480 | N11: 378 | O11: 480 | P11: 378 | Q11: 0 | R11: 0
A12: 1236962 | B12: 400 | C12: 0 | D12: 0 | E12: 250 | F12: 250 | G12: 0 | H12: 250 | I12: 250 | J12: 0 | K12: 0 | L12: 200 | M12: 400 | N12: 200 | O12: 200 | P12: 300 | Q12: 0 | R12: 0
A13: 1233761 | B13: 0 | C13: 0 | D13: 0 | E13: 0 | F13: 0 | G13: 0 | H13: 250 | I13: 0 | J13: 0 | K13: 0 | L13: 0 | M13: 0 | N13: 0 | O13: 150 | P13: 0 | Q13: 0 | R13: 0
... A18: 1240308 | B18: 0 | C18: 0 | D18: 0 | E18: 0 | F18: 200 | G18: 0 | H18: 350 | I18: 200 | J18: 0 | K18: 0 | L18: 0 | M18: 450 | N18: 300 | O18: 0 | P18: 0 | Q18: 0 | R18: 0
A22: 품번 | B22: 01/09(금) | C22: 01/10(토) | D22: 01/11(일) | E22: 01/12(월) | F22: 01/13(화) | G22: 01/14(수) | H22: 01/15(목) | I22: 01/16(금) | J22: 01/17(토) | K22: 01/18(일) | L22: 01/19(월) | M22: 01/20(화) | N22: 01/21(수) | O22: 01/22(목) | P22: 01/23(금) | Q22: 01/24(토) | R22: 01/25(일)
A23: 1237608 | B23: 0 | C23: 0 | D23: 0 | E23: 0 | F23: 350 | G23: 250 | H23: 0 | I23: 0 | J23: 0 | K23: 0 | L23: 0 | M23: 0 | N23: 0 | O23: 0 | P23: 0 | Q23: 0 | R23: 0
A24: 1232846 | B24: 0 | C24: 0 | D24: 0 | E24: 0 | F24: 327 | G24: 352 | H24: 21 | I24: 0 | J24: 0 | K24: 0 | L24: 0 | M24: 403 | N24: 352 | O24: 449 | P24: 7 | Q24: 0 | R24: 0
A25: 1232895 | B25: 0 | C25: 0 | D25: 0 | E25: 0 | F25: 327 | G25: 352 | H25: 21 | I25: 0 | J25: 0 | K25: 0 | L25: 0 | M25: 403 | N25: 352 | O25: 449 | P25: 7 | Q25: 0 | R25: 0
A26: 1233384 | B26: 0 | C26: 0 | D26: 0 | E26: 0 | F26: 327 | G26: 352 | H26: 21 | I26: 0 | J26: 0 | K26: 0 | L26: 0 | M26: 403 | N26: 352 | O26: 449 | P26: 7 | Q26: 0 | R26: 0
A27: 1233165 | B27: 0 | C27: 0 | D27: 0 | E27: 0 | F27: 0 | G27: 0 | H27: 0 | I27: 0 | J27: 0 | K27: 0 | L27: 0 | M27: 0 | N27: 0 | O27: 0 | P27: 250 | Q27: 0 | R27: 0
A28: 1236387 | B28: 0 | C28: 0 | D28: 0 | E28: 0 | F28: 0 | G28: 0 | H28: 0 | I28: 0 | J28: 0 | K28: 0 | L28: 411 | M28: 325 | N28: 0 | O28: 0 | P28: 0 | Q28: 0 | R28: 0
A29: 1232775 | B29: 14 | C29: 0 | D29: 0 | E29: 0 | F29: 288 | G29: 243 | H29: 309 | I29: 309 | J29: 0 | K29: 0 | L29: 298 | M29: 8 | N29: 0 | O29: 0 | P29: 0 | Q29: 0 | R29: 0
A30: 1238605 | B30: 189 | C30: 0 | D30: 0 | E30: 238 | F30: 6 | G30: 0 | H30: 0 | I30: 0 | J30: 0 | K30: 0 | L30: 0 | M30: 42 | N30: 187 | O30: 182 | P30: 4 | Q30: 0 | R30: 0
A34: 품번 | B34: 01/09(금) | C34: 01/10(토) | D34: 01/11(일) | E34: 01/12(월) | F34: 01/13(화) | G34: 01/14(수) | H34: 01/15(목) | I34: 01/16(금) | J34: 01/17(토) | K34: 01/18(일) | L34: 01/19(월) | M34: 01/20(화) | N34: 01/21(수) | O34: 01/22(목) | P34: 01/23(금) | Q34: 01/24(토) | R34: 01/25(일)
A35: 1230692 | B35: 0 | C35: 0 | D35: 0 | E35: 0 | F35: 0 | G35: 0 | H35: 0 | I35: 0 | J35: 0 | K35: 0 | L35: 0 | M35: 0 | N35: 0 | O35: 100 | P35: 0 | Q35: 0 | R35: 0
A36: 1221967 | B36: 0 | C36: 0 | D36: 0 | E36: 0 | F36: 0 | G36: 176 | H36: 0 | I36: 0 | J36: 0 | K36: 0 | L36: 0 | M36: 0 | N36: 0 | O36: 0 | P36: 0 | Q36: 0 | R36: 0
A37: 1227306 | B37: 0 | C37: 0 | D37: 0 | E37: 0 | F37: 0 | G37: 0 | H37: 0 | I37: 0 | J37: 0 | K37: 0 | L37: 150 | M37: 500 | N37: 600 | O37: 0 | P37: 0 | Q37: 0 | R37: 0
A38: 1229088 | B38: 0 | C38: 0 | D38: 0 | E38: 0 | F38: 490 | G38: 0 | H38: 0 | I38: 0 | J38: 0 | K38: 0 | L38: 0 | M38: 0 | N38: 0 | O38: 0 | P38: 0 | Q38: 0 | R38: 0
A39: 1231090 | B39: 0 | C39: 0 | D39: 0 | E39: 0 | F39: 0 | G39: 0 | H39: 0 | I39: 0 | J39: 0 | K39: 0 | L39: 200 | M39: 0 | N39: 0 | O39: 0 | P39: 0 | Q39: 0 | R39: 0
A40: 1229776 | B40: 0 | C40: 0 | D40: 0 | E40: 0 | F40: 0 | G40: 0 | H40: 0 | I40: 0 | J40: 0 | K40: 0 | L40: 200 | M40: 0 | N40: 0 | O40: 0 | P40: 0 | Q40: 0 | R40: 0
A41: 1231797 | B41: 0 | C41: 0 | D41: 0 | E41: 0 | F41: 113 | G41: 0 | H41: 0 | I41: 0 | J41: 0 | K41: 0 | L41: 0 | M41: 0 | N41: 0 | O41: 0 | P41: 0 | Q41: 0 | R41: 0
A42: 1225464 | B42: 0 | C42: 0 | D42: 0 | E42: 0 | F42: 0 | G42: 0 | H42: 0 | I42: 0 | J42: 0 | K42: 0 | L42: 0 | M42: 0 | N42: 0 | O42: 0 | P42: 28 | Q42: 0 | R42: 0
A43: 1234222 | B43: 0 | C43: 0 | D43: 0 | E43: 0 | F43: 0 | G43: 0 | H43: 0 | I43: 0 | J43: 0 | K43: 0 | L43: 0 | M43: 220 | N43: 258 | O43: 0 | P43: 0 | Q43: 0 | R43: 0
A44: 1232528 | B44: 0 | C44: 0 | D44: 0 | E44: 161 | F44: 686 | G44: 539 | H44: 651 | I44: 0 | J44: 0 | K44: 0 | L44: 0 | M44: 0 | N44: 0 | O44: 0 | P44: 147 | Q44: 0 | R44: 0
A45: 1233587 | B45: 0 | C45: 0 | D45: 0 | E45: 0 | F45: 0 | G45: 10 | H45: 0 | I45: 0 | J45: 0 | K45: 0 | L45: 0 | M45: 0 | N45: 0 | O45: 0 | P45: 0 | Q45: 0 | R45: 0
A46: 1232846 | B46: 0 | C46: 0 | D46: 0 | E46: 0 | F46: 0 | G46: 0 | H46: 34 | I46: 142 | J46: 0 | K46: 0 | L46: 0 | M46: 0 | N46: 0 | O46: 0 | P46: 0 | Q46: 0 | R46: 0
... A77: 1233580 | B77: 0 | C77: 0 | D77: 0 | E77: 0 | F77: 0 | G77: 0 | H77: 0 | I77: 0 | J77: 0 | K77: 0 | L77: 130 | M77: 0 | N77: 0 | O77: 0 | P77: 0 | Q77: 0 | R77: 0

Sheet 0112
A1: 품번 | B1: 01/12(월) | C1: 01/13(화) | D1: 01/14(수) | E1: 01/15(목) | F1: 01/16(금) | G1: 01/17(토) | H1: 01/18(일) | I1: 01/19(월) | J1: 01/20(화) | K1: 01/21(수) | L1: 01/22(목) | M1: 01/23(금) | N1: 01/24(토) | O1: 01/25(일)
A2: 1221154 | B2: 0 | C2: 0 | D2: 50 | E2: 0 | F2: 0 | G2: 0 | H2: 0 | I2: 0 | J2: 0 | K2: 0 | L2: 0 | M2: 0 | N2: 0 | O2: 0
A3: 1234614 | B3: 0 | C3: 0 | D3: 352 | E3: 50 | F3: 0 | G3: 0 | H3: 0 | I3: 0 | J3: 0 | K3: 354 | L3: 516 | M3: 0 | N3: 0 | O3: 0
A4: 1226384 | B4: 360 | C4: 100 | D4: 400 | E4: 0 | F4: 0 | G4: 0 | H4: 0 | I4: 0 | J4: 0 | K4: 0 | L4: 0 | M4: 0 | N4: 0 | O4: 0
A5: 1226388 | B5: 360 | C5: 100 | D5: 400 | E5: 0 | F5: 0 | G5: 0 | H5: 0 | I5: 0 | J5: 0 | K5: 0 | L5: 0 | M5: 0 | N5: 0 | O5: 0
A6: 1229673 | B6: 250 | C6: 0 | D6: 0 | E6: 0 | F6: 0 | G6: 0 | H6: 0 | I6: 400 | J6: 400 | K6: 400 | L6: 400 | M6: 400 | N6: 0 | O6: 0
A7: 1230854 | B7: 200 | C7: 0 | D7: 0 | E7: 0 | F7: 0 | G7: 0 | H7: 0 | I7: 0 | J7: 0 | K7: 0 | L7: 0 | M7: 0 | N7: 0 | O7: 0
A8: 1233632 | B8: 406 | C8: 0 | D8: 0 | E8: 0 | F8: 0 | G8: 0 | H8: 0 | I8: 0 | J8: 0 | K8: 0 | L8: 0 | M8: 0 | N8: 0 | O8: 0
A9: 1237088 | B9: 1276 | C9: 1106 | D9: 1206 | E9: 1142 | F9: 1656 | G9: 0 | H9: 0 | I9: 1308 | J9: 564 | K9: 770 | L9: 350 | M9: 1043 | N9: 0 | O9: 0
A10: 1236091 | B10: 0 | C10: 0 | D10: 200 | E10: 0 | F10: 0 | G10: 0 | H10: 0 | I10: 0 | J10: 0 | K10: 0 | L10: 0 | M10: 0 | N10: 0 | O10: 0
A11: 1238128 | B11: 480 | C11: 480 | D11: 378 | E11: 912 | F11: 960 | G11: 0 | H11: 0 | I11: 546 | J11: 480 | K11: 378 | L11: 480 | M11: 378 | N11: 0 | O11: 0
A12: 1236962 | B12: 250 | C12: 250 | D12: 0 | E12: 250 | F12: 250 | G12: 0 | H12: 0 | I12: 200 | J12: 400 | K12: 200 | L12: 200 | M12: 300 | N12: 0 | O12: 0
A13: 1233761 | B13: 0 | C13: 0 | D13: 0 | E13: 250 | F13: 0 | G13: 0 | H13: 0 | I13: 0 | J13: 0 | K13: 0 | L13: 150 | M13: 0 | N13: 0 | O13: 0
... A18: 1240308 | B18: 0 | C18: 200 | D18: 0 | E18: 350 | F18: 200 | G18: 0 | H18: 0 | I18: 0 | J18: 450 | K18: 300 | L18: 0 | M18: 0 | N18: 0 | O18: 0
A22: 품번 | B22: 01/12(월) | C22: 01/13(화) | D22: 01/14(수) | E22: 01/15(목) | F22: 01/16(금) | G22: 01/17(토) | H22: 01/18(일) | I22: 01/19(월) | J22: 01/20(화) | K22: 01/21(수) | L22: 01/22(목) | M22: 01/23(금) | N22: 01/24(토) | O22: 01/25(일)
A23: 1237608 | B23: 0 | C23: 350 | D23: 250 | E23: 0 | F23: 0 | G23: 0 | H23: 0 | I23: 0 | J23: 0 | K23: 0 | L23: 0 | M23: 0 | N23: 0 | O23: 0
A24: 1232846 | B24: 0 | C24: 327 | D24: 352 | E24: 21 | F24: 0 | G24: 0 | H24: 0 | I24: 0 | J24: 403 | K24: 352 | L24: 449 | M24: 7 | N24: 0 | O24: 0
A25: 1232895 | B25: 0 | C25: 327 | D25: 352 | E25: 21 | F25: 0 | G25: 0 | H25: 0 | I25: 0 | J25: 403 | K25: 352 | L25: 449 | M25: 7 | N25: 0 | O25: 0
A26: 1233384 | B26: 0 | C26: 327 | D26: 352 | E26: 21 | F26: 0 | G26: 0 | H26: 0 | I26: 0 | J26: 403 | K26: 352 | L26: 449 | M26: 7 | N26: 0 | O26: 0
A27: 1233165 | B27: 0 | C27: 0 | D27: 0 | E27: 0 | F27: 0 | G27: 0 | H27: 0 | I27: 0 | J27: 0 | K27: 0 | L27: 0 | M27: 250 | N27: 0 | O27: 0
A28: 1236387 | B28: 0 | C28: 0 | D28: 0 | E28: 0 | F28: 0 | G28: 0 | H28: 0 | I28: 411 | J28: 325 | K28: 0 | L28: 0 | M28: 0 | N28: 0 | O28: 0
A29: 1232775 | B29: 0 | C29: 288 | D29: 243 | E29: 309 | F29: 309 | G29: 0 | H29: 0 | I29: 298 | J29: 8 | K29: 0 | L29: 0 | M29: 0 | N29: 0 | O29: 0
A30: 1238605 | B30: 238 | C30: 6 | D30: 0 | E30: 0 | F30: 0 | G30: 0 | H30: 0 | I30: 0 | J30: 42 | K30: 187 | L30: 182 | M30: 4 | N30: 0 | O30: 0
A35: 품번 | B35: 01/12(월) | C35: 01/13(화) | D35: 01/14(수) | E35: 01/15(목) | F35: 01/16(금) | G35: 01/17(토) | H35: 01/18(일) | I35: 01/19(월) | J35: 01/20(화) | K35: 01/21(수) | L35: 01/22(목) | M35: 01/23(금) | N35: 01/24(토) | O35: 01/25(일)
A36: 1230692 | B36: 0 | C36: 0 | D36: 0 | E36: 0 | F36: 0 | G36: 0 | H36: 0 | I36: 0 | J36: 0 | K36: 0 | L36: 100 | M36: 0 | N36: 0 | O36: 0
A37: 1221967 | B37: 0 | C37: 0 | D37: 176 | E37: 0 | F37: 0 | G37: 0 | H37: 0 | I37: 0 | J37: 0 | K37: 0 | L37: 0 | M37: 0 | N37: 0 | O37: 0
A38: 1227306 | B38: 0 | C38: 0 | D38: 0 | E38: 0 | F38: 0 | G38: 0 | H38: 0 | I38: 150 | J38: 500 | K38: 600 | L38: 0 | M38: 0 | N38: 0 | O38: 0
A39: 1229088 | B39: 0 | C39: 490 | D39: 0 | E39: 0 | F39: 0 | G39: 0 | H39: 0 | I39: 0 | J39: 0 | K39: 0 | L39: 0 | M39: 0 | N39: 0 | O39: 0
A40: 1231090 | B40: 0 | C40: 0 | D40: 0 | E40: 0 | F40: 0 | G40: 0 | H40: 0 | I40: 200 | J40: 0 | K40: 0 | L40: 0 | M40: 0 | N40: 0 | O40: 0
A41: 1229776 | B41: 0 | C41: 0 | D41: 0 | E41: 0 | F41: 0 | G41: 0 | H41: 0 | I41: 200 | J41: 0 | K41: 0 | L41: 0 | M41: 0 | N41: 0 | O41: 0
A42: 1231797 | B42: 0 | C42: 113 | D42: 0 | E42: 0 | F42: 0 | G42: 0 | H42: 0 | I42: 0 | J42: 0 | K42: 0 | L42: 0 | M42: 0 | N42: 0 | O42: 0
A43: 1225464 | B43: 0 | C43: 0 | D43: 0 | E43: 0 | F43: 0 | G43: 0 | H43: 0 | I43: 0 | J43: 0 | K43: 0 | L43: 0 | M43: 28 | N43: 0 | O43: 0
A44: 1234222 | B44: 0 | C44: 0 | D44: 0 | E44: 0 | F44: 0 | G44: 0 | H44: 0 | I44: 0 | J44: 220 | K44: 258 | L44: 0 | M44: 0 | N44: 0 | O44: 0
A45: 1232528 | B45: 161 | C45: 686 | D45: 539 | E45: 651 | F45: 0 | G45: 0 | H45: 0 | I45: 0 | J45: 0 | K45: 0 | L45: 0 | M45: 147 | N45: 0 | O45: 0
A46: 1233587 | B46: 0 | C46: 0 | D46: 10 | E46: 0 | F46: 0 | G46: 0 | H46: 0 | I46: 0 | J46: 0 | K46: 0 | L46: 0 | M46: 0 | N46: 0 | O46: 0
A47: 1232846 | B47: 0 | C47: 0 | D47: 0 | E47: 34 | F47: 142 | G47: 0 | H47: 0 | I47: 0 | J47: 0 | K47: 0 | L47: 0 | M47: 0 | N47: 0 | O47: 0
... A77: 1233580 | B77: 0 | C77: 0 | D77: 0 | E77: 0 | F77: 0 | G77: 0 | H77: 0 | I77: 130 | J77: 0 | K77: 0 | L77: 0 | M77: 0 | N77: 0 | O77: 0

Sheet 0113
A1: 품번 | B1: 01/13(화) | C1: 01/14(수) | D1: 01/15(목) | E1: 01/16(금) | F1: 01/17(토) | G1: 01/18(일) | H1: 01/19(월) | I1: 01/20(화) | J1: 01/21(수) | K1: 01/22(목) | L1: 01/23(금) | M1: 01/24(토) | N1: 01/25(일) | O1: 01/26(월) | P1: 01/27(화) | Q1: 01/28(수) | R1: 01/29(목) | S1: 01/30(금) | T1: 01/31(토) | U1: 02/01(일)
A2: 1221154 | B2: 0 | C2: 50 | D2: 0 | E2: 0 | F2: 0 | G2: 0 | H2: 0 | I2: 0 | J2: 0 | K2: 0 | L2: 0 | M2: 0 | N2: 0 | O2: 0 | P2: 0 | Q2: 0 | R2: 0 | S2: 0 | T2: 0 | U2: 0
A3: 1234614 | B3: 0 | C3: 352 | D3: 50 | E3: 0 | F3: 0 | G3: 0 | H3: 508 | I3: 362 | J3: 0 | K3: 0 | L3: 0 | M3: 0 | N3: 0 | O3: 0 | P3: 0 | Q3: 0 | R3: 0 | S3: 0 | T3: 0 | U3: 0
A4: 1226384 | B4: 100 | C4: 400 | D4: 0 | E4: 0 | F4: 0 | G4: 0 | H4: 0 | I4: 0 | J4: 0 | K4: 0 | L4: 0 | M4: 0 | N4: 0 | O4: 0 | P4: 0 | Q4: 0 | R4: 0 | S4: 0 | T4: 0 | U4: 0
A5: 1226388 | B5: 100 | C5: 400 | D5: 0 | E5: 0 | F5: 0 | G5: 0 | H5: 0 | I5: 0 | J5: 0 | K5: 0 | L5: 0 | M5: 0 | N5: 0 | O5: 0 | P5: 0 | Q5: 0 | R5: 0 | S5: 0 | T5: 0 | U5: 0
A6: 1229673 | B6: 0 | C6: 0 | D6: 0 | E6: 0 | F6: 0 | G6: 0 | H6: 400 | I6: 400 | J6: 400 | K6: 400 | L6: 400 | M6: 0 | N6: 0 | O6: 0 | P6: 200 | Q6: 0 | R6: 300 | S6: 300 | T6: 0 | U6: 0
A7: 1233632 | B7: 0 | C7: 0 | D7: 0 | E7: 0 | F7: 0 | G7: 0 | H7: 0 | I7: 0 | J7: 0 | K7: 0 | L7: 0 | M7: 0 | N7: 0 | O7: 0 | P7: 0 | Q7: 64 | R7: 337 | S7: 0 | T7: 0 | U7: 0
A8: 1237088 | B8: 1106 | C8: 1206 | D8: 1142 | E8: 1656 | F8: 0 | G8: 0 | H8: 1026 | I8: 554 | J8: 794 | K8: 330 | L8: 1039 | M8: 0 | N8: 0 | O8: 0 | P8: 430 | Q8: 788 | R8: 1168 | S8: 1638 | T8: 0 | U8: 0
A9: 1236091 | B9: 0 | C9: 200 | D9: 0 | E9: 0 | F9: 0 | G9: 0 | H9: 0 | I9: 0 | J9: 0 | K9: 0 | L9: 0 | M9: 0 | N9: 0 | O9: 0 | P9: 0 | Q9: 0 | R9: 0 | S9: 0 | T9: 0 | U9: 0
A10: 1238128 | B10: 480 | C10: 378 | D10: 912 | E10: 960 | F10: 0 | G10: 0 | H10: 546 | I10: 480 | J10: 76 | K10: 144 | L10: 480 | M10: 0 | N10: 0 | O10: 60 | P10: 0 | Q10: 0 | R10: 280 | S10: 480 | T10: 0 | U10: 0
A11: 1236962 | B11: 250 | C11: 0 | D11: 250 | E11: 250 | F11: 0 | G11: 0 | H11: 200 | I11: 400 | J11: 200 | K11: 200 | L11: 300 | M11: 0 | N11: 0 | O11: 0 | P11: 500 | Q11: 300 | R11: 300 | S11: 290 | T11: 0 | U11: 0
A12: 1233761 | B12: 0 | C12: 0 | D12: 250 | E12: 0 | F12: 0 | G12: 0 | H12: 0 | I12: 0 | J12: 0 | K12: 150 | L12: 0 | M12: 0 | N12: 0 | O12: 0 | P12: 0 | Q12: 0 | R12: 0 | S12: 0 | T12: 0 | U12: 0
