Workbook

Sheet 23년(세부_실적)
B1: ▣ 23년 매출 마감현황 | T1: =T420+T501+T747+T765+T1087+T1094+T1104+T1105 -> 5072.7803 | V1: =V420+V501+V747+V765+V1087+V1094+V1104+V1105 -> 5345.4204 | X1: =X420+X501+X747+X765+X1087+X1094+X1104+X1105 -> 5741.7766 | Z1: =Z420+Z501+Z747+Z765+Z1087+Z1094+Z1104+Z1105 -> 16159.977 | AB1: =AB420+AB501+AB747+AB765+AB1087+AB1094+AB1104+AB1105 -> 6814.4977 | AD1: =AD420+AD501+AD747+AD765+AD1087+AD1094+AD1104+AD1105 -> 6958.7836
B2: 2024. 01. 19 | T2: 1245.69 | V2: 1274.22 | X2: 1303.43 | AB2: 1323.32 | AD2: 1327.09 | AF2: 1300.23 | AL2: 1278.83 | AN2: 1322.79 | AP2: 1333.8 | AT2: 1350.71 | AV2: 1301.41 | AX2: 1300.28
B3: 거래선 | C3: 제품 | D3: Set | E3: 모델 | F3: Code | G3: 구분 | H3: 제조지 | I3: 단가 | Q3: 년계 | S3: 1월 | U3: 2월 | W3: 3월 | Y3: 1분기 | AA3: 4월 | AC3: 5월 | AE3: 6월 | AG3: 2분기 | AI3: 상반기 | AK3: 7월 | AM3: 8월 | AO3: 9월 | AQ3: 3분기 | AS3: 10월 | AU3: 11월 | AW3: 12월 | AY3: 4분기 | BA3: 하반기
I4: 1Q | K4: 2Q | M4: 3Q | O4: 4Q
I5: USD | J5: KRW | K5: USD | L5: KRW | M5: USD | N5: KRW | O5: USD | P5: KRW | Q5: 수량 | R5: 금액 | S5: 수량 | T5: 금액 | U5: 수량 | V5: 금액 | W5: 수량 | X5: 금액 | Y5: 수량 | Z5: 금액 | AA5: 수량 | AB5: 금액 | AC5: 수량 | AD5: 금액 | AE5: 수량 | AF5: 금액 | AG5: 수량 | AH5: 금액 | AI5: 수량 | AJ5: 금액 | AK5: 수량 | AL5: 금액 | AM5: 수량 | AN5: 금액 | AO5: 수량 | AP5: 금액 | AQ5: 수량 | AR5: 금액 | AS5: 수량 | AT5: 금액 | AU5: 수량 | AV5: 금액 | AW5: 수량 | AX5: 금액 | AY5: 수량 | AZ5: 금액 | BA5: 수량 | BB5: 금액
B6: 합 계 | Q6: =SUM(Q222,Q319,Q420,Q423,Q476,Q480,Q501,Q747,Q751,Q765,Q1094,Q1105,Q1087,Q1089,Q1097,Q1104) -> 19455.781 | R6: =SUM(R222,R319,R420,R423,R476,R480,R501,R747,R751,R765,R1094,R1105,R1087,R1089,R1097,R1104) -> 185585.57 | S6: =SUM(S222,S319,S420,S423,S476,S480,S501,S747,S751,S765,S1094,S1105,S1087,S1089,S1097,S1104) -> 1499.263 | T6: =SUM(T222,T319,T420,T423,T476,T480,T501,T747,T751,T765,T1094,T1105,T1087,T1089,T1097,T1104) -> 14181.044 | U6: =SUM(U222,U319,U420,U423,U476,U480,U501,U747,U751,U765,U1094,U1105,U1087,U1089,U1097,U1104) -> 1721.058 | V6: =SUM(V222,V319,V420,V423,V476,V480,V501,V747,V751,V765,V1094,V1105,V1087,V1089,V1097,V1104) -> 15371.435 | W6: =SUM(W222,W319,W420,W423,W476,W480,W501,W747,W751,W765,W1094,W1105,W1087,W1089,W1097,W1104) -> 1748.564 | X6: =SUM(X222,X319,X420,X423,X476,X480,X501,X747,X751,X765,X1094,X1105,X1087,X1089,X1097,X1104) -> 15496.546 | ... BB6: =SUM(BB222,BB319,BB420,BB423,BB476,BB480,BB501,BB747,BB751,BB765,BB1094,BB1105,BB1087,BB1089,BB1097,BB1104) -> 88939.616
A7: 1 | B7: SEC VD | C7: PD-Board | D7: TV/MFM | E7: L22S0Q_EPN | F7: 692A | G7: 구 | H7: QD | I7: 4.12 | K7: 4.12 | M7: 4.12 | O7: 4.12 | Q7: =SUM(AI7+BA7) -> 0 | R7: =SUM(AJ7+BB7) -> 0 | T7: =I7*S7*$T$2/1000 -> 0 | V7: =I7*U7*$V$2/1000 -> 0 | X7: =I7*W7*$X$2/1000 -> 0 | Y7: =SUM(S7+U7+W7) -> 0 | Z7: =SUM(T7,V7,X7) -> 0 | AB7: =K7*AA7*$AB$2/1000 -> 0 | AD7: =K7*AC7*$AD$2/1000 -> 0 | AF7: =K7*AE7*$AF$2/1000 -> 0 | AG7: =SUM(AA7+AC7+AE7) -> 0 | AH7: =SUM(AB7,AD7,AF7) -> 0 | AI7: =SUM(Y7+AG7) -> 0 | AJ7: =SUM(Z7,AH7) -> 0 | AL7: =M7*AK7*$AL$2/1000 -> 0 | AN7: =M7*AM7*$AN$2/1000 -> 0 | AP7: =M7*AO7*AP2/1000 -> 0 | AQ7: =SUM(AK7+AM7+AO7) -> 0 | AR7: =SUM(AL7,AN7,AP7) -> 0 | AT7: =O7*AS7*$AT$2/1000 -> 0 | AV7: =O7*AU7*$AV$2/1000 -> 0 | AX7: =O7*AW7*$AX$2/1000 -> 0 | AY7: =SUM(AS7+AU7+AW7) -> 0 | AZ7: =SUM(AT7,AV7,AX7) -> 0 | BA7: =SUM(AQ7+AY7) -> 0 | BB7: =SUM(AR7,AZ7) -> 0
A8: 2 | E8: L23S0D_EPN | F8: 746A | G8: 구 | H8: QD | I8: 4.13 | K8: 4.13 | M8: 4.13 | O8: 4.13 | Q8: =SUM(AI8+BA8) -> 0.028 | R8: =SUM(AJ8+BB8) -> 0.1473508 | T8: =I8*S8*$T$2/1000 -> 0 | U8: 0.028 | V8: =I8*U8*$V$2/1000 -> 0.1473508 | X8: =I8*W8*$X$2/1000 -> 0 | Y8: =SUM(S8+U8+W8) -> 0.028 | Z8: =SUM(T8,V8,X8) -> 0.1473508 | AB8: =K8*AA8*$AB$2/1000 -> 0 | AD8: =K8*AC8*$AD$2/1000 -> 0 | AF8: =K8*AE8*$AF$2/1000 -> 0 | AG8: =SUM(AA8+AC8+AE8) -> 0 | AH8: =SUM(AB8,AD8,AF8) -> 0 | AI8: =SUM(Y8+AG8) -> 0.028 | AJ8: =SUM(Z8,AH8) -> 0.1473508 | AL8: =M8*AK8*$AL$2/1000 -> 0 | AN8: =K8*AM8*$AN$2/1000 -> 0 | AP8: =M8*AO8*$AP$2/1000 -> 0 | AQ8: =SUM(AK8+AM8+AO8) -> 0 | AR8: =SUM(AL8,AN8,AP8) -> 0 | AT8: =O8*AS8*$AT$2/1000 -> 0 | AV8: =O8*AU8*$AV$2/1000 -> 0 | AX8: =O8*AW8*$AX$2/1000 -> 0 | AY8: =SUM(AS8+AU8+AW8) -> 0 | AZ8: =SUM(AT8,AV8,AX8) -> 0 | BA8: =SUM(AQ8+AY8) -> 0 | BB8: =SUM(AR8,AZ8) -> 0
A9: 3 | E9: L23S0DN_EPN | F9: 746B | G9: 구 | H9: QD | I9: 4.3 | K9: 4.28 | M9: 4.28 | O9: 4.26 | Q9: =SUM(AI9+BA9) -> 34.832 | R9: =SUM(AJ9+BB9) -> 195.54476 | S9: 1.008 | T9: =I9*S9*$T$2/1000 -> 5.3993187 | U9: 0.784 | V9: =I9*U9*$V$2/1000 -> 4.2956505 | W9: 7.182 | X9: =I9*W9*$X$2/1000 -> 40.253307 | Y9: =SUM(S9+U9+W9) -> 8.974 | Z9: =SUM(T9,V9,X9) -> 49.948277 | AA9: 2.352 | AB9: =K9*AA9*$AB$2/1000 -> 13.32128 | AC9: 0.84 | AD9: =K9*AC9*$AD$2/1000 -> 4.771154 | AE9: 10.248 | AF9: =K9*AE9*$AF$2/1000 -> 57.02996 | AG9: =SUM(AA9+AC9+AE9) -> 13.44 | AH9: =SUM(AB9,AD9,AF9) -> 75.122394 | AI9: =SUM(Y9+AG9) -> 22.414 | AJ9: =SUM(Z9,AH9) -> 125.07067 | AK9: 1.008 | AL9: =M9*AK9*$AL$2/1000 -> 5.5171795 | AM9: 6.048 | AN9: =K9*AM9*$AN$2/1000 -> 34.241001 | AO9: 3.024 | AP9: =M9*AO9*$AP$2/1000 -> 17.263 | AQ9: =SUM(AK9+AM9+AO9) -> 10.08 | AR9: =SUM(AL9,AN9,AP9) -> 57.021181 | AS9: 2.338 | AT9: =O9*AS9*$AT$2/1000 -> 13.45291 | AV9: =O9*AU9*$AV$2/1000 -> 0 | AX9: =O9*AW9*$AX$2/1000 -> 0 | AY9: =SUM(AS9+AU9+AW9) -> 2.338 | AZ9: =SUM(AT9,AV9,AX9) -> 13.45291 | BA9: =SUM(AQ9+AY9) -> 12.418 | BB9: =SUM(AR9,AZ9) -> 70.47409
A10: 4 | E10: L23S0DS_EPN | F10: 746C | G10: 구 | H10: QD | I10: 4.27 | K10: 4.27 | M10: 4.27 | O10: 4.27 | Q10: =SUM(AI10+BA10) -> 0 | R10: =SUM(AJ10+BB10) -> 0 | T10: =I10*S10*$T$2/1000 -> 0 | V10: =I10*U10*$V$2/1000 -> 0 | X10: =I10*W10*$X$2/1000 -> 0 | Y10: =SUM(S10+U10+W10) -> 0 | Z10: =SUM(T10,V10,X10) -> 0 | AB10: =K10*AA10*$AB$2/1000 -> 0 | AD10: =K10*AC10*$AD$2/1000 -> 0 | AF10: =K10*AE10*$AF$2/1000 -> 0 | AG10: =SUM(AA10+AC10+AE10) -> 0 | AH10: =SUM(AB10,AD10,AF10) -> 0 | AI10: =SUM(Y10+AG10) -> 0 | AJ10: =SUM(Z10,AH10) -> 0 | AL10: =M10*AK10*$AL$2/1000 -> 0 | AN10: =M10*AM10*$AN$2/1000 -> 0 | AP10: =M10*AO10*AP2/1000 -> 0 | AQ10: =SUM(AK10+AM10+AO10) -> 0 | AR10: =SUM(AL10,AN10,AP10) -> 0 | AT10: =O10*AS10*$AT$2/1000 -> 0 | AV10: =O10*AU10*$AV$2/1000 -> 0 | AX10: =O10*AW10*$AX$2/1000 -> 0 | AY10: =SUM(AS10+AU10+AW10) -> 0 | AZ10: =SUM(AT10,AV10,AX10) -> 0 | BA10: =SUM(AQ10+AY10) -> 0 | BB10: =SUM(AR10,AZ10) -> 0
A11: 5 | E11: L23S0DMN_FPN | F11: 746D | G11: 구 | H11: QD | I11: 5.21 | K11: 5.21 | M11: 5.21 | O11: 5.21 | Q11: =SUM(AI11+BA11) -> 0 | R11: =SUM(AJ11+BB11) -> 0 | T11: =I11*S11*$T$2/1000 -> 0 | V11: =I11*U11*$V$2/1000 -> 0 | X11: =I11*W11*$X$2/1000 -> 0 | Y11: =SUM(S11+U11+W11) -> 0 | Z11: =SUM(T11,V11,X11) -> 0 | AB11: =K11*AA11*$AB$2/1000 -> 0 | AD11: =K11*AC11*$AD$2/1000 -> 0 | AF11: =K11*AE11*$AF$2/1000 -> 0 | AG11: =SUM(AA11+AC11+AE11) -> 0 | AH11: =SUM(AB11,AD11,AF11) -> 0 | AI11: =SUM(Y11+AG11) -> 0 | AJ11: =SUM(Z11,AH11) -> 0 | AL11: =M11*AK11*$AL$2/1000 -> 0 | AN11: =M11*AM11*$AN$2/1000 -> 0 | AP11: =M11*AO11*AP2/1000 -> 0 | AQ11: =SUM(AK11+AM11+AO11) -> 0 | AR11: =SUM(AL11,AN11,AP11) -> 0 | AT11: =O11*AS11*$AT$2/1000 -> 0 | AV11: =O11*AU11*$AV$2/1000 -> 0 | AX11: =O11*AW11*$AX$2/1000 -> 0 | AY11: =SUM(AS11+AU11+AW11) -> 0 | AZ11: =SUM(AT11,AV11,AX11) -> 0 | BA11: =SUM(AQ11+AY11) -> 0 | BB11: =SUM(AR11,AZ11) -> 0
A12: 6 | E12: L23S0DF_FPN | F12: 746E | G12: 구 | H12: QD | I12: 6.32 | K12: 6.32 | M12: 6.32 | O12: 6.32 | Q12: =SUM(AI12+BA12) -> 0 | R12: =SUM(AJ12+BB12) -> 0 | T12: =I12*S12*$T$2/1000 -> 0 | V12: =I12*U12*$V$2/1000 -> 0 | X12: =I12*W12*$X$2/1000 -> 0 | Y12: =SUM(S12+U12+W12) -> 0 | Z12: =SUM(T12,V12,X12) -> 0 | AB12: =K12*AA12*$AB$2/1000 -> 0 | AD12: =K12*AC12*$AD$2/1000 -> 0 | AF12: =K12*AE12*$AF$2/1000 -> 0 | AG12: =SUM(AA12+AC12+AE12) -> 0 | AH12: =SUM(AB12,AD12,AF12) -> 0 | AI12: =SUM(Y12+AG12) -> 0 | AJ12: =SUM(Z12,AH12) -> 0 | AL12: =M12*AK12*$AL$2/1000 -> 0 | AN12: =M12*AM12*$AN$2/1000 -> 0 | AP12: =M12*AO12*AP2/1000 -> 0 | AQ12: =SUM(AK12+AM12+AO12) -> 0 | AR12: =SUM(AL12,AN12,AP12) -> 0 | AT12: =O12*AS12*$AT$2/1000 -> 0 | AV12: =O12*AU12*$AV$2/1000 -> 0 | AX12: =O12*AW12*$AX$2/1000 -> 0 | AY12: =SUM(AS12+AU12+AW12) -> 0 | AZ12: =SUM(AT12,AV12,AX12) -> 0 | BA12: =SUM(AQ12+AY12) -> 0 | BB12: =SUM(AR12,AZ12) -> 0
A13: 7 | E13: L23S0DSR_MPN | F13: 746F | G13: 구 | H13: QD | I13: 5.03 | K13: 5.02 | M13: 5.02 | O13: 5.01 | Q13: =SUM(AI13+BA13) -> 126.203 | R13: =SUM(AJ13+BB13) -> 828.18647 | T13: =I13*S13*$T$2/1000 -> 0 | U13: 20.303 | V13: =I13*U13*$V$2/1000 -> 130.12856 | W13: 6.962 | X13: =I13*W13*$X$2/1000 -> 45.644633 | Y13: =SUM(S13+U13+W13) -> 27.265 | Z13: =SUM(T13,V13,X13) -> 175.77319 | AA13: 19.536 | AB13: =K13*AA13*$AB$2/1000 -> 129.77895 | AC13: 6.048 | AD13: =K13*AC13*$AD$2/1000 -> 40.291726 | AE13: 12.24 | AF13: =K13*AE13*$AF$2/1000 -> 79.892372 | AG13: =SUM(AA13+AC13+AE13) -> 37.824 | AH13: =SUM(AB13,AD13,AF13) -> 249.96304 | AI13: =SUM(Y13+AG13) -> 65.089 | AJ13: =SUM(Z13,AH13) -> 425.73623 | AK13: 13.632 | AL13: =M13*AK13*$AL$2/1000 -> 87.513713 | AM13: 14.4 | AN13: =M13*AM13*$AN$2/1000 -> 95.621844 | AO13: 15.96 | AP13: =M13*AO13*$AP$2/1000 -> 106.86299 | AQ13: =SUM(AK13+AM13+AO13) -> 43.992 | AR13: =SUM(AL13,AN13,AP13) -> 289.99855 | AS13: 3.61 | AT13: =O13*AS13*$AT$2/1000 -> 24.429076 | AV13: =O13*AU13*$AV$2/1000 -> 0 | AW13: 13.512 | AX13: =O13*AW13*$AX$2/1000 -> 88.022611 | AY13: =SUM(AS13+AU13+AW13) -> 17.122 | AZ13: =SUM(AT13,AV13,AX13) -> 112.45169 | BA13: =SUM(AQ13+AY13) -> 61.114 | BB13: =SUM(AR13,AZ13) -> 402.45023
A14: 8 | E14: L23S0DSR_RPN | F14: 746G | G14: 구 | H14: QD | I14: 5.03 | K14: 5.03 | M14: 5.03 | O14: 5.03 | Q14: =SUM(AI14+BA14) -> 4.212 | R14: =SUM(AJ14+BB14) -> 27.784672 | T14: =I14*S14*$T$2/1000 -> 0 | V14: =I14*U14*$V$2/1000 -> 0 | W14: 1.5 | X14: =I14*W14*$X$2/1000 -> 9.8343794 | Y14: =SUM(S14+U14+W14) -> 1.5 | Z14: =SUM(T14,V14,X14) -> 9.8343794 | AB14: =K14*AA14*$AB$2/1000 -> 0 | AD14: =K14*AC14*$AD$2/1000 -> 0 | AE14: 0.6 | AF14: =K14*AE14*$AF$2/1000 -> 3.9240941 | AG14: =SUM(AA14+AC14+AE14) -> 0.6 | AH14: =SUM(AB14,AD14,AF14) -> 3.9240941 | AI14: =SUM(Y14+AG14) -> 2.1 | AJ14: =SUM(Z14,AH14) -> 13.758473 | AL14: =M14*AK14*$AL$2/1000 -> 0 | AN14: =M14*AM14*$AN$2/1000 -> 0 | AO14: 0.744 | AP14: =M14*AO14*$AP$2/1000 -> 4.9915064 | AQ14: =SUM(AK14+AM14+AO14) -> 0.744 | AR14: =SUM(AL14,AN14,AP14) -> 4.9915064 | AS14: 0.336 | AT14: =O14*AS14*$AT$2/1000 -> 2.282808 | AU14: 0.384 | AV14: =O14*AU14*$AV$2/1000 -> 2.5136994 | AW14: 0.648 | AX14: =O14*AW14*$AX$2/1000 -> 4.2381846 | AY14: =SUM(AS14+AU14+AW14) -> 1.368 | AZ14: =SUM(AT14,AV14,AX14) -> 9.034692 | BA14: =SUM(AQ14+AY14) -> 2.112 | BB14: =SUM(AR14,AZ14) -> 14.026198
A15: 9 | E15: L32S0X_EPN | F15: 750A | G15: 구 | H15: QD | I15: 10.06 | K15: 10.06 | M15: 10.06 | O15: 10.06 | Q15: =SUM(AI15+BA15) -> 0 | R15: =SUM(AJ15+BB15) -> 0 | T15: =I15*S15*$T$2/1000 -> 0 | V15: =I15*U15*$V$2/1000 -> 0 | X15: =I15*W15*$X$2/1000 -> 0 | Y15: =SUM(S15+U15+W15) -> 0 | Z15: =SUM(T15,V15,X15) -> 0 | AB15: =K15*AA15*$AB$2/1000 -> 0 | AD15: =K15*AC15*$AD$2/1000 -> 0 | AF15: =K15*AE15*$AF$2/1000 -> 0 | AG15: =SUM(AA15+AC15+AE15) -> 0 | AH15: =SUM(AB15,AD15,AF15) -> 0 | AI15: =SUM(Y15+AG15) -> 0 | AJ15: =SUM(Z15,AH15) -> 0 | AL15: =M15*AK15*$AL$2/1000 -> 0 | AN15: =M15*AM15*$AN$2/1000 -> 0 | AP15: =M15*AO15*$AP$2/1000 -> 0 | AQ15: =SUM(AK15+AM15+AO15) -> 0 | AR15: =SUM(AL15,AN15,AP15) -> 0 | AT15: =O15*AS15*$AT$2/1000 -> 0 | AV15: =O15*AU15*$AV$2/1000 -> 0 | AX15: =O15*AW15*$AX$2/1000 -> 0 | AY15: =SUM(AS15+AU15+AW15) -> 0 | AZ15: =SUM(AT15,AV15,AX15) -> 0 | BA15: =SUM(AQ15+AY15) -> 0 | BB15: =SUM(AR15,AZ15) -> 0
A16: 10 | E16: L32S0XN_EPN | F16: 750B | G16: 구 | H16: QD | I16: 12.19 | K16: 12.19 | M16: 12.19 | O16: 12.19 | Q16: =SUM(AI16+BA16) -> 0 | R16: =SUM(AJ16+BB16) -> 0 | T16: =I16*S16*$T$2/1000 -> 0 | V16: =I16*U16*$V$2/1000 -> 0 | X16: =I16*W16*$X$2/1000 -> 0 | Y16: =SUM(S16+U16+W16) -> 0 | Z16: =SUM(T16,V16,X16) -> 0 | AB16: =K16*AA16*$AB$2/1000 -> 0 | AD16: =K16*AC16*$AD$2/1000 -> 0 | AF16: =K16*AE16*$AF$2/1000 -> 0 | AG16: =SUM(AA16+AC16+AE16) -> 0 | AH16: =SUM(AB16,AD16,AF16) -> 0 | AI16: =SUM(Y16+AG16) -> 0 | AJ16: =SUM(Z16,AH16) -> 0 | AL16: =M16*AK16*$AL$2/1000 -> 0 | AN16: =M16*AM16*$AN$2/1000 -> 0 | AP16: =M16*AO16*$AP$2/1000 -> 0 | AQ16: =SUM(AK16+AM16+AO16) -> 0 | AR16: =SUM(AL16,AN16,AP16) -> 0 | AT16: =O16*AS16*$AT$2/1000 -> 0 | AV16: =O16*AU16*$AV$2/1000 -> 0 | AX16: =O16*AW16*$AX$2/1000 -> 0 | AY16: =SUM(AS16+AU16+AW16) -> 0 | AZ16: =SUM(AT16,AV16,AX16) -> 0 | BA16: =SUM(AQ16+AY16) -> 0 | BB16: =SUM(AR16,AZ16) -> 0
A17: 11 | E17: F24SFD_APN | F17: 1122A | G17: 신 | H17: SY | I17: 7.34 | K17: 7.33 | M17: 7.33 | O17: 7.33 | Q17: =SUM(AI17+BA17) -> 28.255 | R17: =SUM(AJ17+BB17) -> 269.74466 | S17: 3.27 | T17: =I17*S17*$T$2/1000 -> 29.898802 | U17: 3.6 | V17: =I17*U17*$V$2/1000 -> 33.669989 | W17: 2.16 | X17: =I17*W17*$X$2/1000 -> 20.665101 | Y17: =SUM(S17+U17+W17) -> 9.03 | Z17: =SUM(T17,V17,X17) -> 84.233892 | AA17: 2.306 | AB17: =K17*AA17*$AB$2/1000 -> 22.368051 | AC17: 4.8 | AD17: =K17*AC17*$AD$2/1000 -> 46.692335 | AE17: 3.3 | AF17: =K17*AE17*$AF$2/1000 -> 31.451263 | AG17: =SUM(AA17+AC17+AE17) -> 10.406 | AH17: =SUM(AB17,AD17,AF17) -> 100.51165 | AI17: =SUM(Y17+AG17) -> 19.436 | AJ17: =SUM(Z17,AH17) -> 184.74554 | AK17: 0.96 | AL17: =M17*AK17*$AL$2/1000 -> 8.9988709 | AM17: 1.686 | AN17: =M17*AM17*$AN$2/1000 -> 16.347541 | AO17: 1.407 | AP17: =M17*AO17*$AP$2/1000 -> 13.755893 | AQ17: =SUM(AK17+AM17+AO17) -> 4.053 | AR17: =SUM(AL17,AN17,AP17) -> 39.102305 | AS17: 1.245 | AT17: =O17*AS17*$AT$2/1000 -> 12.326377 | AU17: 1.401 | AV17: =O17*AU17*$AV$2/1000 -> 13.364609 | AW17: 2.12 | AX17: =O17*AW17*$AX$2/1000 -> 20.205831 | AY17: =SUM(AS17+AU17+AW17) -> 4.766 | AZ17: =SUM(AT17,AV17,AX17) -> 45.896817 | BA17: =SUM(AQ17+AY17) -> 8.819 | BB17: =SUM(AR17,AZ17) -> 84.999122
A18: 12 | E18: F24SFDN_APN | F18: 1122B | G18: 신 | H18: SY | I18: 7.9 | K18: 7.9 | M18: 7.9 | O18: 7.9 | Q18: =SUM(AI18+BA18) -> 1.635 | R18: =SUM(AJ18+BB18) -> 16.976274 | S18: 0.09 | T18: =I18*S18*$T$2/1000 -> 0.88568559 | U18: 0.06 | V18: =I18*U18*$V$2/1000 -> 0.60398028 | W18: 0.09 | X18: =I18*W18*$X$2/1000 -> 0.92673873 | Y18: =SUM(S18+U18+W18) -> 0.24 | Z18: =SUM(T18,V18,X18) -> 2.4164046 | AA18: 0.12 | AB18: =K18*AA18*$AB$2/1000 -> 1.2545074 | AC18: 0.111 | AD18: =K18*AC18*$AD$2/1000 -> 1.1637252 | AE18: 0.09 | AF18: =K18*AE18*$AF$2/1000 -> 0.92446353 | AG18: =SUM(AA18+AC18+AE18) -> 0.321 | AH18: =SUM(AB18,AD18,AF18) -> 3.3426961 | AI18: =SUM(Y18+AG18) -> 0.561 | AJ18: =SUM(Z18,AH18) -> 5.7591007 | AK18: 0.069 | AL18: =M18*AK18*$AL$2/1000 -> 0.69709023 | AM18: 0.205 | AN18: =M18*AM18*$AN$2/1000 -> 2.1422584 | AO18: 0.218 | AP18: =M18*AO18*$AP$2/1000 -> 2.2970704 | AQ18: =SUM(AK18+AM18+AO18) -> 0.492 | AR18: =SUM(AL18,AN18,AP18) -> 5.136419 | AS18: 0.254 | AT18: =O18*AS18*$AT$2/1000 -> 2.7103347 | AU18: 0.127 | AV18: =O18*AU18*$AV$2/1000 -> 1.3057047 | AW18: 0.201 | AX18: =O18*AW18*$AX$2/1000 -> 2.0647146 | AY18: =SUM(AS18+AU18+AW18) -> 0.582 | AZ18: =SUM(AT18,AV18,AX18) -> 6.080754 | BA18: =SUM(AQ18+AY18) -> 1.074 | BB18: =SUM(AR18,AZ18) -> 11.217173
A19: 13 | E19: L23S0T_EPN | F19: 793A | G19: 구 | H19: QD | I19: 4.19 | K19: 4.19 | M19: 4.19 | O19: 4.19 | Q19: =SUM(AI19+BA19) -> 0 | R19: =SUM(AJ19+BB19) -> 0 | T19: =I19*S19*$T$2/1000 -> 0 | V19: =I19*U19*$V$2/1000 -> 0 | X19: =I19*W19*$X$2/1000 -> 0 | Y19: =SUM(S19+U19+W19) -> 0 | Z19: =SUM(T19,V19,X19) -> 0 | AB19: =K19*AA19*$AB$2/1000 -> 0 | AD19: =K19*AC19*$AD$2/1000 -> 0 | AF19: =K19*AE19*$AF$2/1000 -> 0 | AG19: =SUM(AA19+AC19+AE19) -> 0 | AH19: =SUM(AB19,AD19,AF19) -> 0 | AI19: =SUM(Y19+AG19) -> 0 | AJ19: =SUM(Z19,AH19) -> 0 | AL19: =M19*AK19*$AL$2/1000 -> 0 | AN19: =M19*AM19*$AN$2/1000 -> 0 | AP19: =M19*AO19*$AP$2/1000 -> 0 | AQ19: =SUM(AK19+AM19+AO19) -> 0 | AR19: =SUM(AL19,AN19,AP19) -> 0 | AT19: =O19*AS19*$AT$2/1000 -> 0 | AV19: =O19*AU19*$AV$2/1000 -> 0 | AX19: =O19*AW19*$AX$2/1000 -> 0 | AY19: =SUM(AS19+AU19+AW19) -> 0 | AZ19: =SUM(AT19,AV19,AX19) -> 0 | BA19: =SUM(AQ19+AY19) -> 0 | BB19: =SUM(AR19,AZ19) -> 0
A20: 14 | E20: L32E1P_KPN | F20: 869A | G20: 구 | H20: SY | I20: 8.64 | K20: 8.64 | M20: 8.64 | O20: 8.64 | Q20: =SUM(AI20+BA20) -> 0 | R20: =SUM(AJ20+BB20) -> 0 | T20: =I20*S20*$T$2/1000 -> 0 | V20: =I20*U20*$V$2/1000 -> 0 | X20: =I20*W20*$X$2/1000 -> 0 | Y20: =SUM(S20+U20+W20) -> 0 | Z20: =SUM(T20,V20,X20) -> 0 | AB20: =K20*AA20*$AB$2/1000 -> 0 | AD20: =K20*AC20*$AD$2/1000 -> 0 | AF20: =K20*AE20*$AF$2/1000 -> 0 | AG20: =SUM(AA20+AC20+AE20) -> 0 | AH20: =SUM(AB20,AD20,AF20) -> 0 | AI20: =SUM(Y20+AG20) -> 0 | AJ20: =SUM(Z20,AH20) -> 0 | AL20: =M20*AK20*$AL$2/1000 -> 0 | AN20: =M20*AM20*$AN$2/1000 -> 0 | AP20: =M20*AO20*$AP$2/1000 -> 0 | AQ20: =SUM(AK20+AM20+AO20) -> 0 | AR20: =SUM(AL20,AN20,AP20) -> 0 | AT20: =O20*AS20*$AT$2/1000 -> 0 | AV20: =O20*AU20*$AV$2/1000 -> 0 | AX20: =O20*AW20*$AX$2/1000 -> 0 | AY20: =SUM(AS20+AU20+AW20) -> 0 | AZ20: =SUM(AT20,AV20,AX20) -> 0 | BA20: =SUM(AQ20+AY20) -> 0 | BB20: =SUM(AR20,AZ20) -> 0
A21: 15 | E21: L32E1P_KPN V | F21: 869B | G21: 구 | H21: SY | I21: 7.7 | K21: 7.7 | M21: 7.7 | O21: 7.7 | Q21: =SUM(AI21+BA21) -> 0 | R21: =SUM(AJ21+BB21) -> 0 | T21: =I21*S21*$T$2/1000 -> 0 | V21: =I21*U21*$V$2/1000 -> 0 | X21: =I21*W21*$X$2/1000 -> 0 | Y21: =SUM(S21+U21+W21) -> 0 | Z21: =SUM(T21,V21,X21) -> 0 | AB21: =K21*AA21*$AB$2/1000 -> 0 | AD21: =K21*AC21*$AD$2/1000 -> 0 | AF21: =K21*AE21*$AF$2/1000 -> 0 | AG21: =SUM(AA21+AC21+AE21) -> 0 | AH21: =SUM(AB21,AD21,AF21) -> 0 | AI21: =SUM(Y21+AG21) -> 0 | AJ21: =SUM(Z21,AH21) -> 0 | AL21: =M21*AK21*$AL$2/1000 -> 0 | AN21: =M21*AM21*$AN$2/1000 -> 0 | AP21: =M21*AO21*$AP$2/1000 -> 0 | AQ21: =SUM(AK21+AM21+AO21) -> 0 | AR21: =SUM(AL21,AN21,AP21) -> 0 | AT21: =O21*AS21*$AT$2/1000 -> 0 | AV21: =O21*AU21*$AV$2/1000 -> 0 | AX21: =O21*AW21*$AX$2/1000 -> 0 | AY21: =SUM(AS21+AU21+AW21) -> 0 | AZ21: =SUM(AT21,AV21,AX21) -> 0 | BA21: =SUM(AQ21+AY21) -> 0 | BB21: =SUM(AR21,AZ21) -> 0
A22: 16 | E22: L32E1N_KPN | F22: 870A | G22: 구 | H22: SY | I22: 8.5 | K22: 8.5 | M22: 8.5 | O22: 8.5 | Q22: =SUM(AI22+BA22) -> 0.494 | R22: =SUM(AJ22+BB22) -> 5.4731026 | T22: =I22*S22*$T$2/1000 -> 0 | V22: =I22*U22*$V$2/1000 -> 0 | W22: 0.494 | X22: =I22*W22*$X$2/1000 -> 5.4731026 | Y22: =SUM(S22+U22+W22) -> 0.494 | Z22: =SUM(T22,V22,X22) -> 5.4731026 | AB22: =K22*AA22*$AB$2/1000 -> 0 | AD22: =K22*AC22*$AD$2/1000 -> 0 | AF22: =K22*AE22*$AF$2/1000 -> 0 | AG22: =SUM(AA22+AC22+AE22) -> 0 | AH22: =SUM(AB22,AD22,AF22) -> 0 | AI22: =SUM(Y22+AG22) -> 0.494 | AJ22: =SUM(Z22,AH22) -> 5.4731026 | AL22: =M22*AK22*$AL$2/1000 -> 0 | AN22: =M22*AM22*$AN$2/1000 -> 0 | AP22: =M22*AO22*$AP$2/1000 -> 0 | AQ22: =SUM(AK22+AM22+AO22) -> 0 | AR22: =SUM(AL22,AN22,AP22) -> 0 | AT22: =O22*AS22*$AT$2/1000 -> 0 | AV22: =O22*AU22*$AV$2/1000 -> 0 | AX22: =O22*AW22*$AX$2/1000 -> 0 | AY22: =SUM(AS22+AU22+AW22) -> 0 | AZ22: =SUM(AT22,AV22,AX22) -> 0 | BA22: =SUM(AQ22+AY22) -> 0 | BB22: =SUM(AR22,AZ22) -> 0
A23: 17 | E23: L32E1NR_KPN | F23: 870B | G23: 구 | H23: SY | I23: 7.79 | K23: 7.79 | M23: 7.79 | O23: 7.79 | Q23: =SUM(AI23+BA23) -> 0 | R23: =SUM(AJ23+BB23) -> 0 | T23: =I23*S23*$T$2/1000 -> 0 | V23: =I23*U23*$V$2/1000 -> 0 | X23: =I23*W23*$X$2/1000 -> 0 | Y23: =SUM(S23+U23+W23) -> 0 | Z23: =SUM(T23,V23,X23) -> 0 | AB23: =K23*AA23*$AB$2/1000 -> 0 | AD23: =K23*AC23*$AD$2/1000 -> 0 | AF23: =K23*AE23*$AF$2/1000 -> 0 | AG23: =SUM(AA23+AC23+AE23) -> 0 | AH23: =SUM(AB23,AD23,AF23) -> 0 | AI23: =SUM(Y23+AG23) -> 0 | AJ23: =SUM(Z23,AH23) -> 0 | AL23: =M23*AK23*$AL$2/1000 -> 0 | AN23: =M23*AM23*$AN$2/1000 -> 0 | AP23: =M23*AO23*$AP$2/1000 -> 0 | AQ23: =SUM(AK23+AM23+AO23) -> 0 | AR23: =SUM(AL23,AN23,AP23) -> 0 | AT23: =O23*AS23*$AT$2/1000 -> 0 | AV23: =O23*AU23*$AV$2/1000 -> 0 | AX23: =O23*AW23*$AX$2/1000 -> 0 | AY23: =SUM(AS23+AU23+AW23) -> 0 | AZ23: =SUM(AT23,AV23,AX23) -> 0 | BA23: =SUM(AQ23+AY23) -> 0 | BB23: =SUM(AR23,AZ23) -> 0
A24: 18 | E24: 소 계 | Q24: =SUM(Q7:Q23) -> 195.659 | R24: =SUM(R7:R23) -> 1343.8573 | S24: =SUM(S7:S23) -> 4.368 | T24: =SUM(T7:T23) -> 36.183807 | U24: =SUM(U7:U23) -> 24.775 | V24: =SUM(V7:V23) -> 168.84553 | W24: =SUM(W7:W23) -> 18.388 | X24: =SUM(X7:X23) -> 122.79726 | ... BB24: =SUM(BB7:BB23) -> 583.16682
A25: 19 | D25: LFD | E25: F24AF_FPN | F25: 861A | G25: 구 | H25: QD | I25: 10.2 | K25: 10.2 | M25: 10.2 | O25: 10.2 | Q25: =SUM(AI25+BA25) -> 0 | R25: =SUM(AJ25+BB25) -> 0 | T25: =I25*S25*$T$2/1000 -> 0 | V25: =I25*U25*$V$2/1000 -> 0 | X25: =I25*W25*$X$2/1000 -> 0 | Y25: =SUM(S25+U25+W25) -> 0 | Z25: =SUM(T25+V25+X25) -> 0 | AB25: =K25*AA25*$AB$2/1000 -> 0 | AD25: =K25*AC25*$AD$2/1000 -> 0 | AF25: =K25*AE25*$AF$2/1000 -> 0 | AG25: =SUM(AA25+AC25+AE25) -> 0 | AH25: =SUM(AB25+AD25+AF25) -> 0 | AI25: =SUM(Y25+AG25) -> 0 | AJ25: =SUM(Z25,AH25) -> 0 | AL25: =M25*AK25*$AL$2/1000 -> 0 | AN25: =M25*AM25*$AN$2/1000 -> 0 | AP25: =M25*AO25*$AP$2/1000 -> 0 | AQ25: =SUM(AK25+AM25+AO25) -> 0 | AR25: =SUM(AL25+AN25+AP25) -> 0 | AT25: =O25*AS25*$AT$2/1000 -> 0 | AV25: =O25*AU25*$AV$2/1000 -> 0 | AX25: =O25*AW25*$AX$2/1000 -> 0 | AY25: =SUM(AS25+AU25+AW25) -> 0 | AZ25: =SUM(AT25+AV25+AX25) -> 0 | BA25: =SUM(AQ25+AY25) -> 0 | BB25: =SUM(AR25,AZ25) -> 0
A26: 20 | E26: F32E6_CPN | F26: 1256A | G26: 구 | H26: SY | M26: 14.38 | O26: 14.38 | Q26: =SUM(AI26+BA26) -> 23.786 | R26: =SUM(AJ26+BB26) -> 450.40285 | T26: =I26*S26*$T$2/1000 -> 0 | V26: =I26*U26*$V$2/1000 -> 0 | X26: =I26*W26*$X$2/1000 -> 0 | Y26: =SUM(S26+U26+W26) -> 0 | Z26: =SUM(T26+V26+X26) -> 0 | AB26: =K26*AA26*$AB$2/1000 -> 0 | AD26: =K26*AC26*$AD$2/1000 -> 0 | AF26: =K26*AE26*$AF$2/1000 -> 0 | AG26: =SUM(AA26+AC26+AE26) -> 0 | AH26: =SUM(AB26+AD26+AF26) -> 0 | AI26: =SUM(Y26+AG26) -> 0 | AJ26: =SUM(Z26,AH26) -> 0 | AL26: =M26*AK26*$AL$2/1000 -> 0 | AM26: 0.12 | AN26: =M26*AM26*$AN$2/1000 -> 2.2826064 | AO26: 4.262 | AP26: =M26*AO26*$AP$2/1000 -> 81.745348 | AQ26: =SUM(AK26+AM26+AO26) -> 4.382 | AR26: =SUM(AL26+AN26+AP26) -> 84.027954 | AS26: 4.752 | AT26: =O26*AS26*$AT$2/1000 -> 92.299093 | AU26: 6.912 | AV26: =O26*AU26*$AV$2/1000 -> 129.35307 | AW26: 7.74 | AX26: =O26*AW26*$AX$2/1000 -> 144.72272 | AY26: =SUM(AS26+AU26+AW26) -> 19.404 | AZ26: =SUM(AT26+AV26+AX26) -> 366.37489 | BA26: =SUM(AQ26+AY26) -> 23.786 | BB26: =SUM(AR26,AZ26) -> 450.40285
A27: 21 | E27: F32E1P_RPN | F27: 882B | G27: 구 | H27: SY | I27: 9.73 | K27: 9.72 | M27: 9.72 | O27: 9.72 | Q27: =SUM(AI27+BA27) -> 69.224 | R27: =SUM(AJ27+BB27) -> 876.53863 | S27: 5.362 | T27: =I27*S27*$T$2/1000 -> 64.990463 | U27: 9.45 | V27: =I27*U27*$V$2/1000 -> 117.16262 | W27: 8.613 | X27: =I27*W27*$X$2/1000 -> 109.23329 | Y27: =SUM(S27+U27+W27) -> 23.425 | Z27: =SUM(T27+V27+X27) -> 291.38637 | AA27: 8.895 | AB27: =K27*AA27*$AB$2/1000 -> 114.41345 | AC27: 10.854 | AD27: =K27*AC27*$AD$2/1000 -> 140.00916 | AE27: 9.45 | AF27: =K27*AE27*$AF$2/1000 -> 119.43133 | AG27: =SUM(AA27+AC27+AE27) -> 29.199 | AH27: =SUM(AB27+AD27+AF27) -> 373.85394 | AI27: =SUM(Y27+AG27) -> 52.624 | AJ27: =SUM(Z27,AH27) -> 665.24031 | AK27: 5.206 | AL27: =M27*AK27*$AL$2/1000 -> 64.711765 | AM27: 7.641 | AN27: =M27*AM27*$AN$2/1000 -> 98.244301 | AO27: 1.863 | AP27: =M27*AO27*$AP$2/1000 -> 24.152931 | AQ27: =SUM(AK27+AM27+AO27) -> 14.71 | AR27: =SUM(AL27+AN27+AP27) -> 187.109 | AS27: 0.594 | AT27: =O27*AS27*$AT$2/1000 -> 7.7985673 | AU27: 0.999 | AV27: =O27*AU27*$AV$2/1000 -> 12.637055 | AW27: 0.297 | AX27: =O27*AW27*$AX$2/1000 -> 3.7537003 | AY27: =SUM(AS27+AU27+AW27) -> 1.89 | AZ27: =SUM(AT27+AV27+AX27) -> 24.189323 | BA27: =SUM(AQ27+AY27) -> 16.6 | BB27: =SUM(AR27,AZ27) -> 211.29832
A28: 22 | E28: 소 계 | Q28: =SUM(Q25:Q27) -> 93.01 | R28: =SUM(R25:R27) -> 1326.9415 | S28: =SUM(S25:S27) -> 5.362 | T28: =SUM(T25:T27) -> 64.990463 | U28: =SUM(U25:U27) -> 9.45 | V28: =SUM(V25:V27) -> 117.16262 | W28: =SUM(W25:W27) -> 8.613 | X28: =SUM(X25:X27) -> 109.23329 | ... BB28: =SUM(BB25:BB27) -> 661.70117
A29: 23 | C29: 제품계 | Q29: =+Q24+Q28 -> 288.669 | R29: =+R24+R28 -> 2670.7988 | S29: =+S24+S28 -> 9.73 | T29: =+T24+T28 -> 101.17427 | U29: =+U24+U28 -> 34.225 | V29: =+V24+V28 -> 286.00815 | W29: =+W24+W28 -> 27.001 | X29: =+X24+X28 -> 232.03055 | ... BB29: =+BB24+BB28 -> 1244.868
A30: 24 | C30: SMPS | D30: TV | E30: P32SF_FPN | F30: 844A | G30: 구 | H30: QD | I30: 5.6 | K30: 5.6 | M30: 5.6 | O30: 5.6 | Q30: =SUM(AI30+BA30) -> 0 | R30: =SUM(AJ30+BB30) -> 0 | T30: =I30*S30*$T$2/1000 -> 0 | V30: =I30*U30*$V$2/1000 -> 0 | X30: =I30*W30*$X$2/1000 -> 0 | Y30: =SUM(S30+U30+W30) -> 0 | Z30: =SUM(T30+V30+X30) -> 0 | AB30: =K30*AA30*$AB$2/1000 -> 0 | AD30: =K30*AC30*$AD$2/1000 -> 0 | AF30: =K30*AE30*$AF$2/1000 -> 0 | AG30: =SUM(AA30+AC30+AE30) -> 0 | AH30: =SUM(AB30+AD30+AF30) -> 0 | AI30: =SUM(Y30+AG30) -> 0 | AJ30: =SUM(Z30,AH30) -> 0 | AL30: =M30*AK30*$AL$2/1000 -> 0 | AN30: =M30*AM30*$AN$2/1000 -> 0 | AP30: =M30*AO30*$AP$2/1000 -> 0 | AQ30: =SUM(AK30+AM30+AO30) -> 0 | AR30: =SUM(AL30+AN30+AP30) -> 0 | AT30: =O30*AS30*$AT$2/1000 -> 0 | AV30: =O30*AU30*$AV$2/1000 -> 0 | AX30: =O30*AW30*$AX$2/1000 -> 0 | AY30: =SUM(AS30+AU30+AW30) -> 0 | AZ30: =SUM(AT30+AV30+AX30) -> 0 | BA30: =SUM(AQ30+AY30) -> 0 | BB30: =SUM(AR30,AZ30) -> 0
A31: 25 | E31: P32SFN_FPN | F31: 844B | G31: 구 | H31: QD | I31: 7.03 | K31: 7.03 | M31: 7.03 | O31: 7.03 | Q31: =SUM(AI31+BA31) -> 0 | R31: =SUM(AJ31+BB31) -> 0 | T31: =I31*S31*$T$2/1000 -> 0 | V31: =I31*U31*$V$2/1000 -> 0 | X31: =I31*W31*$X$2/1000 -> 0 | Y31: =SUM(S31+U31+W31) -> 0 | Z31: =SUM(T31+V31+X31) -> 0 | AB31: =K31*AA31*$AB$2/1000 -> 0 | AD31: =K31*AC31*$AD$2/1000 -> 0 | AF31: =K31*AE31*$AF$2/1000 -> 0 | AG31: =SUM(AA31+AC31+AE31) -> 0 | AH31: =SUM(AB31+AD31+AF31) -> 0 | AI31: =SUM(Y31+AG31) -> 0 | AJ31: =SUM(Z31,AH31) -> 0 | AL31: =M31*AK31*$AL$2/1000 -> 0 | AN31: =M31*AM31*$AN$2/1000 -> 0 | AP31: =M31*AO31*$AP$2/1000 -> 0 | AQ31: =SUM(AK31+AM31+AO31) -> 0 | AR31: =SUM(AL31+AN31+AP31) -> 0 | AT31: =O31*AS31*$AT$2/1000 -> 0 | AV31: =O31*AU31*$AV$2/1000 -> 0 | AX31: =O31*AW31*$AX$2/1000 -> 0 | AY31: =SUM(AS31+AU31+AW31) -> 0 | AZ31: =SUM(AT31+AV31+AX31) -> 0 | BA31: =SUM(AQ31+AY31) -> 0 | BB31: =SUM(AR31,AZ31) -> 0
A32: 26 | E32: P32MF_KPN | F32: 844C | G32: 구 | H32: QD | I32: 6.45 | K32: 6.45 | M32: 6.45 | O32: 6.45 | Q32: =SUM(AI32+BA32) -> 0 | R32: =SUM(AJ32+BB32) -> 0 | T32: =I32*S32*$T$2/1000 -> 0 | V32: =I32*U32*$V$2/1000 -> 0 | X32: =I32*W32*$X$2/1000 -> 0 | Y32: =SUM(S32+U32+W32) -> 0 | Z32: =SUM(T32+V32+X32) -> 0 | AB32: =K32*AA32*$AB$2/1000 -> 0 | AD32: =K32*AC32*$AD$2/1000 -> 0 | AF32: =K32*AE32*$AF$2/1000 -> 0 | AG32: =SUM(AA32+AC32+AE32) -> 0 | AH32: =SUM(AB32+AD32+AF32) -> 0 | AI32: =SUM(Y32+AG32) -> 0 | AJ32: =SUM(Z32,AH32) -> 0 | AL32: =M32*AK32*$AL$2/1000 -> 0 | AN32: =M32*AM32*$AN$2/1000 -> 0 | AP32: =M32*AO32*$AP$2/1000 -> 0 | AQ32: =SUM(AK32+AM32+AO32) -> 0 | AR32: =SUM(AL32+AN32+AP32) -> 0 | AT32: =O32*AS32*$AT$2/1000 -> 0 | AV32: =O32*AU32*$AV$2/1000 -> 0 | AX32: =O32*AW32*$AX$2/1000 -> 0 | AY32: =SUM(AS32+AU32+AW32) -> 0 | AZ32: =SUM(AT32+AV32+AX32) -> 0 | BA32: =SUM(AQ32+AY32) -> 0 | BB32: =SUM(AR32,AZ32) -> 0
A33: 27 | E33: P32SF_MPN | F33: 844D | G33: 구 | H33: QD | I33: 5.5 | K33: 5.5 | M33: 5.5 | O33: 5.5 | Q33: =SUM(AI33+BA33) -> 0 | R33: =SUM(AJ33+BB33) -> 0 | T33: =I33*S33*$T$2/1000 -> 0 | V33: =I33*U33*$V$2/1000 -> 0 | X33: =I33*W33*$X$2/1000 -> 0 | Y33: =SUM(S33+U33+W33) -> 0 | Z33: =SUM(T33+V33+X33) -> 0 | AB33: =K33*AA33*$AB$2/1000 -> 0 | AD33: =K33*AC33*$AD$2/1000 -> 0 | AF33: =K33*AE33*$AF$2/1000 -> 0 | AG33: =SUM(AA33+AC33+AE33) -> 0 | AH33: =SUM(AB33+AD33+AF33) -> 0 | AI33: =SUM(Y33+AG33) -> 0 | AJ33: =SUM(Z33,AH33) -> 0 | AL33: =M33*AK33*$AL$2/1000 -> 0 | AN33: =M33*AM33*$AN$2/1000 -> 0 | AP33: =M33*AO33*$AP$2/1000 -> 0 | AQ33: =SUM(AK33+AM33+AO33) -> 0 | AR33: =SUM(AL33+AN33+AP33) -> 0 | AT33: =O33*AS33*$AT$2/1000 -> 0 | AV33: =O33*AU33*$AV$2/1000 -> 0 | AX33: =O33*AW33*$AX$2/1000 -> 0 | AY33: =SUM(AS33+AU33+AW33) -> 0 | AZ33: =SUM(AT33+AV33+AX33) -> 0 | BA33: =SUM(AQ33+AY33) -> 0 | BB33: =SUM(AR33,AZ33) -> 0
A34: 28 | E34: P32SFN_MPN | F34: 844E | G34: 구 | H34: QD | I34: 5.95 | K34: 5.95 | M34: 5.95 | O34: 5.95 | Q34: =SUM(AI34+BA34) -> 0.1 | R34: =SUM(AJ34+BB34) -> 0.74118555 | S34: 0.1 | T34: =I34*S34*$T$2/1000 -> 0.74118555 | V34: =I34*U34*$V$2/1000 -> 0 | X34: =I34*W34*$X$2/1000 -> 0 | Y34: =SUM(S34+U34+W34) -> 0.1 | Z34: =SUM(T34+V34+X34) -> 0.74118555 | AB34: =K34*AA34*$AB$2/1000 -> 0 | AD34: =K34*AC34*$AD$2/1000 -> 0 | AF34: =K34*AE34*$AF$2/1000 -> 0 | AG34: =SUM(AA34+AC34+AE34) -> 0 | AH34: =SUM(AB34+AD34+AF34) -> 0 | AI34: =SUM(Y34+AG34) -> 0.1 | AJ34: =SUM(Z34,AH34) -> 0.74118555 | AL34: =M34*AK34*$AL$2/1000 -> 0 | AN34: =M34*AM34*$AN$2/1000 -> 0 | AP34: =M34*AO34*$AP$2/1000 -> 0 | AQ34: =SUM(AK34+AM34+AO34) -> 0 | AR34: =SUM(AL34+AN34+AP34) -> 0 | AT34: =O34*AS34*$AT$2/1000 -> 0 | AV34: =O34*AU34*$AV$2/1000 -> 0 | AX34: =O34*AW34*$AX$2/1000 -> 0 | AY34: =SUM(AS34+AU34+AW34) -> 0 | AZ34: =SUM(AT34+AV34+AX34) -> 0 | BA34: =SUM(AQ34+AY34) -> 0 | BB34: =SUM(AR34,AZ34) -> 0
A35: 29 | E35: P230NQ_NPN | F35: 933A | G35: 구 | H35: SY | I35: 18.7 | K35: 18.7 | M35: 18.7 | O35: 18.7 | Q35: =SUM(AI35+BA35) -> 0.396 | R35: =SUM(AJ35+BB35) -> 9.5059139 | S35: 0.126 | T35: =I35*S35*$T$2/1000 -> 2.9350948 | V35: =I35*U35*$V$2/1000 -> 0 | X35: =I35*W35*$X$2/1000 -> 0 | Y35: =SUM(S35+U35+W35) -> 0.126 | Z35: =SUM(T35,V35,X35) -> 2.9350948 | AB35: =K35*AA35*$AB$2/1000 -> 0 | AD35: =K35*AC35*$AD$2/1000 -> 0 | AF35: =K35*AE35*$AF$2/1000 -> 0 | AG35: =SUM(AA35+AC35+AE35) -> 0 | AH35: =SUM(AB35,AD35,AF35) -> 0 | AI35: =SUM(Y35+AG35) -> 0.126 | AJ35: =SUM(Z35,AH35) -> 2.9350948 | AL35: =M35*AK35*$AL$2/1000 -> 0 | AN35: =M35*AM35*$AN$2/1000 -> 0 | AP35: =M35*AO35*$AP$2/1000 -> 0 | AQ35: =SUM(AK35+AM35+AO35) -> 0 | AR35: =SUM(AL35,AN35,AP35) -> 0 | AT35: =O35*AS35*$AT$2/1000 -> 0 | AU35: 0.27 | AV35: =O35*AU35*$AV$2/1000 -> 6.5708191 | AX35: =O35*AW35*$AX$2/1000 -> 0 | AY35: =SUM(AS35+AU35+AW35) -> 0.27 | AZ35: =SUM(AT35,AV35,AX35) -> 6.5708191 | BA35: =SUM(AQ35+AY35) -> 0.27 | BB35: =SUM(AR35,AZ35) -> 6.5708191
A36: 31 | E36: P230NQ_TPN | F36: 1066B | G36: 구 | H36: SY | I36: 19.73 | K36: 19.72 | M36: 19.72 | O36: 19.72 | Q36: =SUM(AI36+BA36) -> 128.421 | R36: =SUM(AJ36+BB36) -> 3291.9751 | S36: 15.654 | T36: =I36*S36*$T$2/1000 -> 384.73562 | U36: 5.43 | V36: =I36*U36*$V$2/1000 -> 136.51216 | W36: 16.474 | X36: =I36*W36*$X$2/1000 -> 423.65649 | Y36: =SUM(S36+U36+W36) -> 37.558 | Z36: =SUM(T36,V36,X36) -> 944.90426 | AA36: 5.598 | AB36: =K36*AA36*$AB$2/1000 -> 146.08468 | AC36: 9.792 | AD36: =K36*AC36*$AD$2/1000 -> 256.25874 | AE36: 5.211 | AF36: =K36*AE36*$AF$2/1000 -> 133.61283 | AG36: =SUM(AA36+AC36+AE36) -> 20.601 | AH36: =SUM(AB36,AD36,AF36) -> 535.95626 | AI36: =SUM(Y36+AG36) -> 58.159 | AJ36: =SUM(Z36,AH36) -> 1480.8605 | AK36: 6.368 | AL36: =M36*AK36*$AL$2/1000 -> 160.59158 | AM36: 4.196 | AN36: =M36*AM36*$AN$2/1000 -> 109.45442 | AO36: 3.466 | AP36: =M36*AO36*$AP$2/1000 -> 91.16459 | AQ36: =SUM(AK36+AM36+AO36) -> 14.03 | AR36: =SUM(AL36,AN36,AP36) -> 361.21059 | AS36: 7.764 | AT36: =O36*AS36*$AT$2/1000 -> 206.80191 | AU36: 13.86 | AV36: =O36*AU36*$AV$2/1000 -> 355.70034 | AW36: 34.608 | AX36: =O36*AW36*$AX$2/1000 -> 887.40178 | AY36: =SUM(AS36+AU36+AW36) -> 56.232 | AZ36: =SUM(AT36,AV36,AX36) -> 1449.904 | BA36: =SUM(AQ36+AY36) -> 70.262 | BB36: =SUM(AR36,AZ36) -> 1811.1146
A37: 32 | E37: P270NQ_NPN | F37: 934A | G37: 구 | H37: SY | I37: 21.1 | K37: 21.1 | M37: 21.1 | O37: 21.1 | Q37: =SUM(AI37+BA37) -> 0.474 | R37: =SUM(AJ37+BB37) -> 12.70718 | S37: 0.27 | T37: =I37*S37*$T$2/1000 -> 7.0966959 | V37: =I37*U37*$V$2/1000 -> 0 | W37: 0.204 | X37: =I37*W37*$X$2/1000 -> 5.6104841 | Y37: =SUM(S37+U37+W37) -> 0.474 | Z37: =SUM(T37,V37,X37) -> 12.70718 | AB37: =K37*AA37*$AB$2/1000 -> 0 | AD37: =K37*AC37*$AD$2/1000 -> 0 | AF37: =K37*AE37*$AF$2/1000 -> 0 | AG37: =SUM(AA37+AC37+AE37) -> 0 | AH37: =SUM(AB37,AD37,AF37) -> 0 | AI37: =SUM(Y37+AG37) -> 0.474 | AJ37: =SUM(Z37,AH37) -> 12.70718 | AL37: =M37*AK37*$AL$2/1000 -> 0 | AN37: =M37*AM37*$AN$2/1000 -> 0 | AP37: =M37*AO37*$AP$2/1000 -> 0 | AQ37: =SUM(AK37+AM37+AO37) -> 0 | AR37: =SUM(AL37,AN37,AP37) -> 0 | AT37: =O37*AS37*$AT$2/1000 -> 0 | AV37: =O37*AU37*$AV$2/1000 -> 0 | AX37: =O37*AW37*$AX$2/1000 -> 0 | AY37: =SUM(AS37+AU37+AW37) -> 0 | AZ37: =SUM(AT37,AV37,AX37) -> 0 | BA37: =SUM(AQ37+AY37) -> 0 | BB37: =SUM(AR37,AZ37) -> 0
A38: 33 | E38: P270NQB_NPN | F38: 934B | G38: 구 | H38: SY | I38: 20.89 | K38: 20.89 | M38: 20.89 | O38: 20.89 | Q38: =SUM(AI38+BA38) -> 0.168 | R38: =SUM(AJ38+BB38) -> 4.371774 | S38: 0.168 | T38: =I38*S38*$T$2/1000 -> 4.371774 | V38: =I38*U38*$V$2/1000 -> 0 | X38: =I38*W38*$X$2/1000 -> 0 | Y38: =SUM(S38+U38+W38) -> 0.168 | Z38: =SUM(T38,V38,X38) -> 4.371774 | AB38: =K38*AA38*$AB$2/1000 -> 0 | AD38: =K38*AC38*$AD$2/1000 -> 0 | AF38: =K38*AE38*$AF$2/1000 -> 0 | AG38: =SUM(AA38+AC38+AE38) -> 0 | AH38: =SUM(AB38,AD38,AF38) -> 0 | AI38: =SUM(Y38+AG38) -> 0.168 | AJ38: =SUM(Z38,AH38) -> 4.371774 | AL38: =M38*AK38*$AL$2/1000 -> 0 | AN38: =M38*AM38*$AN$2/1000 -> 0 | AP38: =M38*AO38*$AP$2/1000 -> 0 | AQ38: =SUM(AK38+AM38+AO38) -> 0 | AR38: =SUM(AL38,AN38,AP38) -> 0 | AT38: =O38*AS38*$AT$2/1000 -> 0 | AV38: =O38*AU38*$AV$2/1000 -> 0 | AX38: =O38*AW38*$AX$2/1000 -> 0 | AY38: =SUM(AS38+AU38+AW38) -> 0 | AZ38: =SUM(AT38,AV38,AX38) -> 0 | BA38: =SUM(AQ38+AY38) -> 0 | BB38: =SUM(AR38,AZ38) -> 0
A39: 35 | E39: P270NQ_TPN | F39: 1066A | G39: 구 | H39: SY | I39: 21.72 | K39: 21.71 | M39: 21.71 | O39: 21.71 | Q39: =SUM(AI39+BA39) -> 61.064 | R39: =SUM(AJ39+BB39) -> 1729.4952 | S39: 5.22 | T39: =I39*S39*$T$2/1000 -> 141.23434 | U39: 2.322 | V39: =I39*U39*$V$2/1000 -> 64.263808 | W39: 0.856 | X39: =I39*W39*$X$2/1000 -> 24.233788 | Y39: =SUM(S39+U39+W39) -> 8.398 | Z39: =SUM(T39,V39,X39) -> 229.73193 | AA39: 2.544 | AB39: =K39*AA39*$AB$2/1000 -> 73.087281 | AC39: 6.468 | AD39: =K39*AC39*$AD$2/1000 -> 186.35035 | AE39: 0.876 | AF39: =K39*AE39*$AF$2/1000 -> 24.727722 | AG39: =SUM(AA39+AC39+AE39) -> 9.888 | AH39: =SUM(AB39,AD39,AF39) -> 284.16535 | AI39: =SUM(Y39+AG39) -> 18.286 | AJ39: =SUM(Z39,AH39) -> 513.89729 | AK39: 7.8 | AL39: =M39*AK39*$AL$2/1000 -> 216.55451 | AM39: 0.72 | AN39: =M39*AM39*$AN$2/1000 -> 20.676795 | AO39: 4.09 | AP39: =M39*AO39*$AP$2/1000 -> 118.4333 | AQ39: =SUM(AK39+AM39+AO39) -> 12.61 | AR39: =SUM(AL39,AN39,AP39) -> 355.66461 | AS39: 7.404 | AT39: =O39*AS39*$AT$2/1000 -> 217.11426 | AU39: 8.652 | AV39: =O39*AU39*$AV$2/1000 -> 244.45024 | AW39: 14.112 | AX39: =O39*AW39*$AX$2/1000 -> 398.36876 | AY39: =SUM(AS39+AU39+AW39) -> 30.168 | AZ39: =SUM(AT39,AV39,AX39) -> 859.93326 | BA39: =SUM(AQ39+AY39) -> 42.778 | BB39: =SUM(AR39,AZ39) -> 1215.5979
E40: P230NQ_TPN (CKD) | F40: 1066B | G40: 신 | H40: SY | I40: 18.75 | K40: 18.75 | M40: 18.75 | O40: 18.75 | Q40: =SUM(AI40+BA40) -> 7.704 | R40: =SUM(AJ40+BB40) -> 186.87911 | S40: 1.356 | T40: =I40*S40*$T$2/1000 -> 31.671668 | U40: 1.02 | V40: =I40*U40*$V$2/1000 -> 24.369457 | W40: 1.944 | X40: =I40*W40*$X$2/1000 -> 47.510023 | Y40: =SUM(S40+U40+W40) -> 4.32 | Z40: =SUM(T40+V40+X40) -> 103.55115 | AA40: 1.733 | AB40: =K40*AA40*$AB$2/1000 -> 42.999629 | AC40: 0.154 | AD40: =K40*AC40*$AD$2/1000 -> 3.8319724 | AE40: 1.393 | AF40: =K40*AE40*$AF$2/1000 -> 33.960382 | AG40: =SUM(AA40+AC40+AE40) -> 3.28 | AH40: =SUM(AB40+AD40+AF40) -> 80.791984 | AI40: =SUM(Y40+AG40) -> 7.6 | AJ40: =SUM(Z40,AH40) -> 184.34313 | AK40: 0.063 | AL40: =M40*AK40*$AL$2/1000 -> 1.5106179 | AN40: =M40*AM40*$AN$2/1000 -> 0 | AO40: 0.041 | AP40: =M40*AO40*$AP$2/1000 -> 1.0253588 | AQ40: =SUM(AK40+AM40+AO40) -> 0.104 | AR40: =SUM(AL40+AN40+AP40) -> 2.5359767 | AT40: =O40*AS40*$AT$2/1000 -> 0 | AV40: =O40*AU40*$AV$2/1000 -> 0 | AX40: =O40*AW40*$AX$2/1000 -> 0 | AY40: =SUM(AS40+AU40+AW40) -> 0 | AZ40: =SUM(AT40+AV40+AX40) -> 0 | BA40: =SUM(AQ40+AY40) -> 0.104 | BB40: =SUM(AR40,AZ40) -> 2.5359767
...

Sheet Sheet1
C1: ='23년(세부_실적)'!B1 -> ▣ 23년 매출 마감현황
C2: ='23년(세부_실적)'!B2 -> 2024. 01. 19 | V2: ='23년(세부_실적)'!T2 -> 1245.69 | X2: ='23년(세부_실적)'!V2 -> 1274.22 | Z2: ='23년(세부_실적)'!X2 -> 1303.43 | AD2: ='23년(세부_실적)'!AB2 -> 1323.32 | AF2: ='23년(세부_실적)'!AD2-3 -> 1324.09 | AH2: ='23년(세부_실적)'!AF2 -> 1300.23 | AN2: ='23년(세부_실적)'!AL2 -> 1278.83 | AP2: ='23년(세부_실적)'!AN2 -> 1322.79 | AR2: ='23년(세부_실적)'!AP2 -> 1333.8 | AV2: ='23년(세부_실적)'!AT2 -> 1350.71 | AX2: ='23년(세부_실적)'!AV2 -> 1301.41 | AZ2: ='23년(세부_실적)'!AX2 -> 1300.28 | BI2: =V2 -> 1245.69 | BM2: =X2 -> 1274.22 | BQ2: =Z2 -> 1303.43 | BU2: =AD2 -> 1323.32 | BY2: =AF2 -> 1324.09 | CC2: =AH2 -> 1300.23 | CG2: =AN2 -> 1278.83 | CK2: =AP2 -> 1322.79 | CO2: =AR2 -> 1333.8 | CS2: =AV2 -> 1350.71 | CW2: =AX2 -> 1301.41 | DA2: =AZ2 -> 1300.28 | DB2: 매출 | DO2: 원가
C3: ='23년(세부_실적)'!B3 -> 거래선 | D3: ='23년(세부_실적)'!C3 -> 제품 | E3: ='23년(세부_실적)'!D3 -> Set | F3: ='23년(세부_실적)'!E3 -> 모델 | H3: ='23년(세부_실적)'!F3 -> Code | I3: ='23년(세부_실적)'!G3 -> 구분 | J3: ='23년(세부_실적)'!H3 -> 제조지 | K3: ='23년(세부_실적)'!I3 -> 단가 | S3: ='23년(세부_실적)'!Q3 -> 년계 | U3: ='23년(세부_실적)'!S3 -> 1월 | W3: ='23년(세부_실적)'!U3 -> 2월 | Y3: ='23년(세부_실적)'!W3 -> 3월 | AA3: ='23년(세부_실적)'!Y3 -> 1분기 | AC3: ='23년(세부_실적)'!AA3 -> 4월 | AE3: ='23년(세부_실적)'!AC3 -> 5월 | AG3: ='23년(세부_실적)'!AE3 -> 6월 | AI3: ='23년(세부_실적)'!AG3 -> 2분기 | AK3: ='23년(세부_실적)'!AI3 -> 상반기 | AM3: ='23년(세부_실적)'!AK3 -> 7월 | AO3: ='23년(세부_실적)'!AM3 -> 8월 | AQ3: ='23년(세부_실적)'!AO3 -> 9월 | AS3: ='23년(세부_실적)'!AQ3 -> 3분기 | AU3: ='23년(세부_실적)'!AS3 -> 10월 | AW3: ='23년(세부_실적)'!AU3 -> 11월 | AY3: ='23년(세부_실적)'!AW3 -> 12월 | BA3: ='23년(세부_실적)'!AY3 -> 4분기 | BC3: ='23년(세부_실적)'!BA3 -> 하반기 | BF3: 1월 | BJ3: 2월 | BN3: 3월 | BR3: 4월 | BV3: 5월 | BZ3: 6월 | CD3: 7월 | CH3: 8월 | CL3: 9월 | CP3: 10월 | CT3: 11월 | CX3: 12월 | DB3: 1월 | DC3: 2월 | DD3: 3월 | DE3: 4월 | DF3: 5월 | DG3: 6월 | DH3: 7월 | DI3: 8월 | DJ3: 9월 | DK3: 10월 | DL3: 11월 | DM3: 12월 | DO3: 1월 | DP3: 2월 | DQ3: 3월 | DR3: 4월 | DS3: 5월 | DT3: 6월 | DU3: 7월 | DV3: 8월 | DW3: 9월 | DX3: 10월 | DY3: 11월 | DZ3: 12월
K4: ='23년(세부_실적)'!I4 -> 1Q | M4: ='23년(세부_실적)'!K4 -> 2Q | O4: ='23년(세부_실적)'!M4 -> 3Q | Q4: ='23년(세부_실적)'!O4 -> 4Q | BF4: 가공비 | BG4: 재료비 | BH4: 판가 | BJ4: 가공비 | BK4: 재료비 | BL4: 판가 | BN4: 가공비 | BO4: 재료비 | BP4: 판가 | BR4: 가공비 | BS4: 재료비 | BT4: 판가 | BV4: 가공비 | BW4: 재료비 | BX4: 판가 | BZ4: 가공비 | CA4: 재료비 | CB4: 판가 | CD4: 가공비 | CE4: 재료비 | CF4: 판가 | CH4: 가공비 | CI4: 재료비 | CJ4: 판가 | CL4: 가공비 | CM4: 재료비 | CN4: 판가 | CP4: 가공비 | CQ4: 재료비 | CR4: 판가 | CT4: 가공비 | CU4: 재료비 | CV4: 판가 | CX4: 가공비 | CY4: 재료비 | CZ4: 판가
K5: ='23년(세부_실적)'!I5 -> USD | L5: ='23년(세부_실적)'!J5 -> KRW | M5: ='23년(세부_실적)'!K5 -> USD | N5: ='23년(세부_실적)'!L5 -> KRW | O5: ='23년(세부_실적)'!M5 -> USD | P5: ='23년(세부_실적)'!N5 -> KRW | Q5: ='23년(세부_실적)'!O5 -> USD | R5: ='23년(세부_실적)'!P5 -> KRW | S5: K | T5: EA | U5: K | V5: EA | W5: K | X5: EA | Y5: K | Z5: EA | AA5: K | AB5: EA | AC5: K | AD5: EA | AE5: K | AF5: EA | AG5: K | AH5: EA | AI5: K | AJ5: EA | AK5: K | AL5: EA | AM5: K | AN5: EA | AO5: K | AP5: EA | AQ5: K | AR5: EA | AS5: K | AT5: EA | AU5: K | AV5: EA | AW5: K | AX5: EA | AY5: K | AZ5: EA | BA5: K | BB5: EA | BC5: K | BD5: EA | BH5: $ | BI5: \ | BL5: $ | BM5: \ | BP5: $ | BQ5: \ | BT5: $ | BU5: \ | BX5: $ | BY5: \ | CB5: $ | CC5: \ | CF5: $ | CG5: \ | CJ5: $ | CK5: \ | CN5: $ | CO5: \ | CR5: $ | CS5: \ | CV5: $ | CW5: \ | CZ5: $ | DA5: \ | DB5: 15260100472 | DC5: 12915961849 | DD5: 16084860560 | DE5: 17515526429 | DF5: 17791309984 | DG5: 19187531241 | DH5: =+DH6 -> 0 | DI5: =+DI6*CK2 -> 0 | DJ5: =+DJ6*CO2 -> 0 | DK5: =+DK6*CS2 -> 0 | DL5: =+DL6*CW2 -> 0 | DM5: =+DM6*DA2 -> 0 | DO5: =+(DB5-DO6)/1000000 -> #REF! | DP5: =(DC5-DP6)/1000000 -> #REF! | DQ5: =(DD5-DQ6)/1000000 -> #REF! | DR5: =+(DE5-DR6)/1000000 -> #REF! | DS5: =+(DF5-DS6)/1000000 -> #REF! | DT5: =+(DG5-DT6)/1000000 -> #REF!
C6: ='23년(세부_실적)'!B6 -> 합 계 | L6: ='23년(세부_실적)'!J6 -> 0 | M6: ='23년(세부_실적)'!K6 -> 0 | N6: ='23년(세부_실적)'!L6 -> 0 | O6: ='23년(세부_실적)'!M6 -> 0 | P6: ='23년(세부_실적)'!N6 -> 0 | Q6: ='23년(세부_실적)'!O6 -> 0 | R6: ='23년(세부_실적)'!P6 -> 0 | S6: ='23년(세부_실적)'!Q6 -> 19455.781 | T6: =+S6*1000 -> 19455781 | U6: ='23년(세부_실적)'!S6 -> 1499.263 | V6: =+U6*1000 -> 1499263 | W6: ='23년(세부_실적)'!U6 -> 1721.058 | X6: =W6*1000 -> 1721058 | Y6: ='23년(세부_실적)'!W6 -> 1748.564 | Z6: =Y6*1000 -> 1748564 | AA6: ='23년(세부_실적)'!Y6 -> 4968.885 | AB6: =AA6*1000 -> 4968885 | AC6: ='23년(세부_실적)'!AA6 -> 1764.525 | AD6: =AC6*1000 -> 1764525 | AE6: ='23년(세부_실적)'!AC6 -> 1810.281 | AF6: =AE6*1000 -> 1810281 | AG6: ='23년(세부_실적)'!AE6 -> 1716.377 | AH6: =AG6*1000 -> 1716377 | AI6: ='23년(세부_실적)'!AG6 -> 5291.183 | AJ6: =AI6*1000 -> 5291183 | AK6: ='23년(세부_실적)'!AI6 -> 10260.068 | AL6: =AK6*1000 -> 10260068 | AM6: ='23년(세부_실적)'!AK6 -> 1786.742 | AN6: =AM6*1000 -> 1786742 | AO6: ='23년(세부_실적)'!AM6 -> 1754.012 | AP6: =AO6*1000 -> 1754012 | AQ6: ='23년(세부_실적)'!AO6 -> 1702.797 | AR6: =AQ6*1000 -> 1702797 | AS6: ='23년(세부_실적)'!AQ6 -> 5243.551 | AT6: =AS6*1000 -> 5243551 | AU6: ='23년(세부_실적)'!AS6 -> 1225.109 | AV6: =AU6*1000 -> 1225109 | AW6: ='23년(세부_실적)'!AU6 -> 1123.314 | AX6: =AW6*1000 -> 1123314 | AY6: ='23년(세부_실적)'!AW6 -> 1603.739 | AZ6: =AY6*1000 -> 1603739 | BA6: ='23년(세부_실적)'!AY6 -> 3952.162 | BB6: =BA6*1000 -> 3952162 | BC6: ='23년(세부_실적)'!BA6 -> 9195.713 | BD6: =BC6*1000 -> 9195713 | DB6: =SUM(DB7:DB823) -> #REF! | DC6: =SUM(DC7:DC823) -> #REF! | DD6: =SUM(DD7:DD823) -> #REF! | DE6: =SUM(DE7:DE823) -> #REF! | DF6: =SUM(DF7:DF823) -> #REF! | DG6: =SUM(DG7:DG823) -> #REF! | DO6: =SUM(DO7:DO823) -> #REF! | DP6: =SUM(DP7:DP823) -> #REF! | DQ6: =SUM(DQ7:DQ823) -> #REF! | DR6: =SUM(DR7:DR823) -> #REF! | DS6: =SUM(DS7:DS823) -> #REF! | DT6: =SUM(DT7:DT823) -> #REF! | DU6: =SUM(DU7:DU823) -> #REF! | DV6: =SUM(DV7:DV823) -> #REF! | ... DZ6: =SUM(DZ7:DZ823) -> #REF! | EF6: 매출 | EG6: 원가 | EH6: 매출이익
B7: ='23년(세부_실적)'!A7 -> 1 | C7: ='23년(세부_실적)'!B7 -> SEC VD | D7: ='23년(세부_실적)'!C7 -> PD-Board | E7: ='23년(세부_실적)'!D7 -> TV/MFM | F7: ='23년(세부_실적)'!E7 -> L22S0Q_EPN | G7: L22S0Q_EPN | H7: ='23년(세부_실적)'!F7 -> 692A | I7: ='23년(세부_실적)'!G7 -> 구 | J7: ='23년(세부_실적)'!H7 -> QD | K7: ='23년(세부_실적)'!I7 -> 4.12 | L7: ='23년(세부_실적)'!J7 -> 0 | M7: ='23년(세부_실적)'!K7 -> 4.12 | N7: ='23년(세부_실적)'!L7 -> 0 | O7: ='23년(세부_실적)'!M7 -> 4.12 | ... S7: ='23년(세부_실적)'!Q7 -> 0 | T7: =+S7*1000 -> 0 | U7: ='23년(세부_실적)'!S7 -> 0 | V7: =+U7*1000 -> 0 | W7: ='23년(세부_실적)'!U7 -> 0 | X7: =W7*1000 -> 0 | Y7: ='23년(세부_실적)'!W7 -> 0 | Z7: =Y7*1000 -> 0 | AA7: ='23년(세부_실적)'!Y7 -> 0 | AB7: =AA7*1000 -> 0 | AC7: ='23년(세부_실적)'!AA7 -> 0 | AD7: =AC7*1000 -> 0 | AE7: ='23년(세부_실적)'!AC7 -> 0 | AF7: =AE7*1000 -> 0 | AG7: ='23년(세부_실적)'!AE7 -> 0 | AH7: =AG7*1000 -> 0 | AI7: ='23년(세부_실적)'!AG7 -> 0 | AJ7: =AI7*1000 -> 0 | AK7: ='23년(세부_실적)'!AI7 -> 0 | AL7: =AK7*1000 -> 0 | AM7: ='23년(세부_실적)'!AK7 -> 0 | AN7: =AM7*1000 -> 0 | AO7: ='23년(세부_실적)'!AM7 -> 0 | AP7: =AO7*1000 -> 0 | AQ7: ='23년(세부_실적)'!AO7 -> 0 | AR7: =AQ7*1000 -> 0 | AS7: ='23년(세부_실적)'!AQ7 -> 0 | AT7: =AS7*1000 -> 0 | AU7: ='23년(세부_실적)'!AS7 -> 0 | AV7: =AU7*1000 -> 0 | AW7: ='23년(세부_실적)'!AU7 -> 0 | AX7: =AW7*1000 -> 0 | AY7: ='23년(세부_실적)'!AW7 -> 0 | AZ7: =AY7*1000 -> 0 | BA7: ='23년(세부_실적)'!AY7 -> 0 | BB7: =BA7*1000 -> 0 | BC7: ='23년(세부_실적)'!BA7 -> 0 | BD7: =BC7*1000 -> 0 | DB7: =+V7*BH7*$BI$2 -> 0 | DC7: =+X7*BL7*$BM$2 -> 0 | DD7: =+BP7*Z7*$BQ$2 -> 0 | DE7: =+AD7*BT7*$BU$2 -> 0 | DF7: =+BX7*AF7*$BY$2 -> 0 | DG7: =+CB7*AH7*$CC$2 -> 0 | DH7: =+CF7*AN7*$CG$2 -> 0 | DI7: =+CB7*AP7*$AP$2 -> 0 | DJ7: =+CN7*AR7*$AR$2 -> 0 | DK7: =+CR7*AV7*$AV$2 -> 0 | DL7: =+CV7*AX7*$AX$2 -> 0 | DM7: =+CZ7*AZ7*$AZ$2 -> 0 | DO7: =+(BF7+BG7)*V7*$V$2 -> 0 | DP7: =+(BJ7+BK7)*X7*$X$2 -> 0 | DQ7: =+(BN7+BO7)*Z7*$Z$2 -> 0 | DR7: =+(BR7+BS7)*AD7*$AD$2 -> 0 | DS7: =+(BV7+BW7)*AF7*$AF$2 -> 0 | DT7: =+(BZ7+CA7)*AH7*$AH$2 -> 0 | DU7: =+(CD7+CE7)*AN7*$AN$2 -> 0 | DV7: =+(CH7+CI7)*AP7*$AP$2 -> 0 | DW7: =+(CL7+CM7)*AR7*$AR$2 -> 0 | DX7: =+(CP7+CQ7)*AV7*$AV$2 -> 0 | DY7: =+(CT7+CU7)*AX7*$AX$2 -> 0 | DZ7: =+(CX7+CY7)*AZ7*$AZ$2 -> 0 | EF7: =SUM(EF14:EF24) -> #REF! | EG7: =SUM(EG14:EG24) -> #REF! | EH7: =SUM(EH14:EH24) -> #REF!
B8: ='23년(세부_실적)'!A8 -> 2 | F8: ='23년(세부_실적)'!E8 -> L23S0D_EPN | G8: L23S0D_EPN | H8: ='23년(세부_실적)'!F8 -> 746A | I8: ='23년(세부_실적)'!G8 -> 구 | J8: ='23년(세부_실적)'!H8 -> QD | K8: ='23년(세부_실적)'!I8 -> 4.13 | L8: ='23년(세부_실적)'!J8 -> 0 | M8: ='23년(세부_실적)'!K8 -> 4.13 | N8: ='23년(세부_실적)'!L8 -> 0 | O8: ='23년(세부_실적)'!M8 -> 4.13 | ... S8: ='23년(세부_실적)'!Q8 -> 0.028 | T8: =+S8*1000 -> 28 | U8: ='23년(세부_실적)'!S8 -> 0 | V8: =+U8*1000 -> 0 | W8: ='23년(세부_실적)'!U8 -> 0.028 | X8: =W8*1000 -> 28 | Y8: ='23년(세부_실적)'!W8 -> 0 | Z8: =Y8*1000 -> 0 | AA8: ='23년(세부_실적)'!Y8 -> 0.028 | AB8: =AA8*1000 -> 28 | AC8: ='23년(세부_실적)'!AA8 -> 0 | AD8: =AC8*1000 -> 0 | AE8: ='23년(세부_실적)'!AC8 -> 0 | AF8: =AE8*1000 -> 0 | AG8: ='23년(세부_실적)'!AE8 -> 0 | AH8: =AG8*1000 -> 0 | AI8: ='23년(세부_실적)'!AG8 -> 0 | AJ8: =AI8*1000 -> 0 | AK8: ='23년(세부_실적)'!AI8 -> 0.028 | AL8: =AK8*1000 -> 28 | AM8: ='23년(세부_실적)'!AK8 -> 0 | AN8: =AM8*1000 -> 0 | AO8: ='23년(세부_실적)'!AM8 -> 0 | AP8: =AO8*1000 -> 0 | AQ8: ='23년(세부_실적)'!AO8 -> 0 | AR8: =AQ8*1000 -> 0 | AS8: ='23년(세부_실적)'!AQ8 -> 0 | AT8: =AS8*1000 -> 0 | AU8: ='23년(세부_실적)'!AS8 -> 0 | AV8: =AU8*1000 -> 0 | AW8: ='23년(세부_실적)'!AU8 -> 0 | AX8: =AW8*1000 -> 0 | AY8: ='23년(세부_실적)'!AW8 -> 0 | AZ8: =AY8*1000 -> 0 | BA8: ='23년(세부_실적)'!AY8 -> 0 | BB8: =BA8*1000 -> 0 | BC8: ='23년(세부_실적)'!BA8 -> 0 | BD8: =BC8*1000 -> 0 | BF8: 0.66 | BG8: 3.0540567 | BH8: 3.4 | BJ8: 0.66 | BK8: 3.0540567 | BL8: 3.4 | BN8: 0.66 | BO8: 3.0540567 | BP8: 3.4 | BR8: 0.66 | BS8: 3.2041842 | BT8: 3.765 | BV8: 0.66 | BW8: 3.2041842 | BX8: 4.13 | BZ8: 0.66 | CA8: 3.2041842 | CB8: 4.13 | DB8: =+V8*BH8*$BI$2 -> 0 | DC8: =+X8*BL8*$BM$2 -> 121305.74 | DD8: =+BP8*Z8*$BQ$2 -> 0 | DE8: =+AD8*BT8*$BU$2 -> 0 | DF8: =+BX8*AF8*$BY$2 -> 0 | DG8: =+CB8*AH8*$CC$2 -> 0 | DH8: =+CF8*AN8*$CG$2 -> 0 | DI8: =+CB8*AP8*$AP$2 -> 0 | DJ8: =+CN8*AR8*$AR$2 -> 0 | DK8: =+CR8*AV8*$AV$2 -> 0 | DL8: =+CV8*AX8*$AX$2 -> 0 | DM8: =+CZ8*AZ8*$AZ$2 -> 0 | DO8: =+(BF8+BG8)*V8*$V$2 -> 0 | DP8: =+(BJ8+BK8)*X8*$X$2 -> 132510.71 | DQ8: =+(BN8+BO8)*Z8*$Z$2 -> 0 | DR8: =+(BR8+BS8)*AD8*$AD$2 -> 0 | DS8: =+(BV8+BW8)*AF8*$AF$2 -> 0 | DT8: =+(BZ8+CA8)*AH8*$AH$2 -> 0 | DU8: =+(CD8+CE8)*AN8*$AN$2 -> 0 | DV8: =+(CH8+CI8)*AP8*$AP$2 -> 0 | DW8: =+(CL8+CM8)*AR8*$AR$2 -> 0 | DX8: =+(CP8+CQ8)*AV8*$AV$2 -> 0 | DY8: =+(CT8+CU8)*AX8*$AX$2 -> 0 | DZ8: =+(CX8+CY8)*AZ8*$AZ$2 -> 0 | ED8: 삼성 VD | EE8: VD | EF8: =SUM(DB8:DG183) -> #REF! | EG8: =SUM(DO8:DT183) -> #REF! | EH8: =+EF8-EG8 -> #REF!
B9: ='23년(세부_실적)'!A9 -> 3 | F9: ='23년(세부_실적)'!E9 -> L23S0DN_EPN | G9: L23S0DN_EPN | H9: ='23년(세부_실적)'!F9 -> 746B | I9: ='23년(세부_실적)'!G9 -> 구 | J9: ='23년(세부_실적)'!H9 -> QD | K9: ='23년(세부_실적)'!I9 -> 4.3 | L9: ='23년(세부_실적)'!J9 -> 0 | M9: ='23년(세부_실적)'!K9 -> 4.28 | N9: ='23년(세부_실적)'!L9 -> 0 | O9: ='23년(세부_실적)'!M9 -> 4.28 | ... S9: ='23년(세부_실적)'!Q9 -> 34.832 | T9: =+S9*1000 -> 34832 | U9: ='23년(세부_실적)'!S9 -> 1.008 | V9: =+U9*1000 -> 1008 | W9: ='23년(세부_실적)'!U9 -> 0.784 | X9: =W9*1000 -> 784 | Y9: ='23년(세부_실적)'!W9 -> 7.182 | Z9: =Y9*1000 -> 7182 | AA9: ='23년(세부_실적)'!Y9 -> 8.974 | AB9: =AA9*1000 -> 8974 | AC9: ='23년(세부_실적)'!AA9 -> 2.352 | AD9: =AC9*1000 -> 2352 | AE9: ='23년(세부_실적)'!AC9 -> 0.84 | AF9: =AE9*1000 -> 840 | AG9: ='23년(세부_실적)'!AE9 -> 10.248 | AH9: =AG9*1000 -> 10248 | AI9: ='23년(세부_실적)'!AG9 -> 13.44 | AJ9: =AI9*1000 -> 13440 | AK9: ='23년(세부_실적)'!AI9 -> 22.414 | AL9: =AK9*1000 -> 22414 | AM9: ='23년(세부_실적)'!AK9 -> 1.008 | AN9: =AM9*1000 -> 1008 | AO9: ='23년(세부_실적)'!AM9 -> 6.048 | AP9: =AO9*1000 -> 6048 | AQ9: ='23년(세부_실적)'!AO9 -> 3.024 | AR9: =AQ9*1000 -> 3024 | AS9: ='23년(세부_실적)'!AQ9 -> 10.08 | AT9: =AS9*1000 -> 10080 | AU9: ='23년(세부_실적)'!AS9 -> 2.338 | AV9: =AU9*1000 -> 2338 | AW9: ='23년(세부_실적)'!AU9 -> 0 | AX9: =AW9*1000 -> 0 | AY9: ='23년(세부_실적)'!AW9 -> 0 | AZ9: =AY9*1000 -> 0 | BA9: ='23년(세부_실적)'!AY9 -> 2.338 | BB9: =BA9*1000 -> 2338 | BC9: ='23년(세부_실적)'!BA9 -> 12.418 | BD9: =BC9*1000 -> 12418 | BF9: 0.66 | BG9: 3.2676776 | BH9: 3.5 | BJ9: 0.66 | BK9: 3.2676776 | BL9: 3.5 | BN9: 0.66 | BO9: 3.2676776 | BP9: 3.5 | BR9: 0.66 | BS9: 3.4607031 | BT9: 3.9 | BV9: 0.66 | BW9: 3.4607031 | BX9: 4.3 | BZ9: 0.66 | CA9: 3.4607031 | CB9: 4.3 | DB9: =+V9*BH9*$BI$2 -> 4394794.3 | DC9: =+X9*BL9*$BM$2 -> 3496459.7 | DD9: =+BP9*Z9*$BQ$2 -> 32764320 | DE9: =+AD9*BT9*$BU$2 -> 12138550 | DF9: =+BX9*AF9*$BY$2 -> 4782613.1 | DG9: =+CB9*AH9*$CC$2 -> 57296455 | DH9: =+CF9*AN9*$CG$2 -> 0 | DI9: =+CB9*AP9*$AP$2 -> 34401006 | DJ9: =+CN9*AR9*$AR$2 -> 0 | DK9: =+CR9*AV9*$AV$2 -> 0 | DL9: =+CV9*AX9*$AX$2 -> 0 | DM9: =+CZ9*AZ9*$AZ$2 -> 0 | DO9: =+(BF9+BG9)*V9*$V$2 -> 4931810 | DP9: =+(BJ9+BK9)*X9*$X$2 -> 3923704.7 | DQ9: =+(BN9+BO9)*Z9*$Z$2 -> 36767910 | DR9: =+(BR9+BS9)*AD9*$AD$2 -> 12825477 | DS9: =+(BV9+BW9)*AF9*$AF$2 -> 4583192.7 | DT9: =+(BZ9+CA9)*AH9*$AH$2 -> 54907367 | DU9: =+(CD9+CE9)*AN9*$AN$2 -> 0 | DV9: =+(CH9+CI9)*AP9*$AP$2 -> 0 | DW9: =+(CL9+CM9)*AR9*$AR$2 -> 0 | DX9: =+(CP9+CQ9)*AV9*$AV$2 -> 0 | DY9: =+(CT9+CU9)*AX9*$AX$2 -> 0 | DZ9: =+(CX9+CY9)*AZ9*$AZ$2 -> 0 | EE9: JDM | EF9: =SUM(DB185:DG246) -> #REF! | EG9: =SUM(DO185:DT246) -> #REF! | EH9: =+EF9-EG9 -> #REF!
B10: ='23년(세부_실적)'!A10 -> 4 | F10: ='23년(세부_실적)'!E10 -> L23S0DS_EPN | G10: L23S0DS_EPN | H10: ='23년(세부_실적)'!F10 -> 746C | I10: ='23년(세부_실적)'!G10 -> 구 | J10: ='23년(세부_실적)'!H10 -> QD | K10: ='23년(세부_실적)'!I10 -> 4.27 | L10: ='23년(세부_실적)'!J10 -> 0 | M10: ='23년(세부_실적)'!K10 -> 4.27 | N10: ='23년(세부_실적)'!L10 -> 0 | O10: ='23년(세부_실적)'!M10 -> 4.27 | ... S10: ='23년(세부_실적)'!Q10 -> 0 | T10: =+S10*1000 -> 0 | U10: ='23년(세부_실적)'!S10 -> 0 | V10: =+U10*1000 -> 0 | W10: ='23년(세부_실적)'!U10 -> 0 | X10: =W10*1000 -> 0 | Y10: ='23년(세부_실적)'!W10 -> 0 | Z10: =Y10*1000 -> 0 | AA10: ='23년(세부_실적)'!Y10 -> 0 | AB10: =AA10*1000 -> 0 | AC10: ='23년(세부_실적)'!AA10 -> 0 | AD10: =AC10*1000 -> 0 | AE10: ='23년(세부_실적)'!AC10 -> 0 | AF10: =AE10*1000 -> 0 | AG10: ='23년(세부_실적)'!AE10 -> 0 | AH10: =AG10*1000 -> 0 | AI10: ='23년(세부_실적)'!AG10 -> 0 | AJ10: =AI10*1000 -> 0 | AK10: ='23년(세부_실적)'!AI10 -> 0 | AL10: =AK10*1000 -> 0 | AM10: ='23년(세부_실적)'!AK10 -> 0 | AN10: =AM10*1000 -> 0 | AO10: ='23년(세부_실적)'!AM10 -> 0 | AP10: =AO10*1000 -> 0 | AQ10: ='23년(세부_실적)'!AO10 -> 0 | AR10: =AQ10*1000 -> 0 | AS10: ='23년(세부_실적)'!AQ10 -> 0 | AT10: =AS10*1000 -> 0 | AU10: ='23년(세부_실적)'!AS10 -> 0 | AV10: =AU10*1000 -> 0 | AW10: ='23년(세부_실적)'!AU10 -> 0 | AX10: =AW10*1000 -> 0 | AY10: ='23년(세부_실적)'!AW10 -> 0 | AZ10: =AY10*1000 -> 0 | BA10: ='23년(세부_실적)'!AY10 -> 0 | BB10: =BA10*1000 -> 0 | BC10: ='23년(세부_실적)'!BA10 -> 0 | BD10: =BC10*1000 -> 0 | DB10: =+V10*BH10*$BI$2 -> 0 | DC10: =+X10*BL10*$BM$2 -> 0 | DD10: =+BP10*Z10*$BQ$2 -> 0 | DE10: =+AD10*BT10*$BU$2 -> 0 | DF10: =+BX10*AF10*$BY$2 -> 0 | DG10: =+CB10*AH10*$CC$2 -> 0 | DH10: =+CF10*AN10*$CG$2 -> 0 | DI10: =+CB10*AP10*$AP$2 -> 0 | DJ10: =+CN10*AR10*$AR$2 -> 0 | DK10: =+CR10*AV10*$AV$2 -> 0 | DL10: =+CV10*AX10*$AX$2 -> 0 | DM10: =+CZ10*AZ10*$AZ$2 -> 0 | DO10: =+(BF10+BG10)*V10*$V$2 -> 0 | DP10: =+(BJ10+BK10)*X10*$X$2 -> 0 | DQ10: =+(BN10+BO10)*Z10*$Z$2 -> 0 | DR10: =+(BR10+BS10)*AD10*$AD$2 -> 0 | DS10: =+(BV10+BW10)*AF10*$AF$2 -> 0 | DT10: =+(BZ10+CA10)*AH10*$AH$2 -> 0 | DU10: =+(CD10+CE10)*AN10*$AN$2 -> 0 | DV10: =+(CH10+CI10)*AP10*$AP$2 -> 0 | DW10: =+(CL10+CM10)*AR10*$AR$2 -> 0 | DX10: =+(CP10+CQ10)*AV10*$AV$2 -> 0 | DY10: =+(CT10+CU10)*AX10*$AX$2 -> 0 | DZ10: =+(CX10+CY10)*AZ10*$AZ$2 -> 0 | EE10: TV | EF10: =+SUM(DB7:DG7)+SUM(DB11:DG14)+SUM(DB19:DG23)+SUM(DB30:DG44) -> #REF! | EG10: =+SUM(DO7:DT7)+SUM(DO11:DT14)+SUM(DO19:DT23)+SUM(DO30:DT44) -> #REF! | EH10: =+EF10-EG10 -> #REF!
B11: ='23년(세부_실적)'!A11 -> 5 | F11: ='23년(세부_실적)'!E11 -> L23S0DMN_FPN | G11: L23S0DMN_FPN | H11: ='23년(세부_실적)'!F11 -> 746D | I11: ='23년(세부_실적)'!G11 -> 구 | J11: ='23년(세부_실적)'!H11 -> QD | K11: ='23년(세부_실적)'!I11 -> 5.21 | L11: ='23년(세부_실적)'!J11 -> 0 | M11: ='23년(세부_실적)'!K11 -> 5.21 | N11: ='23년(세부_실적)'!L11 -> 0 | O11: ='23년(세부_실적)'!M11 -> 5.21 | ... S11: ='23년(세부_실적)'!Q11 -> 0 | T11: =+S11*1000 -> 0 | U11: ='23년(세부_실적)'!S11 -> 0 | V11: =+U11*1000 -> 0 | W11: ='23년(세부_실적)'!U11 -> 0 | X11: =W11*1000 -> 0 | Y11: ='23년(세부_실적)'!W11 -> 0 | Z11: =Y11*1000 -> 0 | AA11: ='23년(세부_실적)'!Y11 -> 0 | AB11: =AA11*1000 -> 0 | AC11: ='23년(세부_실적)'!AA11 -> 0 | AD11: =AC11*1000 -> 0 | AE11: ='23년(세부_실적)'!AC11 -> 0 | AF11: =AE11*1000 -> 0 | AG11: ='23년(세부_실적)'!AE11 -> 0 | AH11: =AG11*1000 -> 0 | AI11: ='23년(세부_실적)'!AG11 -> 0 | AJ11: =AI11*1000 -> 0 | AK11: ='23년(세부_실적)'!AI11 -> 0 | AL11: =AK11*1000 -> 0 | AM11: ='23년(세부_실적)'!AK11 -> 0 | AN11: =AM11*1000 -> 0 | AO11: ='23년(세부_실적)'!AM11 -> 0 | AP11: =AO11*1000 -> 0 | AQ11: ='23년(세부_실적)'!AO11 -> 0 | AR11: =AQ11*1000 -> 0 | AS11: ='23년(세부_실적)'!AQ11 -> 0 | AT11: =AS11*1000 -> 0 | AU11: ='23년(세부_실적)'!AS11 -> 0 | AV11: =AU11*1000 -> 0 | AW11: ='23년(세부_실적)'!AU11 -> 0 | AX11: =AW11*1000 -> 0 | AY11: ='23년(세부_실적)'!AW11 -> 0 | AZ11: =AY11*1000 -> 0 | BA11: ='23년(세부_실적)'!AY11 -> 0 | BB11: =BA11*1000 -> 0 | BC11: ='23년(세부_실적)'!BA11 -> 0 | BD11: =BC11*1000 -> 0 | BF11: 0.66 | BG11: 3.9150973 | BJ11: 0.66 | BK11: 3.9150973 | BN11: 0.66 | BO11: 3.9150973 | BR11: 0.66 | BS11: 3.9820478 | BV11: 0.66 | BW11: 3.9820478 | BZ11: 0.66 | CA11: 3.9820478 | DB11: =+V11*BH11*$BI$2 -> 0 | DC11: =+X11*BL11*$BM$2 -> 0 | DD11: =+BP11*Z11*$BQ$2 -> 0 | DE11: =+AD11*BT11*$BU$2 -> 0 | DF11: =+BX11*AF11*$BY$2 -> 0 | DG11: =+CB11*AH11*$CC$2 -> 0 | DH11: =+CF11*AN11*$CG$2 -> 0 | DI11: =+CB11*AP11*$AP$2 -> 0 | DJ11: =+CN11*AR11*$AR$2 -> 0 | DK11: =+CR11*AV11*$AV$2 -> 0 | DL11: =+CV11*AX11*$AX$2 -> 0 | DM11: =+CZ11*AZ11*$AZ$2 -> 0 | DO11: =+(BF11+BG11)*V11*$V$2 -> 0 | DP11: =+(BJ11+BK11)*X11*$X$2 -> 0 | DQ11: =+(BN11+BO11)*Z11*$Z$2 -> 0 | DR11: =+(BR11+BS11)*AD11*$AD$2 -> 0 | DS11: =+(BV11+BW11)*AF11*$AF$2 -> 0 | DT11: =+(BZ11+CA11)*AH11*$AH$2 -> 0 | DU11: =+(CD11+CE11)*AN11*$AN$2 -> 0 | DV11: =+(CH11+CI11)*AP11*$AP$2 -> 0 | DW11: =+(CL11+CM11)*AR11*$AR$2 -> 0 | DX11: =+(CP11+CQ11)*AV11*$AV$2 -> 0 | DY11: =+(CT11+CU11)*AX11*$AX$2 -> 0 | DZ11: =+(CX11+CY11)*AZ11*$AZ$2 -> 0 | EE11: MNT | EF11: =SUM(DB8:DG10)+SUM(DB15:DG18)+SUM(DB25:DG27)+SUM(DB46:DG71)+SUM(DB107:DG143)+SUM(DB153:DG154)+SUM(DB185:DG203) -> #REF! | EG11: =SUM(DO8:DT10)+SUM(DO15:DT18)+SUM(DO25:DT27)+SUM(DO46:DT71)+SUM(DO107:DT143)+SUM(DO153:DT154)+SUM(DO185:DT203) -> #REF! | EH11: =+EF11-EG11 -> #REF!
B12: ='23년(세부_실적)'!A12 -> 6 | F12: ='23년(세부_실적)'!E12 -> L23S0DF_FPN | G12: L23S0DF_FPN | H12: ='23년(세부_실적)'!F12 -> 746E | I12: ='23년(세부_실적)'!G12 -> 구 | J12: ='23년(세부_실적)'!H12 -> QD | K12: ='23년(세부_실적)'!I12 -> 6.32 | L12: ='23년(세부_실적)'!J12 -> 0 | M12: ='23년(세부_실적)'!K12 -> 6.32 | N12: ='23년(세부_실적)'!L12 -> 0 | O12: ='23년(세부_실적)'!M12 -> 6.32 | ... S12: ='23년(세부_실적)'!Q12 -> 0 | T12: =+S12*1000 -> 0 | U12: ='23년(세부_실적)'!S12 -> 0 | V12: =+U12*1000 -> 0 | W12: ='23년(세부_실적)'!U12 -> 0 | X12: =W12*1000 -> 0 | Y12: ='23년(세부_실적)'!W12 -> 0 | Z12: =Y12*1000 -> 0 | AA12: ='23년(세부_실적)'!Y12 -> 0 | AB12: =AA12*1000 -> 0 | AC12: ='23년(세부_실적)'!AA12 -> 0 | AD12: =AC12*1000 -> 0 | AE12: ='23년(세부_실적)'!AC12 -> 0 | AF12: =AE12*1000 -> 0 | AG12: ='23년(세부_실적)'!AE12 -> 0 | AH12: =AG12*1000 -> 0 | AI12: ='23년(세부_실적)'!AG12 -> 0 | AJ12: =AI12*1000 -> 0 | AK12: ='23년(세부_실적)'!AI12 -> 0 | AL12: =AK12*1000 -> 0 | AM12: ='23년(세부_실적)'!AK12 -> 0 | AN12: =AM12*1000 -> 0 | AO12: ='23년(세부_실적)'!AM12 -> 0 | AP12: =AO12*1000 -> 0 | AQ12: ='23년(세부_실적)'!AO12 -> 0 | AR12: =AQ12*1000 -> 0 | AS12: ='23년(세부_실적)'!AQ12 -> 0 | AT12: =AS12*1000 -> 0 | AU12: ='23년(세부_실적)'!AS12 -> 0 | AV12: =AU12*1000 -> 0 | AW12: ='23년(세부_실적)'!AU12 -> 0 | AX12: =AW12*1000 -> 0 | AY12: ='23년(세부_실적)'!AW12 -> 0 | AZ12: =AY12*1000 -> 0 | BA12: ='23년(세부_실적)'!AY12 -> 0 | BB12: =BA12*1000 -> 0 | BC12: ='23년(세부_실적)'!BA12 -> 0 | BD12: =BC12*1000 -> 0 | DB12: =+V12*BH12*$BI$2 -> 0 | DC12: =+X12*BL12*$BM$2 -> 0 | DD12: =+BP12*Z12*$BQ$2 -> 0 | DE12: =+AD12*BT12*$BU$2 -> 0 | DF12: =+BX12*AF12*$BY$2 -> 0 | DG12: =+CB12*AH12*$CC$2 -> 0 | DH12: =+CF12*AN12*$CG$2 -> 0 | DI12: =+CB12*AP12*$AP$2 -> 0 | DJ12: =+CN12*AR12*$AR$2 -> 0 | DK12: =+CR12*AV12*$AV$2 -> 0 | DL12: =+CV12*AX12*$AX$2 -> 0 | DM12: =+CZ12*AZ12*$AZ$2 -> 0 | DO12: =+(BF12+BG12)*V12*$V$2 -> 0 | DP12: =+(BJ12+BK12)*X12*$X$2 -> 0 | DQ12: =+(BN12+BO12)*Z12*$Z$2 -> 0 | DR12: =+(BR12+BS12)*AD12*$AD$2 -> 0 | DS12: =+(BV12+BW12)*AF12*$AF$2 -> 0 | DT12: =+(BZ12+CA12)*AH12*$AH$2 -> 0 | DU12: =+(CD12+CE12)*AN12*$AN$2 -> 0 | DV12: =+(CH12+CI12)*AP12*$AP$2 -> 0 | DW12: =+(CL12+CM12)*AR12*$AR$2 -> 0 | DX12: =+(CP12+CQ12)*AV12*$AV$2 -> 0 | DY12: =+(CT12+CU12)*AX12*$AX$2 -> 0 | DZ12: =+(CX12+CY12)*AZ12*$AZ$2 -> 0 | EE12: AV | EF12: =SUM(DB78:DG105)+SUM(DB149:DG152)+SUM(DB155:DG160)+SUM(DB208:DG245) -> #REF! | EG12: =SUM(DO78:DT105)+SUM(DO149:DT152)+SUM(DO155:DT160)+SUM(DO208:DT245) -> #REF! | EH12: =+EF12-EG12 -> #REF!
B13: ='23년(세부_실적)'!A13 -> 7 | F13: ='23년(세부_실적)'!E13 -> L23S0DSR_MPN | G13: L23S0DSR_MPN | H13: ='23년(세부_실적)'!F13 -> 746F | I13: ='23년(세부_실적)'!G13 -> 구 | J13: ='23년(세부_실적)'!H13 -> QD | K13: ='23년(세부_실적)'!I13 -> 5.03 | L13: ='23년(세부_실적)'!J13 -> 0 | M13: ='23년(세부_실적)'!K13 -> 5.02 | N13: ='23년(세부_실적)'!L13 -> 0 | O13: ='23년(세부_실적)'!M13 -> 5.02 | ... S13: ='23년(세부_실적)'!Q13 -> 126.203 | T13: =+S13*1000 -> 126203 | U13: ='23년(세부_실적)'!S13 -> 0 | V13: =+U13*1000 -> 0 | W13: ='23년(세부_실적)'!U13 -> 20.303 | X13: =W13*1000 -> 20303 | Y13: ='23년(세부_실적)'!W13 -> 6.962 | Z13: =Y13*1000 -> 6962 | AA13: ='23년(세부_실적)'!Y13 -> 27.265 | AB13: =AA13*1000 -> 27265 | AC13: ='23년(세부_실적)'!AA13 -> 19.536 | AD13: =AC13*1000 -> 19536 | AE13: ='23년(세부_실적)'!AC13 -> 6.048 | AF13: =AE13*1000 -> 6048 | AG13: ='23년(세부_실적)'!AE13 -> 12.24 | AH13: =AG13*1000 -> 12240 | AI13: ='23년(세부_실적)'!AG13 -> 37.824 | AJ13: =AI13*1000 -> 37824 | AK13: ='23년(세부_실적)'!AI13 -> 65.089 | AL13: =AK13*1000 -> 65089 | AM13: ='23년(세부_실적)'!AK13 -> 13.632 | AN13: =AM13*1000 -> 13632 | AO13: ='23년(세부_실적)'!AM13 -> 14.4 | AP13: =AO13*1000 -> 14400 | AQ13: ='23년(세부_실적)'!AO13 -> 15.96 | AR13: =AQ13*1000 -> 15960 | AS13: ='23년(세부_실적)'!AQ13 -> 43.992 | AT13: =AS13*1000 -> 43992 | AU13: ='23년(세부_실적)'!AS13 -> 3.61 | AV13: =AU13*1000 -> 3610 | AW13: ='23년(세부_실적)'!AU13 -> 0 | AX13: =AW13*1000 -> 0 | AY13: ='23년(세부_실적)'!AW13 -> 13.512 | AZ13: =AY13*1000 -> 13512 | BA13: ='23년(세부_실적)'!AY13 -> 17.122 | BB13: =BA13*1000 -> 17122 | BC13: ='23년(세부_실적)'!BA13 -> 61.114 | BD13: =BC13*1000 -> 61114 | BF13: 0.66 | BG13: 3.3310047 | BH13: 3.5 | BJ13: 0.66 | BK13: 3.3310047 | BL13: 3.5 | BN13: 0.66 | BO13: 3.3310047 | BP13: 3.5 | BR13: 0.66 | BS13: 3.5337022 | BT13: 4.04 | BV13: 0.66 | BW13: 3.5337022 | BX13: 4.58 | BZ13: 0.66 | CA13: 3.5337022 | CB13: 4.58 | DB13: =+V13*BH13*$BI$2 -> 0 | DC13: =+X13*BL13*$BM$2 -> 90546710 | DD13: =+BP13*Z13*$BQ$2 -> 31760679 | DE13: =+AD13*BT13*$BU$2 -> 1.0444361e+08 | DF13: =+BX13*AF13*$BY$2 -> 36677081 | DG13: =+CB13*AH13*$CC$2 -> 72889854 | DH13: =+CF13*AN13*$CG$2 -> 0 | DI13: =+CB13*AP13*$AP$2 -> 87240646 | DJ13: =+CN13*AR13*$AR$2 -> 0 | DK13: =+CR13*AV13*$AV$2 -> 0 | DL13: =+CV13*AX13*$AX$2 -> 0 | DM13: =+CZ13*AZ13*$AZ$2 -> 0 | DO13: =+(BF13+BG13)*V13*$V$2 -> 0 | DP13: =+(BJ13+BK13)*X13*$X$2 -> 1.0324924e+08 | DQ13: =+(BN13+BO13)*Z13*$Z$2 -> 36216291 | DR13: =+(BR13+BS13)*AD13*$AD$2 -> 1.0841718e+08 | DS13: =+(BV13+BW13)*AF13*$AF$2 -> 33583571 | DT13: =+(BZ13+CA13)*AH13*$AH$2 -> 66741995 | DU13: =+(CD13+CE13)*AN13*$AN$2 -> 0 | DV13: =+(CH13+CI13)*AP13*$AP$2 -> 0 | DW13: =+(CL13+CM13)*AR13*$AR$2 -> 0 | DX13: =+(CP13+CQ13)*AV13*$AV$2 -> 0 | DY13: =+(CT13+CU13)*AX13*$AX$2 -> 0 | DZ13: =+(CX13+CY13)*AZ13*$AZ$2 -> 0 | EE13: STB외 | EF13: =SUM(DB162:DG175)+SUM(DB204:DG207) -> #REF! | EG13: =SUM(DO162:DT175)+SUM(DO204:DT207) -> #REF! | EH13: =+EF13-EG13 -> #REF!
