Workbook

Sheet 26년(세부_실적)
B1: ▣ 26년 매출 마감현황
B2: 2026. 05. 22 | T2: 1443.65 | V2: 1438.26 | X2: 1502.37 | AB2: 1480.76
B3: 거래선 | C3: 제품 | D3: Set | E3: 모델 | F3: Code | G3: 구분 | H3: 제조지 | I3: 단가 | Q3: 년계 | S3: 1월 | U3: 2월 | W3: 3월 | Y3: 1분기 | AA3: 4월 | AC3: 5월 | AE3: 6월 | AG3: 2분기 | AI3: 상반기 | AK3: 7월 | AM3: 8월 | AO3: 9월 | AQ3: 3분기 | AS3: 10월 | AU3: 11월 | AW3: 12월 | AY3: 4분기 | BA3: 하반기
I4: 1Q | K4: 2Q | M4: 3Q | O4: 4Q
I5: USD | J5: KRW | K5: USD | L5: KRW | M5: USD | N5: KRW | O5: USD | P5: KRW | Q5: 수량 | R5: 금액 | S5: 수량 | T5: 금액 | U5: 수량 | V5: 금액 | W5: 수량 | X5: 금액 | Y5: 수량 | Z5: 금액 | AA5: 수량 | AB5: 금액 | AC5: 수량 | AD5: 금액 | AE5: 수량 | AF5: 금액 | AG5: 수량 | AH5: 금액 | AI5: 수량 | AJ5: 금액 | AK5: 수량 | AL5: 금액 | AM5: 수량 | AN5: 금액 | AO5: 수량 | AP5: 금액 | AQ5: 수량 | AR5: 금액 | AS5: 수량 | AT5: 금액 | AU5: 수량 | AV5: 금액 | AW5: 수량 | AX5: 금액 | AY5: 수량 | AZ5: 금액 | BA5: 수량 | BB5: 금액
B6: 합 계 | Q6: =SUM(Q290,Q442,Q544,Q547,Q602,Q606,Q626,Q931,Q950,Q1315,Q1347,Q1308,Q1310,Q1322,Q1329,Q1333,Q1346) -> 7305.095 | R6: =SUM(R290,R442,R544,R547,R602,R606,R626,R931,R950,R1315,R1347,R1308,R1310,R1322,R1329,R1333,R1346) -> 70528.291 | S6: =SUM(S290,S442,S544,S547,S602,S606,S626,S931,S950,S1315,S1347,S1308,S1310,S1322,S1329,S1333,S1346) -> 2270.627 | T6: =SUM(T290,T442,T544,T547,T602,T606,T626,T931,T950,T1315,T1347,T1308,T1310,T1322,T1329,T1333,T1346) -> 20548.931 | U6: =SUM(U290,U442,U544,U547,U602,U606,U626,U931,U950,U1315,U1347,U1308,U1310,U1322,U1329,U1333,U1346) -> 1917.332 | V6: =SUM(V290,V442,V544,V547,V602,V606,V626,V931,V950,V1315,V1347,V1308,V1310,V1322,V1329,V1333,V1346) -> 18592.85 | W6: =SUM(W290,W442,W544,W547,W602,W606,W626,W931,W950,W1315,W1347,W1308,W1310,W1322,W1329,W1333,W1346) -> 1884.707 | X6: =SUM(X290,X442,X544,X547,X602,X606,X626,X931,X950,X1315,X1347,X1308,X1310,X1322,X1329,X1333,X1346) -> 18719.14 | ... BB6: =SUM(BB290,BB442,BB544,BB547,BB602,BB606,BB626,BB931,BB950,BB1315,BB1347,BB1308,BB1310,BB1322,BB1329,BB1333,BB1346) -> 0
A7: 1 | B7: SEC VD | C7: PD-Board | D7: TV/MFM | E7: L22S0Q_EPN | F7: 692A | G7: 구 | H7: QD | I7: 4.12 | K7: 4.12 | Q7: =SUM(AI7+BA7) -> 0 | R7: =SUM(AJ7+BB7) -> 0 | T7: =I7*S7*$T$2/1000 -> 0 | V7: =I7*U7*$V$2/1000 -> 0 | X7: =I7*W7*$X$2/1000 -> 0 | Y7: =SUM(S7+U7+W7) -> 0 | Z7: =SUM(T7,V7,X7) -> 0 | AB7: =K7*AA7*$AB$2/1000 -> 0 | AD7: =K7*AC7*$AD$2/1000 -> 0 | AF7: =K7*AE7*$AF$2/1000 -> 0 | AG7: =SUM(AA7+AC7+AE7) -> 0 | AH7: =SUM(AB7,AD7,AF7) -> 0 | AI7: =SUM(Y7+AG7) -> 0 | AJ7: =SUM(Z7,AH7) -> 0 | AL7: =M7*AK7*$AL$2/1000 -> 0 | AN7: =M7*AM7*$AN$2/1000 -> 0 | AP7: =M7*AO7*AP2/1000 -> 0 | AQ7: =SUM(AK7+AM7+AO7) -> 0 | AR7: =SUM(AL7,AN7,AP7) -> 0 | AT7: =O7*AS7*$AT$2/1000 -> 0 | AV7: =O7*AU7*$AV$2/1000 -> 0 | AX7: =O7*AW7*$AX$2/1000 -> 0 | AY7: =SUM(AS7+AU7+AW7) -> 0 | AZ7: =SUM(AT7,AV7,AX7) -> 0 | BA7: =SUM(AQ7+AY7) -> 0 | BB7: =SUM(AR7,AZ7) -> 0
A8: 2 | E8: L23S0D_EPN | F8: 746A | G8: 구 | H8: QD | I8: 4.13 | K8: 4.13 | Q8: =SUM(AI8+BA8) -> 0 | R8: =SUM(AJ8+BB8) -> 0 | T8: =I8*S8*$T$2/1000 -> 0 | V8: =I8*U8*$V$2/1000 -> 0 | X8: =I8*W8*$X$2/1000 -> 0 | Y8: =SUM(S8+U8+W8) -> 0 | Z8: =SUM(T8,V8,X8) -> 0 | AB8: =K8*AA8*$AB$2/1000 -> 0 | AD8: =K8*AC8*$AD$2/1000 -> 0 | AF8: =K8*AE8*$AF$2/1000 -> 0 | AG8: =SUM(AA8+AC8+AE8) -> 0 | AH8: =SUM(AB8,AD8,AF8) -> 0 | AI8: =SUM(Y8+AG8) -> 0 | AJ8: =SUM(Z8,AH8) -> 0 | AL8: =M8*AK8*$AL$2/1000 -> 0 | AN8: =K8*AM8*$AN$2/1000 -> 0 | AP8: =M8*AO8*$AP$2/1000 -> 0 | AQ8: =SUM(AK8+AM8+AO8) -> 0 | AR8: =SUM(AL8,AN8,AP8) -> 0 | AT8: =O8*AS8*$AT$2/1000 -> 0 | AV8: =O8*AU8*$AV$2/1000 -> 0 | AX8: =O8*AW8*$AX$2/1000 -> 0 | AY8: =SUM(AS8+AU8+AW8) -> 0 | AZ8: =SUM(AT8,AV8,AX8) -> 0 | BA8: =SUM(AQ8+AY8) -> 0 | BB8: =SUM(AR8,AZ8) -> 0 | BC8: 구
A9: 3 | E9: L23S0DN_EPN | F9: 746B | G9: 구 | H9: QD | I9: 4.27 | K9: 4.27 | Q9: =SUM(AI9+BA9) -> 0 | R9: =SUM(AJ9+BB9) -> 0 | T9: =I9*S9*$T$2/1000 -> 0 | V9: =I9*U9*$V$2/1000 -> 0 | X9: =I9*W9*$X$2/1000 -> 0 | Y9: =SUM(S9+U9+W9) -> 0 | Z9: =SUM(T9,V9,X9) -> 0 | AB9: =K9*AA9*$AB$2/1000 -> 0 | AD9: =K9*AC9*$AD$2/1000 -> 0 | AF9: =K9*AE9*$AF$2/1000 -> 0 | AG9: =SUM(AA9+AC9+AE9) -> 0 | AH9: =SUM(AB9,AD9,AF9) -> 0 | AI9: =SUM(Y9+AG9) -> 0 | AJ9: =SUM(Z9,AH9) -> 0 | AL9: =M9*AK9*$AL$2/1000 -> 0 | AN9: =K9*AM9*$AN$2/1000 -> 0 | AP9: =M9*AO9*$AP$2/1000 -> 0 | AQ9: =SUM(AK9+AM9+AO9) -> 0 | AR9: =SUM(AL9,AN9,AP9) -> 0 | AT9: =O9*AS9*$AT$2/1000 -> 0 | AV9: =O9*AU9*$AV$2/1000 -> 0 | AX9: =O9*AW9*$AX$2/1000 -> 0 | AY9: =SUM(AS9+AU9+AW9) -> 0 | AZ9: =SUM(AT9,AV9,AX9) -> 0 | BA9: =SUM(AQ9+AY9) -> 0 | BB9: =SUM(AR9,AZ9) -> 0 | BC9: 구
A10: 4 | E10: L23S0DS_EPN | F10: 746C | G10: 구 | H10: QD | I10: 4.27 | K10: 4.27 | Q10: =SUM(AI10+BA10) -> 0 | R10: =SUM(AJ10+BB10) -> 0 | T10: =I10*S10*$T$2/1000 -> 0 | V10: =I10*U10*$V$2/1000 -> 0 | X10: =I10*W10*$X$2/1000 -> 0 | Y10: =SUM(S10+U10+W10) -> 0 | Z10: =SUM(T10,V10,X10) -> 0 | AB10: =K10*AA10*$AB$2/1000 -> 0 | AD10: =K10*AC10*$AD$2/1000 -> 0 | AF10: =K10*AE10*$AF$2/1000 -> 0 | AG10: =SUM(AA10+AC10+AE10) -> 0 | AH10: =SUM(AB10,AD10,AF10) -> 0 | AI10: =SUM(Y10+AG10) -> 0 | AJ10: =SUM(Z10,AH10) -> 0 | AL10: =M10*AK10*$AL$2/1000 -> 0 | AN10: =M10*AM10*$AN$2/1000 -> 0 | AP10: =M10*AO10*AP2/1000 -> 0 | AQ10: =SUM(AK10+AM10+AO10) -> 0 | AR10: =SUM(AL10,AN10,AP10) -> 0 | AT10: =O10*AS10*$AT$2/1000 -> 0 | AV10: =O10*AU10*$AV$2/1000 -> 0 | AX10: =O10*AW10*$AX$2/1000 -> 0 | AY10: =SUM(AS10+AU10+AW10) -> 0 | AZ10: =SUM(AT10,AV10,AX10) -> 0 | BA10: =SUM(AQ10+AY10) -> 0 | BB10: =SUM(AR10,AZ10) -> 0 | BC10: 구
A11: 5 | E11: L23S0DMN_FPN | F11: 746D | G11: 구 | H11: QD | I11: 5.21 | K11: 5.21 | Q11: =SUM(AI11+BA11) -> 0 | R11: =SUM(AJ11+BB11) -> 0 | T11: =I11*S11*$T$2/1000 -> 0 | V11: =I11*U11*$V$2/1000 -> 0 | X11: =I11*W11*$X$2/1000 -> 0 | Y11: =SUM(S11+U11+W11) -> 0 | Z11: =SUM(T11,V11,X11) -> 0 | AB11: =K11*AA11*$AB$2/1000 -> 0 | AD11: =K11*AC11*$AD$2/1000 -> 0 | AF11: =K11*AE11*$AF$2/1000 -> 0 | AG11: =SUM(AA11+AC11+AE11) -> 0 | AH11: =SUM(AB11,AD11,AF11) -> 0 | AI11: =SUM(Y11+AG11) -> 0 | AJ11: =SUM(Z11,AH11) -> 0 | AL11: =M11*AK11*$AL$2/1000 -> 0 | AN11: =M11*AM11*$AN$2/1000 -> 0 | AP11: =M11*AO11*AP2/1000 -> 0 | AQ11: =SUM(AK11+AM11+AO11) -> 0 | AR11: =SUM(AL11,AN11,AP11) -> 0 | AT11: =O11*AS11*$AT$2/1000 -> 0 | AV11: =O11*AU11*$AV$2/1000 -> 0 | AX11: =O11*AW11*$AX$2/1000 -> 0 | AY11: =SUM(AS11+AU11+AW11) -> 0 | AZ11: =SUM(AT11,AV11,AX11) -> 0 | BA11: =SUM(AQ11+AY11) -> 0 | BB11: =SUM(AR11,AZ11) -> 0 | BC11: 구
A12: 6 | E12: L23S0DF_FPN | F12: 746E | G12: 구 | H12: QD | I12: 6.32 | K12: 6.32 | Q12: =SUM(AI12+BA12) -> 0 | R12: =SUM(AJ12+BB12) -> 0 | T12: =I12*S12*$T$2/1000 -> 0 | V12: =I12*U12*$V$2/1000 -> 0 | X12: =I12*W12*$X$2/1000 -> 0 | Y12: =SUM(S12+U12+W12) -> 0 | Z12: =SUM(T12,V12,X12) -> 0 | AB12: =K12*AA12*$AB$2/1000 -> 0 | AD12: =K12*AC12*$AD$2/1000 -> 0 | AF12: =K12*AE12*$AF$2/1000 -> 0 | AG12: =SUM(AA12+AC12+AE12) -> 0 | AH12: =SUM(AB12,AD12,AF12) -> 0 | AI12: =SUM(Y12+AG12) -> 0 | AJ12: =SUM(Z12,AH12) -> 0 | AL12: =M12*AK12*$AL$2/1000 -> 0 | AN12: =M12*AM12*$AN$2/1000 -> 0 | AP12: =M12*AO12*AP2/1000 -> 0 | AQ12: =SUM(AK12+AM12+AO12) -> 0 | AR12: =SUM(AL12,AN12,AP12) -> 0 | AT12: =O12*AS12*$AT$2/1000 -> 0 | AV12: =O12*AU12*$AV$2/1000 -> 0 | AX12: =O12*AW12*$AX$2/1000 -> 0 | AY12: =SUM(AS12+AU12+AW12) -> 0 | AZ12: =SUM(AT12,AV12,AX12) -> 0 | BA12: =SUM(AQ12+AY12) -> 0 | BB12: =SUM(AR12,AZ12) -> 0 | BC12: 구
A13: 7 | E13: L23S0DSR_MPN | F13: 746F | G13: 구 | H13: QD | I13: 4.99 | K13: 4.99 | Q13: =SUM(AI13+BA13) -> 0 | R13: =SUM(AJ13+BB13) -> 0 | T13: =I13*S13*$T$2/1000 -> 0 | V13: =I13*U13*$V$2/1000 -> 0 | X13: =I13*W13*$X$2/1000 -> 0 | Y13: =SUM(S13+U13+W13) -> 0 | Z13: =SUM(T13,V13,X13) -> 0 | AB13: =K13*AA13*$AB$2/1000 -> 0 | AD13: =K13*AC13*$AD$2/1000 -> 0 | AF13: =K13*AE13*$AF$2/1000 -> 0 | AG13: =SUM(AA13+AC13+AE13) -> 0 | AH13: =SUM(AB13,AD13,AF13) -> 0 | AI13: =SUM(Y13+AG13) -> 0 | AJ13: =SUM(Z13,AH13) -> 0 | AL13: =M13*AK13*$AL$2/1000 -> 0 | AN13: =M13*AM13*$AN$2/1000 -> 0 | AP13: =M13*AO13*$AP$2/1000 -> 0 | AQ13: =SUM(AK13+AM13+AO13) -> 0 | AR13: =SUM(AL13,AN13,AP13) -> 0 | AT13: =O13*AS13*$AT$2/1000 -> 0 | AV13: =O13*AU13*$AV$2/1000 -> 0 | AX13: =O13*AW13*$AX$2/1000 -> 0 | AY13: =SUM(AS13+AU13+AW13) -> 0 | AZ13: =SUM(AT13,AV13,AX13) -> 0 | BA13: =SUM(AQ13+AY13) -> 0 | BB13: =SUM(AR13,AZ13) -> 0 | BC13: 구
A14: 8 | E14: L23S0DSR_RPN | F14: 746G | G14: 구 | H14: QD | I14: 5.03 | K14: 5.03 | Q14: =SUM(AI14+BA14) -> 0 | R14: =SUM(AJ14+BB14) -> 0 | T14: =I14*S14*$T$2/1000 -> 0 | V14: =I14*U14*$V$2/1000 -> 0 | X14: =I14*W14*$X$2/1000 -> 0 | Y14: =SUM(S14+U14+W14) -> 0 | Z14: =SUM(T14,V14,X14) -> 0 | AB14: =K14*AA14*$AB$2/1000 -> 0 | AD14: =K14*AC14*$AD$2/1000 -> 0 | AF14: =K14*AE14*$AF$2/1000 -> 0 | AG14: =SUM(AA14+AC14+AE14) -> 0 | AH14: =SUM(AB14,AD14,AF14) -> 0 | AI14: =SUM(Y14+AG14) -> 0 | AJ14: =SUM(Z14,AH14) -> 0 | AL14: =M14*AK14*$AL$2/1000 -> 0 | AN14: =M14*AM14*$AN$2/1000 -> 0 | AP14: =M14*AO14*$AP$2/1000 -> 0 | AQ14: =SUM(AK14+AM14+AO14) -> 0 | AR14: =SUM(AL14,AN14,AP14) -> 0 | AT14: =O14*AS14*$AT$2/1000 -> 0 | AV14: =O14*AU14*$AV$2/1000 -> 0 | AX14: =O14*AW14*$AX$2/1000 -> 0 | AY14: =SUM(AS14+AU14+AW14) -> 0 | AZ14: =SUM(AT14,AV14,AX14) -> 0 | BA14: =SUM(AQ14+AY14) -> 0 | BB14: =SUM(AR14,AZ14) -> 0 | BC14: 구
A15: 9 | E15: L32S0X_EPN | F15: 750A | G15: 구 | H15: QD | I15: 10.06 | K15: 10.06 | Q15: =SUM(AI15+BA15) -> 0 | R15: =SUM(AJ15+BB15) -> 0 | T15: =I15*S15*$T$2/1000 -> 0 | V15: =I15*U15*$V$2/1000 -> 0 | X15: =I15*W15*$X$2/1000 -> 0 | Y15: =SUM(S15+U15+W15) -> 0 | Z15: =SUM(T15,V15,X15) -> 0 | AB15: =K15*AA15*$AB$2/1000 -> 0 | AD15: =K15*AC15*$AD$2/1000 -> 0 | AF15: =K15*AE15*$AF$2/1000 -> 0 | AG15: =SUM(AA15+AC15+AE15) -> 0 | AH15: =SUM(AB15,AD15,AF15) -> 0 | AI15: =SUM(Y15+AG15) -> 0 | AJ15: =SUM(Z15,AH15) -> 0 | AL15: =M15*AK15*$AL$2/1000 -> 0 | AN15: =M15*AM15*$AN$2/1000 -> 0 | AP15: =M15*AO15*$AP$2/1000 -> 0 | AQ15: =SUM(AK15+AM15+AO15) -> 0 | AR15: =SUM(AL15,AN15,AP15) -> 0 | AT15: =O15*AS15*$AT$2/1000 -> 0 | AV15: =O15*AU15*$AV$2/1000 -> 0 | AX15: =O15*AW15*$AX$2/1000 -> 0 | AY15: =SUM(AS15+AU15+AW15) -> 0 | AZ15: =SUM(AT15,AV15,AX15) -> 0 | BA15: =SUM(AQ15+AY15) -> 0 | BB15: =SUM(AR15,AZ15) -> 0 | BC15: 구
A16: 10 | E16: L32S0XN_EPN | F16: 750B | G16: 구 | H16: QD | I16: 12.19 | K16: 12.19 | Q16: =SUM(AI16+BA16) -> 0 | R16: =SUM(AJ16+BB16) -> 0 | T16: =I16*S16*$T$2/1000 -> 0 | V16: =I16*U16*$V$2/1000 -> 0 | X16: =I16*W16*$X$2/1000 -> 0 | Y16: =SUM(S16+U16+W16) -> 0 | Z16: =SUM(T16,V16,X16) -> 0 | AB16: =K16*AA16*$AB$2/1000 -> 0 | AD16: =K16*AC16*$AD$2/1000 -> 0 | AF16: =K16*AE16*$AF$2/1000 -> 0 | AG16: =SUM(AA16+AC16+AE16) -> 0 | AH16: =SUM(AB16,AD16,AF16) -> 0 | AI16: =SUM(Y16+AG16) -> 0 | AJ16: =SUM(Z16,AH16) -> 0 | AL16: =M16*AK16*$AL$2/1000 -> 0 | AN16: =M16*AM16*$AN$2/1000 -> 0 | AP16: =M16*AO16*$AP$2/1000 -> 0 | AQ16: =SUM(AK16+AM16+AO16) -> 0 | AR16: =SUM(AL16,AN16,AP16) -> 0 | AT16: =O16*AS16*$AT$2/1000 -> 0 | AV16: =O16*AU16*$AV$2/1000 -> 0 | AX16: =O16*AW16*$AX$2/1000 -> 0 | AY16: =SUM(AS16+AU16+AW16) -> 0 | AZ16: =SUM(AT16,AV16,AX16) -> 0 | BA16: =SUM(AQ16+AY16) -> 0 | BB16: =SUM(AR16,AZ16) -> 0 | BC16: 구
A17: 11 | E17: F24SFD_APN | F17: 1122A | G17: 신 | H17: SY | I17: 7.24 | K17: 7.19 | Q17: =SUM(AI17+BA17) -> 6.84 | R17: =SUM(AJ17+BB17) -> 72.086117 | S17: 3.87 | T17: =I17*S17*$T$2/1000 -> 40.449341 | U17: 1.44 | V17: =I17*U17*$V$2/1000 -> 14.994723 | W17: 1.53 | X17: =I17*W17*$X$2/1000 -> 16.642053 | Y17: =SUM(S17+U17+W17) -> 6.84 | Z17: =SUM(T17,V17,X17) -> 72.086117 | AB17: =K17*AA17*$AB$2/1000 -> 0 | AD17: =K17*AC17*$AD$2/1000 -> 0 | AF17: =K17*AE17*$AF$2/1000 -> 0 | AG17: =SUM(AA17+AC17+AE17) -> 0 | AH17: =SUM(AB17,AD17,AF17) -> 0 | AI17: =SUM(Y17+AG17) -> 6.84 | AJ17: =SUM(Z17,AH17) -> 72.086117 | AL17: =M17*AK17*$AL$2/1000 -> 0 | AN17: =M17*AM17*$AN$2/1000 -> 0 | AP17: =M17*AO17*$AP$2/1000 -> 0 | AQ17: =SUM(AK17+AM17+AO17) -> 0 | AR17: =SUM(AL17,AN17,AP17) -> 0 | AT17: =O17*AS17*$AT$2/1000 -> 0 | AV17: =O17*AU17*$AV$2/1000 -> 0 | AX17: =O17*AW17*$AX$2/1000 -> 0 | AY17: =SUM(AS17+AU17+AW17) -> 0 | AZ17: =SUM(AT17,AV17,AX17) -> 0 | BA17: =SUM(AQ17+AY17) -> 0 | BB17: =SUM(AR17,AZ17) -> 0 | BC17: 구
A18: 12 | E18: F24SFDN_APN | F18: 1122B | G18: 신 | H18: SY | I18: 7.78 | K18: 7.78 | Q18: =SUM(AI18+BA18) -> 0.998 | R18: =SUM(AJ18+BB18) -> 11.279924 | S18: 0.45 | T18: =I18*S18*$T$2/1000 -> 5.0542187 | U18: 0.36 | V18: =I18*U18*$V$2/1000 -> 4.0282786 | W18: 0.188 | X18: =I18*W18*$X$2/1000 -> 2.1974265 | Y18: =SUM(S18+U18+W18) -> 0.998 | Z18: =SUM(T18,V18,X18) -> 11.279924 | AB18: =K18*AA18*$AB$2/1000 -> 0 | AD18: =K18*AC18*$AD$2/1000 -> 0 | AF18: =K18*AE18*$AF$2/1000 -> 0 | AG18: =SUM(AA18+AC18+AE18) -> 0 | AH18: =SUM(AB18,AD18,AF18) -> 0 | AI18: =SUM(Y18+AG18) -> 0.998 | AJ18: =SUM(Z18,AH18) -> 11.279924 | AL18: =M18*AK18*$AL$2/1000 -> 0 | AN18: =M18*AM18*$AN$2/1000 -> 0 | AP18: =M18*AO18*$AP$2/1000 -> 0 | AQ18: =SUM(AK18+AM18+AO18) -> 0 | AR18: =SUM(AL18,AN18,AP18) -> 0 | AT18: =O18*AS18*$AT$2/1000 -> 0 | AV18: =O18*AU18*$AV$2/1000 -> 0 | AX18: =O18*AW18*$AX$2/1000 -> 0 | AY18: =SUM(AS18+AU18+AW18) -> 0 | AZ18: =SUM(AT18,AV18,AX18) -> 0 | BA18: =SUM(AQ18+AY18) -> 0 | BB18: =SUM(AR18,AZ18) -> 0 | BC18: 구
A19: 13 | E19: L23S0T_EPN | F19: 793A | G19: 구 | H19: QD | I19: 4.19 | Q19: =SUM(AI19+BA19) -> 0 | R19: =SUM(AJ19+BB19) -> 0 | T19: =I19*S19*$T$2/1000 -> 0 | V19: =I19*U19*$V$2/1000 -> 0 | X19: =I19*W19*$X$2/1000 -> 0 | Y19: =SUM(S19+U19+W19) -> 0 | Z19: =SUM(T19,V19,X19) -> 0 | AB19: =K19*AA19*$AB$2/1000 -> 0 | AD19: =K19*AC19*$AD$2/1000 -> 0 | AF19: =K19*AE19*$AF$2/1000 -> 0 | AG19: =SUM(AA19+AC19+AE19) -> 0 | AH19: =SUM(AB19,AD19,AF19) -> 0 | AI19: =SUM(Y19+AG19) -> 0 | AJ19: =SUM(Z19,AH19) -> 0 | AL19: =M19*AK19*$AL$2/1000 -> 0 | AN19: =M19*AM19*$AN$2/1000 -> 0 | AP19: =M19*AO19*$AP$2/1000 -> 0 | AQ19: =SUM(AK19+AM19+AO19) -> 0 | AR19: =SUM(AL19,AN19,AP19) -> 0 | AT19: =O19*AS19*$AT$2/1000 -> 0 | AV19: =O19*AU19*$AV$2/1000 -> 0 | AX19: =O19*AW19*$AX$2/1000 -> 0 | AY19: =SUM(AS19+AU19+AW19) -> 0 | AZ19: =SUM(AT19,AV19,AX19) -> 0 | BA19: =SUM(AQ19+AY19) -> 0 | BB19: =SUM(AR19,AZ19) -> 0 | BC19: 구
A20: 14 | E20: L32E1P_KPN | F20: 869A | G20: 구 | H20: SY | I20: 8.64 | Q20: =SUM(AI20+BA20) -> 0 | R20: =SUM(AJ20+BB20) -> 0 | T20: =I20*S20*$T$2/1000 -> 0 | V20: =I20*U20*$V$2/1000 -> 0 | X20: =I20*W20*$X$2/1000 -> 0 | Y20: =SUM(S20+U20+W20) -> 0 | Z20: =SUM(T20,V20,X20) -> 0 | AB20: =K20*AA20*$AB$2/1000 -> 0 | AD20: =K20*AC20*$AD$2/1000 -> 0 | AF20: =K20*AE20*$AF$2/1000 -> 0 | AG20: =SUM(AA20+AC20+AE20) -> 0 | AH20: =SUM(AB20,AD20,AF20) -> 0 | AI20: =SUM(Y20+AG20) -> 0 | AJ20: =SUM(Z20,AH20) -> 0 | AL20: =M20*AK20*$AL$2/1000 -> 0 | AN20: =M20*AM20*$AN$2/1000 -> 0 | AP20: =M20*AO20*$AP$2/1000 -> 0 | AQ20: =SUM(AK20+AM20+AO20) -> 0 | AR20: =SUM(AL20,AN20,AP20) -> 0 | AT20: =O20*AS20*$AT$2/1000 -> 0 | AV20: =O20*AU20*$AV$2/1000 -> 0 | AX20: =O20*AW20*$AX$2/1000 -> 0 | AY20: =SUM(AS20+AU20+AW20) -> 0 | AZ20: =SUM(AT20,AV20,AX20) -> 0 | BA20: =SUM(AQ20+AY20) -> 0 | BB20: =SUM(AR20,AZ20) -> 0 | BC20: 구
A21: 15 | E21: L32E1P_KPN V | F21: 869B | G21: 구 | H21: SY | I21: 7.7 | Q21: =SUM(AI21+BA21) -> 0 | R21: =SUM(AJ21+BB21) -> 0 | T21: =I21*S21*$T$2/1000 -> 0 | V21: =I21*U21*$V$2/1000 -> 0 | X21: =I21*W21*$X$2/1000 -> 0 | Y21: =SUM(S21+U21+W21) -> 0 | Z21: =SUM(T21,V21,X21) -> 0 | AB21: =K21*AA21*$AB$2/1000 -> 0 | AD21: =K21*AC21*$AD$2/1000 -> 0 | AF21: =K21*AE21*$AF$2/1000 -> 0 | AG21: =SUM(AA21+AC21+AE21) -> 0 | AH21: =SUM(AB21,AD21,AF21) -> 0 | AI21: =SUM(Y21+AG21) -> 0 | AJ21: =SUM(Z21,AH21) -> 0 | AL21: =M21*AK21*$AL$2/1000 -> 0 | AN21: =M21*AM21*$AN$2/1000 -> 0 | AP21: =M21*AO21*$AP$2/1000 -> 0 | AQ21: =SUM(AK21+AM21+AO21) -> 0 | AR21: =SUM(AL21,AN21,AP21) -> 0 | AT21: =O21*AS21*$AT$2/1000 -> 0 | AV21: =O21*AU21*$AV$2/1000 -> 0 | AX21: =O21*AW21*$AX$2/1000 -> 0 | AY21: =SUM(AS21+AU21+AW21) -> 0 | AZ21: =SUM(AT21,AV21,AX21) -> 0 | BA21: =SUM(AQ21+AY21) -> 0 | BB21: =SUM(AR21,AZ21) -> 0 | BC21: 구
A22: 16 | E22: L32E1N_KPN | F22: 870A | G22: 구 | H22: SY | I22: 8.5 | Q22: =SUM(AI22+BA22) -> 0 | R22: =SUM(AJ22+BB22) -> 0 | T22: =I22*S22*$T$2/1000 -> 0 | V22: =I22*U22*$V$2/1000 -> 0 | X22: =I22*W22*$X$2/1000 -> 0 | Y22: =SUM(S22+U22+W22) -> 0 | Z22: =SUM(T22,V22,X22) -> 0 | AB22: =K22*AA22*$AB$2/1000 -> 0 | AD22: =K22*AC22*$AD$2/1000 -> 0 | AF22: =K22*AE22*$AF$2/1000 -> 0 | AG22: =SUM(AA22+AC22+AE22) -> 0 | AH22: =SUM(AB22,AD22,AF22) -> 0 | AI22: =SUM(Y22+AG22) -> 0 | AJ22: =SUM(Z22,AH22) -> 0 | AL22: =M22*AK22*$AL$2/1000 -> 0 | AN22: =M22*AM22*$AN$2/1000 -> 0 | AP22: =M22*AO22*$AP$2/1000 -> 0 | AQ22: =SUM(AK22+AM22+AO22) -> 0 | AR22: =SUM(AL22,AN22,AP22) -> 0 | AT22: =O22*AS22*$AT$2/1000 -> 0 | AV22: =O22*AU22*$AV$2/1000 -> 0 | AX22: =O22*AW22*$AX$2/1000 -> 0 | AY22: =SUM(AS22+AU22+AW22) -> 0 | AZ22: =SUM(AT22,AV22,AX22) -> 0 | BA22: =SUM(AQ22+AY22) -> 0 | BB22: =SUM(AR22,AZ22) -> 0 | BC22: 구
A23: 17 | E23: L32E1NR_KPN | F23: 870B | G23: 구 | H23: SY | I23: 7.79 | Q23: =SUM(AI23+BA23) -> 0 | R23: =SUM(AJ23+BB23) -> 0 | T23: =I23*S23*$T$2/1000 -> 0 | V23: =I23*U23*$V$2/1000 -> 0 | X23: =I23*W23*$X$2/1000 -> 0 | Y23: =SUM(S23+U23+W23) -> 0 | Z23: =SUM(T23,V23,X23) -> 0 | AB23: =K23*AA23*$AB$2/1000 -> 0 | AD23: =K23*AC23*$AD$2/1000 -> 0 | AF23: =K23*AE23*$AF$2/1000 -> 0 | AG23: =SUM(AA23+AC23+AE23) -> 0 | AH23: =SUM(AB23,AD23,AF23) -> 0 | AI23: =SUM(Y23+AG23) -> 0 | AJ23: =SUM(Z23,AH23) -> 0 | AL23: =M23*AK23*$AL$2/1000 -> 0 | AN23: =M23*AM23*$AN$2/1000 -> 0 | AP23: =M23*AO23*$AP$2/1000 -> 0 | AQ23: =SUM(AK23+AM23+AO23) -> 0 | AR23: =SUM(AL23,AN23,AP23) -> 0 | AT23: =O23*AS23*$AT$2/1000 -> 0 | AV23: =O23*AU23*$AV$2/1000 -> 0 | AX23: =O23*AW23*$AX$2/1000 -> 0 | AY23: =SUM(AS23+AU23+AW23) -> 0 | AZ23: =SUM(AT23,AV23,AX23) -> 0 | BA23: =SUM(AQ23+AY23) -> 0 | BB23: =SUM(AR23,AZ23) -> 0 | BC23: 구
A24: 18 | E24: 소 계 | Q24: =SUM(Q7:Q23) -> 7.838 | R24: =SUM(R7:R23) -> 83.366041 | S24: =SUM(S7:S23) -> 4.32 | T24: =SUM(T7:T23) -> 45.503559 | U24: =SUM(U7:U23) -> 1.8 | V24: =SUM(V7:V23) -> 19.023002 | W24: =SUM(W7:W23) -> 1.718 | X24: =SUM(X7:X23) -> 18.839479 | ... BB24: =SUM(BB7:BB23) -> 0 | BC24: X
A25: 19 | D25: LFD | E25: F24AF_FPN | F25: 861A | G25: 구 | H25: QD | I25: 10.2 | Q25: =SUM(AI25+BA25) -> 0 | R25: =SUM(AJ25+BB25) -> 0 | T25: =I25*S25*$T$2/1000 -> 0 | V25: =I25*U25*$V$2/1000 -> 0 | X25: =I25*W25*$X$2/1000 -> 0 | Y25: =SUM(S25+U25+W25) -> 0 | Z25: =SUM(T25+V25+X25) -> 0 | AB25: =K25*AA25*$AB$2/1000 -> 0 | AD25: =K25*AC25*$AD$2/1000 -> 0 | AF25: =K25*AE25*$AF$2/1000 -> 0 | AG25: =SUM(AA25+AC25+AE25) -> 0 | AH25: =SUM(AB25+AD25+AF25) -> 0 | AI25: =SUM(Y25+AG25) -> 0 | AJ25: =SUM(Z25,AH25) -> 0 | AL25: =M25*AK25*$AL$2/1000 -> 0 | AN25: =M25*AM25*$AN$2/1000 -> 0 | AP25: =M25*AO25*$AP$2/1000 -> 0 | AQ25: =SUM(AK25+AM25+AO25) -> 0 | AR25: =SUM(AL25+AN25+AP25) -> 0 | AT25: =O25*AS25*$AT$2/1000 -> 0 | AV25: =O25*AU25*$AV$2/1000 -> 0 | AX25: =O25*AW25*$AX$2/1000 -> 0 | AY25: =SUM(AS25+AU25+AW25) -> 0 | AZ25: =SUM(AT25+AV25+AX25) -> 0 | BA25: =SUM(AQ25+AY25) -> 0 | BB25: =SUM(AR25,AZ25) -> 0 | BC25: 구
A26: 20 | E26: F32E6_CPN | F26: 1256A | G26: 구 | H26: SY | I26: 11.73 | K26: 11.72 | Q26: =SUM(AI26+BA26) -> 36.036 | R26: =SUM(AJ26+BB26) -> 618.64568 | S26: 10.332 | T26: =I26*S26*$T$2/1000 -> 174.96224 | U26: 11.664 | V26: =I26*U26*$V$2/1000 -> 196.78089 | W26: 12.096 | X26: =I26*W26*$X$2/1000 -> 213.16539 | Y26: =SUM(S26+U26+W26) -> 34.092 | Z26: =SUM(T26+V26+X26) -> 584.90852 | AA26: 1.944 | AB26: =K26*AA26*$AB$2/1000 -> 33.737162 | AD26: =K26*AC26*$AD$2/1000 -> 0 | AF26: =K26*AE26*$AF$2/1000 -> 0 | AG26: =SUM(AA26+AC26+AE26) -> 1.944 | AH26: =SUM(AB26+AD26+AF26) -> 33.737162 | AI26: =SUM(Y26+AG26) -> 36.036 | AJ26: =SUM(Z26,AH26) -> 618.64568 | AL26: =M26*AK26*$AL$2/1000 -> 0 | AN26: =M26*AM26*$AN$2/1000 -> 0 | AP26: =M26*AO26*$AP$2/1000 -> 0 | AQ26: =SUM(AK26+AM26+AO26) -> 0 | AR26: =SUM(AL26+AN26+AP26) -> 0 | AT26: =O26*AS26*$AT$2/1000 -> 0 | AV26: =O26*AU26*$AV$2/1000 -> 0 | AX26: =O26*AW26*$AX$2/1000 -> 0 | AY26: =SUM(AS26+AU26+AW26) -> 0 | AZ26: =SUM(AT26+AV26+AX26) -> 0 | BA26: =SUM(AQ26+AY26) -> 0 | BB26: =SUM(AR26,AZ26) -> 0 | BC26: 구
A27: 21 | E27: F32E1P_RPN | F27: 882B | G27: 구 | H27: SY | I27: 9.51 | K27: 9.51 | Q27: =SUM(AI27+BA27) -> 1.358 | R27: =SUM(AJ27+BB27) -> 18.995875 | S27: 0.378 | T27: =I27*S27*$T$2/1000 -> 5.1896041 | U27: 0.109 | V27: =I27*U27*$V$2/1000 -> 1.4908859 | W27: 0.243 | X27: =I27*W27*$X$2/1000 -> 3.4718719 | Y27: =SUM(S27+U27+W27) -> 0.73 | Z27: =SUM(T27+V27+X27) -> 10.152362 | AA27: 0.628 | AB27: =K27*AA27*$AB$2/1000 -> 8.8435133 | AD27: =K27*AC27*$AD$2/1000 -> 0 | AF27: =K27*AE27*$AF$2/1000 -> 0 | AG27: =SUM(AA27+AC27+AE27) -> 0.628 | AH27: =SUM(AB27+AD27+AF27) -> 8.8435133 | AI27: =SUM(Y27+AG27) -> 1.358 | AJ27: =SUM(Z27,AH27) -> 18.995875 | AL27: =M27*AK27*$AL$2/1000 -> 0 | AN27: =M27*AM27*$AN$2/1000 -> 0 | AP27: =M27*AO27*$AP$2/1000 -> 0 | AQ27: =SUM(AK27+AM27+AO27) -> 0 | AR27: =SUM(AL27+AN27+AP27) -> 0 | AT27: =O27*AS27*$AT$2/1000 -> 0 | AV27: =O27*AU27*$AV$2/1000 -> 0 | AX27: =O27*AW27*$AX$2/1000 -> 0 | AY27: =SUM(AS27+AU27+AW27) -> 0 | AZ27: =SUM(AT27+AV27+AX27) -> 0 | BA27: =SUM(AQ27+AY27) -> 0 | BB27: =SUM(AR27,AZ27) -> 0 | BC27: 구
A28: 22 | E28: 소 계 | Q28: =SUM(Q25:Q27) -> 37.394 | R28: =SUM(R25:R27) -> 637.64156 | S28: =SUM(S25:S27) -> 10.71 | T28: =SUM(T25:T27) -> 180.15184 | U28: =SUM(U25:U27) -> 11.773 | V28: =SUM(V25:V27) -> 198.27178 | W28: =SUM(W25:W27) -> 12.339 | X28: =SUM(X25:X27) -> 216.63726 | ... BB28: =SUM(BB25:BB27) -> 0 | BC28: X
A29: 23 | C29: 제품계 | Q29: =+Q24+Q28 -> 45.232 | R29: =+R24+R28 -> 721.0076 | S29: =+S24+S28 -> 15.03 | T29: =+T24+T28 -> 225.6554 | U29: =+U24+U28 -> 13.573 | V29: =+V24+V28 -> 217.29478 | W29: =+W24+W28 -> 14.057 | X29: =+X24+X28 -> 235.47674 | ... BB29: =+BB24+BB28 -> 0 | BC29: X
A30: 24 | C30: SMPS | D30: TV | E30: P32SF_FPN | F30: 844A | G30: 구 | H30: QD | I30: 5.6 | Q30: =SUM(AI30+BA30) -> 0 | R30: =SUM(AJ30+BB30) -> 0 | T30: =I30*S30*$T$2/1000 -> 0 | V30: =I30*U30*$V$2/1000 -> 0 | X30: =I30*W30*$X$2/1000 -> 0 | Y30: =SUM(S30+U30+W30) -> 0 | Z30: =SUM(T30+V30+X30) -> 0 | AB30: =K30*AA30*$AB$2/1000 -> 0 | AD30: =K30*AC30*$AD$2/1000 -> 0 | AF30: =K30*AE30*$AF$2/1000 -> 0 | AG30: =SUM(AA30+AC30+AE30) -> 0 | AH30: =SUM(AB30+AD30+AF30) -> 0 | AI30: =SUM(Y30+AG30) -> 0 | AJ30: =SUM(Z30,AH30) -> 0 | AL30: =M30*AK30*$AL$2/1000 -> 0 | AN30: =M30*AM30*$AN$2/1000 -> 0 | AP30: =M30*AO30*$AP$2/1000 -> 0 | AQ30: =SUM(AK30+AM30+AO30) -> 0 | AR30: =SUM(AL30+AN30+AP30) -> 0 | AT30: =O30*AS30*$AT$2/1000 -> 0 | AV30: =O30*AU30*$AV$2/1000 -> 0 | AX30: =O30*AW30*$AX$2/1000 -> 0 | AY30: =SUM(AS30+AU30+AW30) -> 0 | AZ30: =SUM(AT30+AV30+AX30) -> 0 | BA30: =SUM(AQ30+AY30) -> 0 | BB30: =SUM(AR30,AZ30) -> 0 | BC30: 구
A31: 25 | E31: P32SFN_FPN | F31: 844B | G31: 구 | H31: QD | I31: 7.03 | Q31: =SUM(AI31+BA31) -> 0 | R31: =SUM(AJ31+BB31) -> 0 | T31: =I31*S31*$T$2/1000 -> 0 | V31: =I31*U31*$V$2/1000 -> 0 | X31: =I31*W31*$X$2/1000 -> 0 | Y31: =SUM(S31+U31+W31) -> 0 | Z31: =SUM(T31+V31+X31) -> 0 | AB31: =K31*AA31*$AB$2/1000 -> 0 | AD31: =K31*AC31*$AD$2/1000 -> 0 | AF31: =K31*AE31*$AF$2/1000 -> 0 | AG31: =SUM(AA31+AC31+AE31) -> 0 | AH31: =SUM(AB31+AD31+AF31) -> 0 | AI31: =SUM(Y31+AG31) -> 0 | AJ31: =SUM(Z31,AH31) -> 0 | AL31: =M31*AK31*$AL$2/1000 -> 0 | AN31: =M31*AM31*$AN$2/1000 -> 0 | AP31: =M31*AO31*$AP$2/1000 -> 0 | AQ31: =SUM(AK31+AM31+AO31) -> 0 | AR31: =SUM(AL31+AN31+AP31) -> 0 | AT31: =O31*AS31*$AT$2/1000 -> 0 | AV31: =O31*AU31*$AV$2/1000 -> 0 | AX31: =O31*AW31*$AX$2/1000 -> 0 | AY31: =SUM(AS31+AU31+AW31) -> 0 | AZ31: =SUM(AT31+AV31+AX31) -> 0 | BA31: =SUM(AQ31+AY31) -> 0 | BB31: =SUM(AR31,AZ31) -> 0 | BC31: 구
A32: 26 | E32: P32MF_KPN | F32: 844C | G32: 구 | H32: QD | I32: 6.45 | Q32: =SUM(AI32+BA32) -> 0 | R32: =SUM(AJ32+BB32) -> 0 | T32: =I32*S32*$T$2/1000 -> 0 | V32: =I32*U32*$V$2/1000 -> 0 | X32: =I32*W32*$X$2/1000 -> 0 | Y32: =SUM(S32+U32+W32) -> 0 | Z32: =SUM(T32+V32+X32) -> 0 | AB32: =K32*AA32*$AB$2/1000 -> 0 | AD32: =K32*AC32*$AD$2/1000 -> 0 | AF32: =K32*AE32*$AF$2/1000 -> 0 | AG32: =SUM(AA32+AC32+AE32) -> 0 | AH32: =SUM(AB32+AD32+AF32) -> 0 | AI32: =SUM(Y32+AG32) -> 0 | AJ32: =SUM(Z32,AH32) -> 0 | AL32: =M32*AK32*$AL$2/1000 -> 0 | AN32: =M32*AM32*$AN$2/1000 -> 0 | AP32: =M32*AO32*$AP$2/1000 -> 0 | AQ32: =SUM(AK32+AM32+AO32) -> 0 | AR32: =SUM(AL32+AN32+AP32) -> 0 | AT32: =O32*AS32*$AT$2/1000 -> 0 | AV32: =O32*AU32*$AV$2/1000 -> 0 | AX32: =O32*AW32*$AX$2/1000 -> 0 | AY32: =SUM(AS32+AU32+AW32) -> 0 | AZ32: =SUM(AT32+AV32+AX32) -> 0 | BA32: =SUM(AQ32+AY32) -> 0 | BB32: =SUM(AR32,AZ32) -> 0 | BC32: 구
A33: 27 | E33: P32SF_MPN | F33: 844D | G33: 구 | H33: QD | I33: 5.5 | Q33: =SUM(AI33+BA33) -> 0 | R33: =SUM(AJ33+BB33) -> 0 | T33: =I33*S33*$T$2/1000 -> 0 | V33: =I33*U33*$V$2/1000 -> 0 | X33: =I33*W33*$X$2/1000 -> 0 | Y33: =SUM(S33+U33+W33) -> 0 | Z33: =SUM(T33+V33+X33) -> 0 | AB33: =K33*AA33*$AB$2/1000 -> 0 | AD33: =K33*AC33*$AD$2/1000 -> 0 | AF33: =K33*AE33*$AF$2/1000 -> 0 | AG33: =SUM(AA33+AC33+AE33) -> 0 | AH33: =SUM(AB33+AD33+AF33) -> 0 | AI33: =SUM(Y33+AG33) -> 0 | AJ33: =SUM(Z33,AH33) -> 0 | AL33: =M33*AK33*$AL$2/1000 -> 0 | AN33: =M33*AM33*$AN$2/1000 -> 0 | AP33: =M33*AO33*$AP$2/1000 -> 0 | AQ33: =SUM(AK33+AM33+AO33) -> 0 | AR33: =SUM(AL33+AN33+AP33) -> 0 | AT33: =O33*AS33*$AT$2/1000 -> 0 | AV33: =O33*AU33*$AV$2/1000 -> 0 | AX33: =O33*AW33*$AX$2/1000 -> 0 | AY33: =SUM(AS33+AU33+AW33) -> 0 | AZ33: =SUM(AT33+AV33+AX33) -> 0 | BA33: =SUM(AQ33+AY33) -> 0 | BB33: =SUM(AR33,AZ33) -> 0 | BC33: 구
A34: 28 | E34: P32SFN_MPN | F34: 844E | G34: 구 | H34: QD | I34: 5.95 | Q34: =SUM(AI34+BA34) -> 0 | R34: =SUM(AJ34+BB34) -> 0 | T34: =I34*S34*$T$2/1000 -> 0 | V34: =I34*U34*$V$2/1000 -> 0 | X34: =I34*W34*$X$2/1000 -> 0 | Y34: =SUM(S34+U34+W34) -> 0 | Z34: =SUM(T34+V34+X34) -> 0 | AB34: =K34*AA34*$AB$2/1000 -> 0 | AD34: =K34*AC34*$AD$2/1000 -> 0 | AF34: =K34*AE34*$AF$2/1000 -> 0 | AG34: =SUM(AA34+AC34+AE34) -> 0 | AH34: =SUM(AB34+AD34+AF34) -> 0 | AI34: =SUM(Y34+AG34) -> 0 | AJ34: =SUM(Z34,AH34) -> 0 | AL34: =M34*AK34*$AL$2/1000 -> 0 | AN34: =M34*AM34*$AN$2/1000 -> 0 | AP34: =M34*AO34*$AP$2/1000 -> 0 | AQ34: =SUM(AK34+AM34+AO34) -> 0 | AR34: =SUM(AL34+AN34+AP34) -> 0 | AT34: =O34*AS34*$AT$2/1000 -> 0 | AV34: =O34*AU34*$AV$2/1000 -> 0 | AX34: =O34*AW34*$AX$2/1000 -> 0 | AY34: =SUM(AS34+AU34+AW34) -> 0 | AZ34: =SUM(AT34+AV34+AX34) -> 0 | BA34: =SUM(AQ34+AY34) -> 0 | BB34: =SUM(AR34,AZ34) -> 0 | BC34: 구
A35: 29 | C35: SMPS | D35: TV | E35: P230NQ_NPN | F35: 933A | G35: 구 | H35: SY | I35: 18.7 | K35: 18.7 | Q35: =SUM(AI35+BA35) -> 0 | R35: =SUM(AJ35+BB35) -> 0 | T35: =I35*S35*$T$2/1000 -> 0 | V35: =I35*U35*$V$2/1000 -> 0 | X35: =I35*W35*$X$2/1000 -> 0 | Y35: =SUM(S35+U35+W35) -> 0 | Z35: =SUM(T35,V35,X35) -> 0 | AB35: =K35*AA35*$AB$2/1000 -> 0 | AD35: =K35*AC35*$AD$2/1000 -> 0 | AF35: =K35*AE35*$AF$2/1000 -> 0 | AG35: =SUM(AA35+AC35+AE35) -> 0 | AH35: =SUM(AB35,AD35,AF35) -> 0 | AI35: =SUM(Y35+AG35) -> 0 | AJ35: =SUM(Z35,AH35) -> 0 | AL35: =M35*AK35*$AL$2/1000 -> 0 | AN35: =M35*AM35*$AN$2/1000 -> 0 | AP35: =M35*AO35*$AP$2/1000 -> 0 | AQ35: =SUM(AK35+AM35+AO35) -> 0 | AR35: =SUM(AL35,AN35,AP35) -> 0 | AT35: =O35*AS35*$AT$2/1000 -> 0 | AV35: =O35*AU35*$AV$2/1000 -> 0 | AX35: =O35*AW35*$AX$2/1000 -> 0 | AY35: =SUM(AS35+AU35+AW35) -> 0 | AZ35: =SUM(AT35,AV35,AX35) -> 0 | BA35: =SUM(AQ35+AY35) -> 0 | BB35: =SUM(AR35,AZ35) -> 0 | BC35: 구
A36: 32 | E36: P230NQ_TPN | F36: 1066B | G36: 구 | H36: SY | I36: 19.29 | K36: 19.28 | Q36: =SUM(AI36+BA36) -> 64.092 | R36: =SUM(AJ36+BB36) -> 1780.4099 | S36: 17.064 | T36: =I36*S36*$T$2/1000 -> 475.19842 | U36: 46.608 | V36: =I36*U36*$V$2/1000 -> 1293.094 | W36: 0.294 | X36: =I36*W36*$X$2/1000 -> 8.5203309 | Y36: =SUM(S36+U36+W36) -> 63.966 | Z36: =SUM(T36,V36,X36) -> 1776.8127 | AA36: 0.126 | AB36: =K36*AA36*$AB$2/1000 -> 3.5971807 | AD36: =K36*AC36*$AD$2/1000 -> 0 | AF36: =K36*AE36*$AF$2/1000 -> 0 | AG36: =SUM(AA36+AC36+AE36) -> 0.126 | AH36: =SUM(AB36,AD36,AF36) -> 3.5971807 | AI36: =SUM(Y36+AG36) -> 64.092 | AJ36: =SUM(Z36,AH36) -> 1780.4099 | AL36: =M36*AK36*$AL$2/1000 -> 0 | AN36: =M36*AM36*$AN$2/1000 -> 0 | AP36: =M36*AO36*$AP$2/1000 -> 0 | AQ36: =SUM(AK36+AM36+AO36) -> 0 | AR36: =SUM(AL36,AN36,AP36) -> 0 | AT36: =O36*AS36*$AT$2/1000 -> 0 | AV36: =O36*AU36*$AV$2/1000 -> 0 | AX36: =O36*AW36*$AX$2/1000 -> 0 | AY36: =SUM(AS36+AU36+AW36) -> 0 | AZ36: =SUM(AT36,AV36,AX36) -> 0 | BA36: =SUM(AQ36+AY36) -> 0 | BB36: =SUM(AR36,AZ36) -> 0 | BC36: 구
A37: 32 | E37: P270NQ_NPN | F37: 934A | G37: 구 | H37: SY | I37: 21.1 | K37: 21.1 | Q37: =SUM(AI37+BA37) -> 0 | R37: =SUM(AJ37+BB37) -> 0 | T37: =I37*S37*$T$2/1000 -> 0 | V37: =I37*U37*$V$2/1000 -> 0 | X37: =I37*W37*$X$2/1000 -> 0 | Y37: =SUM(S37+U37+W37) -> 0 | Z37: =SUM(T37,V37,X37) -> 0 | AB37: =K37*AA37*$AB$2/1000 -> 0 | AD37: =K37*AC37*$AD$2/1000 -> 0 | AF37: =K37*AE37*$AF$2/1000 -> 0 | AG37: =SUM(AA37+AC37+AE37) -> 0 | AH37: =SUM(AB37,AD37,AF37) -> 0 | AI37: =SUM(Y37+AG37) -> 0 | AJ37: =SUM(Z37,AH37) -> 0 | AL37: =M37*AK37*$AL$2/1000 -> 0 | AN37: =M37*AM37*$AN$2/1000 -> 0 | AP37: =M37*AO37*$AP$2/1000 -> 0 | AQ37: =SUM(AK37+AM37+AO37) -> 0 | AR37: =SUM(AL37,AN37,AP37) -> 0 | AT37: =O37*AS37*$AT$2/1000 -> 0 | AV37: =O37*AU37*$AV$2/1000 -> 0 | AX37: =O37*AW37*$AX$2/1000 -> 0 | AY37: =SUM(AS37+AU37+AW37) -> 0 | AZ37: =SUM(AT37,AV37,AX37) -> 0 | BA37: =SUM(AQ37+AY37) -> 0 | BB37: =SUM(AR37,AZ37) -> 0 | BC37: 구
A38: 33 | E38: P270NQB_NPN | F38: 934B | G38: 구 | H38: SY | I38: 20.89 | K38: 20.89 | Q38: =SUM(AI38+BA38) -> 0 | R38: =SUM(AJ38+BB38) -> 0 | T38: =I38*S38*$T$2/1000 -> 0 | V38: =I38*U38*$V$2/1000 -> 0 | X38: =I38*W38*$X$2/1000 -> 0 | Y38: =SUM(S38+U38+W38) -> 0 | Z38: =SUM(T38,V38,X38) -> 0 | AB38: =K38*AA38*$AB$2/1000 -> 0 | AD38: =K38*AC38*$AD$2/1000 -> 0 | AF38: =K38*AE38*$AF$2/1000 -> 0 | AG38: =SUM(AA38+AC38+AE38) -> 0 | AH38: =SUM(AB38,AD38,AF38) -> 0 | AI38: =SUM(Y38+AG38) -> 0 | AJ38: =SUM(Z38,AH38) -> 0 | AL38: =M38*AK38*$AL$2/1000 -> 0 | AN38: =M38*AM38*$AN$2/1000 -> 0 | AP38: =M38*AO38*$AP$2/1000 -> 0 | AQ38: =SUM(AK38+AM38+AO38) -> 0 | AR38: =SUM(AL38,AN38,AP38) -> 0 | AT38: =O38*AS38*$AT$2/1000 -> 0 | AV38: =O38*AU38*$AV$2/1000 -> 0 | AX38: =O38*AW38*$AX$2/1000 -> 0 | AY38: =SUM(AS38+AU38+AW38) -> 0 | AZ38: =SUM(AT38,AV38,AX38) -> 0 | BA38: =SUM(AQ38+AY38) -> 0 | BB38: =SUM(AR38,AZ38) -> 0 | BC38: 구
A39: 35 | E39: P270NQ_TPN | F39: 1066A | G39: 구 | H39: SY | I39: 21.67 | K39: 21.66 | Q39: =SUM(AI39+BA39) -> 27.738 | R39: =SUM(AJ39+BB39) -> 865.75284 | S39: 3.606 | T39: =I39*S39*$T$2/1000 -> 112.80973 | U39: 23.286 | V39: =I39*U39*$V$2/1000 -> 725.75696 | W39: 0.108 | X39: =I39*W39*$X$2/1000 -> 3.5160867 | Y39: =SUM(S39+U39+W39) -> 27 | Z39: =SUM(T39,V39,X39) -> 842.08277 | AA39: 0.738 | AB39: =K39*AA39*$AB$2/1000 -> 23.670067 | AD39: =K39*AC39*$AD$2/1000 -> 0 | AF39: =K39*AE39*$AF$2/1000 -> 0 | AG39: =SUM(AA39+AC39+AE39) -> 0.738 | AH39: =SUM(AB39,AD39,AF39) -> 23.670067 | AI39: =SUM(Y39+AG39) -> 27.738 | AJ39: =SUM(Z39,AH39) -> 865.75284 | AL39: =M39*AK39*$AL$2/1000 -> 0 | AN39: =M39*AM39*$AN$2/1000 -> 0 | AP39: =M39*AO39*$AP$2/1000 -> 0 | AQ39: =SUM(AK39+AM39+AO39) -> 0 | AR39: =SUM(AL39,AN39,AP39) -> 0 | AT39: =O39*AS39*$AT$2/1000 -> 0 | AV39: =O39*AU39*$AV$2/1000 -> 0 | AX39: =O39*AW39*$AX$2/1000 -> 0 | AY39: =SUM(AS39+AU39+AW39) -> 0 | AZ39: =SUM(AT39,AV39,AX39) -> 0 | BA39: =SUM(AQ39+AY39) -> 0 | BB39: =SUM(AR39,AZ39) -> 0 | BC39: 구
E40: P230NQ_TPN (CKD) | F40: 1066B | G40: 신 | H40: SY | I40: 18.75 | K40: 18.75 | Q40: =SUM(AI40+BA40) -> 0 | R40: =SUM(AJ40+BB40) -> 0 | T40: =I40*S40*$T$2/1000 -> 0 | V40: =I40*U40*$V$2/1000 -> 0 | X40: =I40*W40*$X$2/1000 -> 0 | Y40: =SUM(S40+U40+W40) -> 0 | Z40: =SUM(T40+V40+X40) -> 0 | AB40: =K40*AA40*$AB$2/1000 -> 0 | AD40: =K40*AC40*$AD$2/1000 -> 0 | AF40: =K40*AE40*$AF$2/1000 -> 0 | AG40: =SUM(AA40+AC40+AE40) -> 0 | AH40: =SUM(AB40+AD40+AF40) -> 0 | AI40: =SUM(Y40+AG40) -> 0 | AJ40: =SUM(Z40,AH40) -> 0 | AL40: =M40*AK40*$AL$2/1000 -> 0 | AN40: =M40*AM40*$AN$2/1000 -> 0 | AP40: =M40*AO40*$AP$2/1000 -> 0 | AQ40: =SUM(AK40+AM40+AO40) -> 0 | AR40: =SUM(AL40+AN40+AP40) -> 0 | AT40: =O40*AS40*$AT$2/1000 -> 0 | AV40: =O40*AU40*$AV$2/1000 -> 0 | AX40: =O40*AW40*$AX$2/1000 -> 0 | AY40: =SUM(AS40+AU40+AW40) -> 0 | AZ40: =SUM(AT40+AV40+AX40) -> 0 | BA40: =SUM(AQ40+AY40) -> 0 | BB40: =SUM(AR40,AZ40) -> 0 | BC40: 구
...

Sheet 매출내역
H1: =SUBTOTAL(9,H3:H10000) -> 8887247 | I1: =SUBTOTAL(9,I3:I10000) -> 87034.486
B2: 월 | C2: 대분류 | D2: 업 체 | E2: CODE | F2: 모델명 | G2: 제품 | H2: 합계 : 수량 | I2: 합계 : 금액 | J2: 신규
B3: 1 | C3: =VLOOKUP(D3,기본!$B$3:$C$90,2,0) -> AV JDM | D3: EASTECH | E3: 16912A | F3: V200SR_CPN | G3: =VLOOKUP(E3,기본!$F$3:$G$320,2,0) -> #N/A | H3: 12880 | I3: 122.52383
B4: 1 | C4: =VLOOKUP(D4,기본!$B$3:$C$90,2,0) -> AV JDM | D4: EASTECH | E4: 16913A | F4: V200SRN_CPN | G4: =VLOOKUP(E4,기본!$F$3:$G$320,2,0) -> #N/A | H4: 404 | I4: 4.1331217
B5: 1 | C5: =VLOOKUP(D5,기본!$B$3:$C$90,2,0) -> AV JDM | D5: EASTECH | E5: A5919_DPN V | F5: A5919_DPN V | G5: =VLOOKUP(E5,기본!$F$3:$G$320,2,0) -> MNT | H5: 12376 | I5: 104.60749
B6: 1 | C6: =VLOOKUP(D6,기본!$B$3:$C$90,2,0) -> AV JDM | D6: EASTECH | E6: A5919_DPNS V | F6: A5919_DPNS V | G6: =VLOOKUP(E6,기본!$F$3:$G$320,2,0) -> MNT | H6: 7056 | I6: 64.36017
B7: 1 | C7: =VLOOKUP(D7,기본!$B$3:$C$90,2,0) -> AV JDM | D7: EASTECH | E7: A5919_DPNSW V | F7: A5919_DPNSW V | G7: =VLOOKUP(E7,기본!$F$3:$G$320,2,0) -> #N/A | H7: 1848 | I7: 17.666592
B8: 1 | C8: =VLOOKUP(D8,기본!$B$3:$C$90,2,0) -> AV JDM | D8: EASTECH | E8: A5919_DPNT V | F8: A5919_DPNT V | G8: =VLOOKUP(E8,기본!$F$3:$G$320,2,0) -> MNT | H8: 2268 | I8: 22.218342
B9: 1 | C9: =VLOOKUP(D9,기본!$B$3:$C$90,2,0) -> AV JDM | D9: EASTECH | E9: A5919_DPNW V | F9: A5919_DPNW V | G9: =VLOOKUP(E9,기본!$F$3:$G$320,2,0) -> #N/A | H9: 1008 | I9: 9.0328946
B10: 1 | C10: =VLOOKUP(D10,기본!$B$3:$C$90,2,0) -> AV JDM | D10: EASTECH | E10: A5919N_DPNS V | F10: A5919N_DPNS V | G10: =VLOOKUP(E10,기본!$F$3:$G$320,2,0) -> #N/A | H10: 224 | I10: 2.2037747
B11: 1 | C11: =VLOOKUP(D11,기본!$B$3:$C$90,2,0) -> AV JDM | D11: EASTECH | E11: A5919N_DPNT V | F11: A5919N_DPNT V | G11: =VLOOKUP(E11,기본!$F$3:$G$320,2,0) -> #N/A | H11: 703 | I11: 7.2816708
B12: 1 | C12: =VLOOKUP(D12,기본!$B$3:$C$90,2,0) -> AV JDM | D12: EASTECH | E12: AH81-09783A | F12: A4024_FPN_C(DA) | G12: =VLOOKUP(E12,기본!$F$3:$G$320,2,0) -> #N/A | H12: 4242 | I12: 37.091369
B13: 1 | C13: =VLOOKUP(D13,기본!$B$3:$C$90,2,0) -> AV JDM | D13: EASTECH | E13: AH81-15048C | F13: V220S_BPNA | G13: =VLOOKUP(E13,기본!$F$3:$G$320,2,0) -> #N/A | H13: 6888 | I13: 75.262342
B14: 1 | C14: =VLOOKUP(D14,기본!$B$3:$C$90,2,0) -> AV JDM | D14: EASTECH | E14: AH81-15505A | F14: V220S_MPNA | G14: =VLOOKUP(E14,기본!$F$3:$G$320,2,0) -> #N/A | H14: 7000 | I14: 68.695663
... B1891: 5 | C1891: =VLOOKUP(D1891,기본!$B$3:$C$90,2,0) -> 한화비전 | D1891: 한화비전 | E1891: EP06-001005 | F1891: PN020STCA-NWF(A) | G1891: =VLOOKUP(E1891,기본!$F$3:$G$320,2,0) -> #N/A | H1891: 756 | I1891: 19.188437
C1892: =VLOOKUP(D1892,기본!$B$3:$C$90,2,0) -> #N/A | G1892: =VLOOKUP(E1892,기본!$F$3:$G$320,2,0) -> #N/A
C1893: =VLOOKUP(D1893,기본!$B$3:$C$90,2,0) -> #N/A | G1893: =VLOOKUP(E1893,기본!$F$3:$G$320,2,0) -> #N/A
C1894: =VLOOKUP(D1894,기본!$B$3:$C$90,2,0) -> #N/A | G1894: =VLOOKUP(E1894,기본!$F$3:$G$320,2,0) -> #N/A
C1895: =VLOOKUP(D1895,기본!$B$3:$C$90,2,0) -> #N/A | G1895: =VLOOKUP(E1895,기본!$F$3:$G$320,2,0) -> #N/A
C1896: =VLOOKUP(D1896,기본!$B$3:$C$90,2,0) -> #N/A | G1896: =VLOOKUP(E1896,기본!$F$3:$G$320,2,0) -> #N/A
C1897: =VLOOKUP(D1897,기본!$B$3:$C$90,2,0) -> #N/A | G1897: =VLOOKUP(E1897,기본!$F$3:$G$320,2,0) -> #N/A
C1898: =VLOOKUP(D1898,기본!$B$3:$C$90,2,0) -> #N/A | G1898: =VLOOKUP(E1898,기본!$F$3:$G$320,2,0) -> #N/A
C1899: =VLOOKUP(D1899,기본!$B$3:$C$90,2,0) -> #N/A | G1899: =VLOOKUP(E1899,기본!$F$3:$G$320,2,0) -> #N/A
C1900: =VLOOKUP(D1900,기본!$B$3:$C$90,2,0) -> #N/A | G1900: =VLOOKUP(E1900,기본!$F$3:$G$320,2,0) -> #N/A
C1901: =VLOOKUP(D1901,기본!$B$3:$C$90,2,0) -> #N/A | G1901: =VLOOKUP(E1901,기본!$F$3:$G$320,2,0) -> #N/A
C1902: =VLOOKUP(D1902,기본!$B$3:$C$90,2,0) -> #N/A | G1902: =VLOOKUP(E1902,기본!$F$3:$G$320,2,0) -> #N/A
C1903: =VLOOKUP(D1903,기본!$B$3:$C$90,2,0) -> #N/A | G1903: =VLOOKUP(E1903,기본!$F$3:$G$320,2,0) -> #N/A
... C4579: =VLOOKUP(D4579,기본!$B$3:$C$90,2,0) -> #N/A | G4579: =VLOOKUP(E4579,기본!$F$3:$G$320,2,0) -> #N/A

Sheet 기본
B2: 업체 | C2: 구분 | F2: 제품 | G2: 구분
B3: EASTECH(동아) (혜주) | C3: AV JDM | F3: 1024A | G3: MNT
B4: SAMEX (멕시코) | C4: 삼성 VD | F4: 1024B | G4: MNT
B5: SEH (헝가리) | C5: 삼성 VD | F5: 1066A | G5: TV
B6: SESK (슬로바키아) | C6: 삼성 VD | F6: 1066B | G6: TV
B7: SIEL C (인도) | C7: 삼성 VD | F7: 1098A | G7: MNT
B8: 기타 | C8: 기타 | F8: 1098B | G8: MNT
B9: AUO | C9: MNT JDM | F9: 1117C | G9: TV
B10: BOE | C10: MNT JDM | F10: 1118C | G10: TV
B11: Lite-on | C11: 삼성 VD | F11: 1119C | G11: TV
B12: BUMJIN (혜주) | C12: AV JDM | F12: 1122A | G12: MNT
B13: CORETRONICS | C13: JDM | F13: 1122B | G13: MNT
... B83: Wise | C83: 상품A | F83: BP81-00715A | G83: 기타
F84: BP81-00715D | G84: 기타
F85: BP81-00715E | G85: 기타
F86: BP81-00715F | G86: 기타
F87: BP81-00715D | G87: 기타
F88: BP81-00715E | G88: 기타
F89: BP81-00715G | G89: 기타
F90: BP81-00715H | G90: 기타
F91: BP81-00715J | G91: 기타
F92: V220SB_FPN | G92: AV
F93: V380SW_FPN | G93: AV
F94: 기타 | G94: 기타
F95: BP81-00715K | G95: 기타
... F140: V220S_MPN HF | G140: AV
