Workbook

Sheet 0624
A1: 품번 | B1: 품명 | C1: 06/24(화) | D1: 06/25(수) | E1: 06/26(목) | F1: 06/27(금) | G1: 06/28(토) | H1: 06/29(일) | I1: 06/30(월) | J1: 07/01(화) | K1: 07/02(수) | L1: 07/03(목) | M1: 07/04(금) | N1: 07/05(토) | O1: 07/06(일) | P1: 07/07(월) | Q1: 07/08(화) | R1: 07/09(수) | S1: 07/10(목) | T1: 07/11(금) | U1: 07/12(토) | V1: 07/13(일)
A2: 1229673 | B2: PBA-TOTAL- 아세이(BA20-D) | C2: 0 | D2: 0 | E2: 0 | F2: 0 | G2: 0 | H2: 0 | I2: 0 | J2: 0 | K2: 0 | L2: 0 | M2: 0 | N2: 0 | O2: 0 | P2: 0 | Q2: 200 | R2: 228 | S2: 0 | T2: 172 | U2: 0 | V2: 0
A3: 1230854 | B3: PBA-토탈- 아세이(BA34-A) | C3: 0 | D3: 0 | E3: 0 | F3: 0 | G3: 0 | H3: 0 | I3: 0 | J3: 0 | K3: 0 | L3: 0 | M3: 0 | N3: 0 | O3: 0 | P3: 150 | Q3: 0 | R3: 0 | S3: 0 | T3: 0 | U3: 0 | V3: 0
A4: 1231202 | B4: PBA-파워- 아세이(AP-1019D) | C4: 0 | D4: 0 | E4: 0 | F4: 0 | G4: 0 | H4: 0 | I4: 0 | J4: 0 | K4: 0 | L4: 0 | M4: 0 | N4: 0 | O4: 0 | P4: 0 | Q4: 0 | R4: 0 | S4: 0 | T4: 250 | U4: 0 | V4: 0
A5: 1233492 | B5: PBA-인버터(AD-1221E) | C5: 196 | D5: 576 | E5: 778 | F5: 402 | G5: 0 | H5: 0 | I5: 778 | J5: 778 | K5: 574 | L5: 0 | M5: 0 | N5: 0 | O5: 0 | P5: 0 | Q5: 0 | R5: 0 | S5: 538 | T5: 558 | U5: 0 | V5: 0
A6: 1233498 | B6: PBA-파워- 아세이(AD-1221E) | C6: 196 | D6: 576 | E6: 778 | F6: 402 | G6: 0 | H6: 0 | I6: 778 | J6: 778 | K6: 574 | L6: 0 | M6: 0 | N6: 0 | O6: 0 | P6: 0 | Q6: 0 | R6: 0 | S6: 538 | T6: 558 | U6: 0 | V6: 0
A7: 1233623 | B7: PBA-노이즈필터- 아세이(AD-1221E) | C7: 196 | D7: 576 | E7: 778 | F7: 402 | G7: 0 | H7: 0 | I7: 778 | J7: 778 | K7: 574 | L7: 0 | M7: 0 | N7: 0 | O7: 0 | P7: 0 | Q7: 0 | R7: 0 | S7: 538 | T7: 558 | U7: 0 | V7: 0
A8: 1233632 | B8: PBA-디스플레이- 아세이(CHP-5601N) | C8: 370 | D8: 0 | E8: 0 | F8: 0 | G8: 0 | H8: 0 | I8: 0 | J8: 0 | K8: 0 | L8: 0 | M8: 0 | N8: 0 | O8: 0 | P8: 0 | Q8: 0 | R8: 0 | S8: 0 | T8: 0 | U8: 0 | V8: 0
A9: 1232693 | B9: PBA-플라즈마파워유닛- 아세이(AP-1520C ) | C9: 0 | D9: 0 | E9: 0 | F9: 0 | G9: 0 | H9: 0 | I9: 0 | J9: 0 | K9: 0 | L9: 776 | M9: 660 | N9: 0 | O9: 0 | P9: 76 | Q9: 0 | R9: 0 | S9: 0 | T9: 0 | U9: 0 | V9: 0
A10: 1233025 | B10: PBA-메인- 아세이(AP-1520C) | C10: 0 | D10: 0 | E10: 0 | F10: 0 | G10: 0 | H10: 0 | I10: 0 | J10: 0 | K10: 0 | L10: 776 | M10: 660 | N10: 0 | O10: 0 | P10: 76 | Q10: 0 | R10: 0 | S10: 0 | T10: 0 | U10: 0 | V10: 0
A11: 1235623 | B11: PBA-SMPS- 아세이(CHP-7211N_WT,일본향) | C11: 0 | D11: 0 | E11: 0 | F11: 0 | G11: 0 | H11: 0 | I11: 0 | J11: 810 | K11: 126 | L11: 0 | M11: 0 | N11: 0 | O11: 0 | P11: 792 | Q11: 934 | R11: 734 | S11: 764 | T11: 0 | U11: 0 | V11: 0
A12: 1237088 | B12: PBA-파워- 아세이(BAS40-A) | C12: 1156 | D12: 826 | E12: 898 | F12: 448 | G12: 0 | H12: 0 | I12: 1092 | J12: 1212 | K12: 1130 | L12: 1274 | M12: 756 | N12: 0 | O12: 0 | P12: 86 | Q12: 0 | R12: 0 | S12: 636 | T12: 228 | U12: 0 | V12: 0
A13: 1237765 | B13: PBA-SMPS- 아세이(CHP-7211N,대만향) | C13: 0 | D13: 0 | E13: 0 | F13: 0 | G13: 0 | H13: 0 | I13: 0 | J13: 0 | K13: 200 | L13: 0 | M13: 0 | N13: 0 | O13: 0 | P13: 0 | Q13: 0 | R13: 0 | S13: 0 | T13: 0 | U13: 0 | V13: 0
... A25: 1239988 | B25: PBA-파워- 아세이(CHPI-7430N ) | C25: 0 | D25: 300 | E25: 0 | F25: 0 | G25: 0 | H25: 0 | I25: 0 | J25: 0 | K25: 0 | L25: 0 | M25: 0 | N25: 0 | O25: 0 | P25: 0 | Q25: 0 | R25: 0 | S25: 0 | T25: 0 | U25: 0 | V25: 0
A38: 품번 | B38: 품명 | C38: 06/24(화) | D38: 06/25(수) | E38: 06/26(목) | F38: 06/27(금) | G38: 06/28(토) | H38: 06/29(일) | I38: 06/30(월) | J38: 07/01(화) | K38: 07/02(수) | L38: 07/03(목) | M38: 07/04(금) | N38: 07/05(토) | O38: 07/06(일) | P38: 07/07(월) | Q38: 07/08(화) | R38: 07/09(수) | S38: 07/10(목) | T38: 07/11(금) | U38: 07/12(토) | V38: 07/13(일)
A39: 1237608 | B39: PBA-SMPS- 아세이(PU-300) | C39: 518 | D39: 692 | E39: 90 | F39: 0 | G39: 0 | H39: 0 | I39: 0 | J39: 0 | K39: 0 | L39: 0 | M39: 0 | N39: 0 | O39: 0 | P39: 0 | Q39: 0 | R39: 0 | S39: 0 | T39: 0 | U39: 0 | V39: 0
A40: 1232846 | B40: PBA-프론트- 아세이(P-6320L) | C40: 199 | D40: 0 | E40: 0 | F40: 0 | G40: 0 | H40: 0 | I40: 0 | J40: 0 | K40: 0 | L40: 0 | M40: 0 | N40: 0 | O40: 0 | P40: 365 | Q40: 448 | R40: 87 | S40: 0 | T40: 0 | U40: 0 | V40: 0
A41: 1232895 | B41: PBA-메인- 아세이(P-6320L) | C41: 199 | D41: 0 | E41: 0 | F41: 0 | G41: 0 | H41: 0 | I41: 0 | J41: 0 | K41: 0 | L41: 0 | M41: 0 | N41: 0 | O41: 0 | P41: 365 | Q41: 448 | R41: 87 | S41: 0 | T41: 0 | U41: 0 | V41: 0
A42: 1233384 | B42: 아답터(P-6320L) | C42: 199 | D42: 0 | E42: 0 | F42: 0 | G42: 0 | H42: 0 | I42: 0 | J42: 0 | K42: 0 | L42: 0 | M42: 0 | N42: 0 | O42: 0 | P42: 365 | Q42: 448 | R42: 87 | S42: 0 | T42: 0 | U42: 0 | V42: 0
A43: 1236110 | B43: PBA-파워(PU-600A) | C43: 333 | D43: 0 | E43: 0 | F43: 0 | G43: 0 | H43: 0 | I43: 0 | J43: 0 | K43: 0 | L43: 0 | M43: 0 | N43: 0 | O43: 0 | P43: 0 | Q43: 0 | R43: 0 | S43: 0 | T43: 0 | U43: 0 | V43: 0
A44: 1232775 | B44: PBA-파워- 아세이(AP-2021A) | C44: 159 | D44: 240 | E44: 229 | F44: 0 | G44: 0 | H44: 0 | I44: 119 | J44: 312 | K44: 243 | L44: 312 | M44: 312 | N44: 0 | O44: 0 | P44: 34 | Q44: 106 | R44: 415 | S44: 560 | T44: 243 | U44: 0 | V44: 0
A45: 1238605 | B45: PBA-파워- 아세이(AP-3024H) | C45: 0 | D45: 0 | E45: 92 | F45: 0 | G45: 0 | H45: 0 | I45: 74 | J45: 192 | K45: 150 | L45: 189 | M45: 191 | N45: 0 | O45: 0 | P45: 189 | Q45: 115 | R45: 0 | S45: 0 | T45: 0 | U45: 0 | V45: 0
A46: 1230685 | B46: PBA-파워- 아세이(AP-1519B) | C46: 0 | D46: 0 | E46: 0 | F46: 0 | G46: 0 | H46: 0 | I46: 0 | J46: 0 | K46: 0 | L46: 0 | M46: 0 | N46: 0 | O46: 0 | P46: 0 | Q46: 0 | R46: 0 | S46: 50 | T46: 250 | U46: 0 | V46: 0
A54: 품번 | B54: 품명 | C54: 06/24(화) | D54: 06/25(수) | E54: 06/26(목) | F54: 06/27(금) | G54: 06/28(토) | H54: 06/29(일) | I54: 06/30(월) | J54: 07/01(화) | K54: 07/02(수) | L54: 07/03(목) | M54: 07/04(금) | N54: 07/05(토) | O54: 07/06(일) | P54: 07/07(월) | Q54: 07/08(화) | R54: 07/09(수) | S54: 07/10(목) | T54: 07/11(금) | U54: 07/12(토) | V54: 07/13(일)
A55: 1234614 | B55: PBA-메인- 아세이(CHP-261N 일본향) | C55: 300 | D55: 0 | E55: 0 | F55: 0 | G55: 0 | H55: 0 | I55: 0 | J55: 324 | K55: 0 | L55: 0 | M55: 0 | N55: 0 | O55: 0 | P55: 600 | Q55: 500 | R55: 0 | S55: 0 | T55: 0 | U55: 0 | V55: 0
A56: 1221967 | B56: PBA-SMPS- 아세이(CHP-06ER, ERP(35W)) | C56: 0 | D56: 0 | E56: 0 | F56: 0 | G56: 0 | H56: 0 | I56: 0 | J56: 0 | K56: 0 | L56: 307 | M56: 0 | N56: 0 | O56: 0 | P56: 0 | Q56: 0 | R56: 0 | S56: 0 | T56: 0 | U56: 0 | V56: 0
A57: 1227306 | B57: PBA-파워V2- 아세이(CHPI-620L) | C57: 200 | D57: 0 | E57: 0 | F57: 0 | G57: 0 | H57: 0 | I57: 0 | J57: 270 | K57: 361 | L57: 500 | M57: 0 | N57: 0 | O57: 0 | P57: 0 | Q57: 350 | R57: 0 | S57: 0 | T57: 0 | U57: 0 | V57: 0
A58: 1225464 | B58: PBA-파워- 아세이(AP-1516D) | C58: 0 | D58: 0 | E58: 0 | F58: 0 | G58: 0 | H58: 0 | I58: 0 | J58: 0 | K58: 0 | L58: 0 | M58: 200 | N58: 0 | O58: 0 | P58: 0 | Q58: 0 | R58: 0 | S58: 0 | T58: 0 | U58: 0 | V58: 0
A59: 1229776 | B59: PBA-필터(CHP-5700R) | C59: 0 | D59: 0 | E59: 0 | F59: 0 | G59: 0 | H59: 0 | I59: 0 | J59: 0 | K59: 0 | L59: 210 | M59: 0 | N59: 0 | O59: 0 | P59: 0 | Q59: 150 | R59: 0 | S59: 0 | T59: 0 | U59: 0 | V59: 0
A60: 1231090 | B60: PBA-SMPS(CHP-5700R) | C60: 0 | D60: 0 | E60: 0 | F60: 0 | G60: 0 | H60: 0 | I60: 0 | J60: 0 | K60: 0 | L60: 210 | M60: 0 | N60: 0 | O60: 0 | P60: 0 | Q60: 150 | R60: 0 | S60: 0 | T60: 0 | U60: 0 | V60: 0
A61: 1229088 | B61: PBA-파워- 아세이(AP-3018B) | C61: 0 | D61: 0 | E61: 0 | F61: 0 | G61: 0 | H61: 0 | I61: 0 | J61: 0 | K61: 0 | L61: 0 | M61: 0 | N61: 0 | O61: 0 | P61: 150 | Q61: 0 | R61: 0 | S61: 0 | T61: 0 | U61: 0 | V61: 0
A62: 1231860 | B62: PBA-SMPS- 아세이(CPSI-8510L) | C62: 0 | D62: 0 | E62: 0 | F62: 0 | G62: 0 | H62: 0 | I62: 0 | J62: 0 | K62: 0 | L62: 0 | M62: 0 | N62: 0 | O62: 0 | P62: 0 | Q62: 100 | R62: 0 | S62: 0 | T62: 0 | U62: 0 | V62: 0
A63: 1231578 | B63: PBA-SMPS- 아세이(CHP-6200N) | C63: 0 | D63: 0 | E63: 200 | F63: 0 | G63: 0 | H63: 0 | I63: 0 | J63: 0 | K63: 0 | L63: 0 | M63: 0 | N63: 0 | O63: 0 | P63: 0 | Q63: 0 | R63: 0 | S63: 0 | T63: 0 | U63: 0 | V63: 0
A64: 1234222 | B64: PBA-파워- 아세이(AP-1520D_JP) | C64: 0 | D64: 0 | E64: 0 | F64: 0 | G64: 0 | H64: 0 | I64: 0 | J64: 0 | K64: 0 | L64: 0 | M64: 0 | N64: 0 | O64: 0 | P64: 424 | Q64: 0 | R64: 0 | S64: 0 | T64: 0 | U64: 0 | V64: 0
A65: 1232528 | B65: PBA-메인- 아세이(CHP-264L) | C65: 600 | D65: 295 | E65: 589 | F65: 429 | G65: 0 | H65: 0 | I65: 600 | J65: 600 | K65: 471 | L65: 1170 | M65: 1045 | N65: 0 | O65: 0 | P65: 1256 | Q65: 1400 | R65: 1271 | S65: 1400 | T65: 2054 | U65: 0 | V65: 0
A66: 1232553 | B66: PBA-메인- 아세이(CHP-6310 일본향) | C66: 0 | D66: 0 | E66: 0 | F66: 0 | G66: 0 | H66: 0 | I66: 0 | J66: 108 | K66: 0 | L66: 0 | M66: 0 | N66: 0 | O66: 0 | P66: 0 | Q66: 0 | R66: 0 | S66: 0 | T66: 0 | U66: 0 | V66: 0
A67: 1232846 | B67: PBA-프론트- 아세이(P-6320L) | C67: 0 | D67: 0 | E67: 146 | F67: 46 | G67: 0 | H67: 0 | I67: 0 | J67: 0 | K67: 0 | L67: 0 | M67: 0 | N67: 0 | O67: 0 | P67: 746 | Q67: 1000 | R67: 1000 | S67: 1000 | T67: 500 | U67: 0
A68: 1229050 | B68: PBA-파워V2(CHPI-620L)- 아세이(CHPI-620L) | C68: 0 | D68: 0 | E68: 0 | F68: 0 | G68: 0 | H68: 0 | I68: 0 | J68: 0 | K68: 0 | L68: 0 | M68: 0 | N68: 0 | O68: 0 | P68: 0 | Q68: 0 | R68: 0 | S68: 120 | T68: 0 | U68: 0 | V68: 0
A69: 1220847 | B69: PBA-SMPS(CHP-670, ERP(35W)) | C69: 0 | D69: 0 | E69: 0 | F69: 0 | G69: 0 | H69: 0 | I69: 0 | J69: 0 | K69: 0 | L69: 0 | M69: 0 | N69: 0 | O69: 0 | P69: 0 | Q69: 0 | R69: 450 | S69: 500 | T69: 500 | U69: 0 | V69: 0
A70: 1225801 | B70: PBA-SMPS(CHP-480L) | C70: 220 | D70: 0 | E70: 0 | F70: 0 | G70: 0 | H70: 0 | I70: 0 | J70: 0 | K70: 0 | L70: 0 | M70: 0 | N70: 0 | O70: 0 | P70: 0 | Q70: 0 | R70: 0 | S70: 0 | T70: 0 | U70: 0 | V70: 0
...

Sheet 0625
A1: 품번 | B1: 품명 | C1: 06/25(수) | D1: 06/26(목) | E1: 06/27(금) | F1: 06/28(토) | G1: 06/29(일) | H1: 06/30(월) | I1: 07/01(화) | J1: 07/02(수) | K1: 07/03(목) | L1: 07/04(금) | M1: 07/05(토) | N1: 07/06(일) | O1: 07/07(월) | P1: 07/08(화) | Q1: 07/09(수) | R1: 07/10(목) | S1: 07/11(금) | T1: 07/12(토) | U1: 07/13(일)
A2: 1229673 | B2: PBA-TOTAL- 아세이(BA20-D) | C2: 0 | D2: 0 | E2: 0 | F2: 0 | G2: 0 | H2: 0 | I2: 0 | J2: 0 | K2: 0 | L2: 0 | M2: 0 | N2: 0 | O2: 0 | P2: 200 | Q2: 228 | R2: 0 | S2: 172 | T2: 0 | U2: 0
A3: 1230854 | B3: PBA-토탈- 아세이(BA34-A) | C3: 0 | D3: 0 | E3: 0 | F3: 0 | G3: 0 | H3: 0 | I3: 0 | J3: 0 | K3: 0 | L3: 0 | M3: 0 | N3: 0 | O3: 150 | P3: 0 | Q3: 0 | R3: 0 | S3: 0 | T3: 0 | U3: 0
A4: 1231202 | B4: PBA-파워- 아세이(AP-1019D) | C4: 0 | D4: 0 | E4: 0 | F4: 0 | G4: 0 | H4: 0 | I4: 0 | J4: 0 | K4: 0 | L4: 0 | M4: 0 | N4: 0 | O4: 0 | P4: 0 | Q4: 0 | R4: 0 | S4: 250 | T4: 0 | U4: 0
A5: 1233492 | B5: PBA-인버터(AD-1221E) | C5: 576 | D5: 778 | E5: 402 | F5: 0 | G5: 0 | H5: 582 | I5: 778 | J5: 574 | K5: 0 | L5: 0 | M5: 0 | N5: 0 | O5: 0 | P5: 0 | Q5: 0 | R5: 538 | S5: 558 | T5: 0 | U5: 0
A6: 1233498 | B6: PBA-파워- 아세이(AD-1221E) | C6: 576 | D6: 778 | E6: 402 | F6: 0 | G6: 0 | H6: 582 | I6: 778 | J6: 574 | K6: 0 | L6: 0 | M6: 0 | N6: 0 | O6: 0 | P6: 0 | Q6: 0 | R6: 538 | S6: 558 | T6: 0 | U6: 0
A7: 1233623 | B7: PBA-노이즈필터- 아세이(AD-1221E) | C7: 576 | D7: 778 | E7: 402 | F7: 0 | G7: 0 | H7: 582 | I7: 778 | J7: 574 | K7: 0 | L7: 0 | M7: 0 | N7: 0 | O7: 0 | P7: 0 | Q7: 0 | R7: 538 | S7: 558 | T7: 0 | U7: 0
A8: 1232693 | B8: PBA-플라즈마파워유닛- 아세이(AP-1520C ) | C8: 0 | D8: 0 | E8: 0 | F8: 0 | G8: 0 | H8: 0 | I8: 0 | J8: 0 | K8: 776 | L8: 660 | M8: 0 | N8: 0 | O8: 76 | P8: 0 | Q8: 0 | R8: 0 | S8: 0 | T8: 0 | U8: 0
A9: 1233025 | B9: PBA-메인- 아세이(AP-1520C) | C9: 0 | D9: 0 | E9: 0 | F9: 0 | G9: 0 | H9: 0 | I9: 0 | J9: 0 | K9: 776 | L9: 660 | M9: 0 | N9: 0 | O9: 76 | P9: 0 | Q9: 0 | R9: 0 | S9: 0 | T9: 0 | U9: 0
A10: 1235623 | B10: PBA-SMPS- 아세이(CHP-7211N_WT,일본향) | C10: 0 | D10: 0 | E10: 0 | F10: 0 | G10: 0 | H10: 0 | I10: 810 | J10: 126 | K10: 0 | L10: 0 | M10: 0 | N10: 0 | O10: 792 | P10: 934 | Q10: 734 | R10: 764 | S10: 0 | T10: 0 | U10: 0
A11: 1237088 | B11: PBA-파워- 아세이(BAS40-A) | C11: 826 | D11: 898 | E11: 448 | F11: 0 | G11: 0 | H11: 1092 | I11: 1212 | J11: 1130 | K11: 1274 | L11: 756 | M11: 0 | N11: 0 | O11: 86 | P11: 0 | Q11: 0 | R11: 636 | S11: 228 | T11: 0 | U11: 0
H12: 264
A13: 1237765 | B13: PBA-SMPS- 아세이(CHP-7211N,대만향) | C13: 0 | D13: 0 | E13: 0 | F13: 0 | G13: 0 | H13: 0 | I13: 0 | J13: 200 | K13: 0 | L13: 0 | M13: 0 | N13: 0 | O13: 0 | P13: 0 | Q13: 0 | R13: 0 | S13: 0 | T13: 0 | U13: 0
A14: 1237748 | B14: PBA-SMPS- 아세이(CHP-1201N) | C14: 0 | D14: 0 | E14: 0 | F14: 0 | G14: 0 | H14: 0 | I14: 0 | J14: 344 | K14: 20 | L14: 0 | M14: 0 | N14: 0 | O14: 0 | P14: 0 | Q14: 0 | R14: 0 | S14: 0 | T14: 0 | U14: 0
A15: 1231898 | B15: PBA-컨트롤- 아세이(BA36-A) | C15: 0 | D15: 0 | E15: 0 | F15: 0 | G15: 0 | H15: 0 | I15: 0 | J15: 0 | K15: 0 | L15: 0 | M15: 0 | N15: 0 | O15: 0 | P15: 740 | Q15: 580 | R15: 480 | S15: 550 | T15: 0 | U15: 0
A16: 1237586 | B16: PBA-토탈- 아세이(BA36-B) | C16: 0 | D16: 0 | E16: 0 | F16: 0 | G16: 0 | H16: 0 | I16: 0 | J16: 0 | K16: 0 | L16: 0 | M16: 0 | N16: 0 | O16: 0 | P16: 740 | Q16: 580 | R16: 480 | S16: 550 | T16: 0 | U16: 0
A17: 1236091 | B17: PBA-파워- 아세이(BAS25-A) | C17: 0 | D17: 300 | E17: 0 | F17: 0 | G17: 0 | H17: 0 | I17: 0 | J17: 0 | K17: 0 | L17: 0 | M17: 0 | N17: 0 | O17: 0 | P17: 0 | Q17: 0 | R17: 0 | S17: 0 | T17: 0 | U17: 0
A18: 1234905 | B18: PBA-파워(CHPI-7400N) | C18: 354 | D18: 410 | E18: 212 | F18: 0 | G18: 0 | H18: 762 | I18: 460 | J18: 50 | K18: 0 | L18: 0 | M18: 0 | N18: 0 | O18: 0 | P18: 0 | Q18: 0 | R18: 0 | S18: 0 | T18: 0 | U18: 0
A19: 1238128 | B19: PBA-SMPS(CHP-6210N,말련향) | C19: 104 | D19: 872 | E19: 580 | F19: 0 | G19: 0 | H19: 114 | I19: 0 | J19: 94 | K19: 1016 | L19: 826 | M19: 0 | N19: 0 | O19: 539 | P19: 50 | Q19: 0 | R19: 66 | S19: 510 | T19: 0 | U19: 0
A20: 1236962 | B20: PBA-파워- 아세이(BAS37-B) | C20: 218 | D20: 274 | E20: 274 | F20: 0 | G20: 0 | H20: 300 | I20: 200 | J20: 0 | K20: 136 | L20: 166 | M20: 0 | N20: 0 | O20: 300 | P20: 300 | Q20: 300 | R20: 300 | S20: 0 | T20: 0 | U20: 0
A21: 1233761 | B21: PBA-파워- 아세이(BAS38-A) | C21: 0 | D21: 0 | E21: 0 | F21: 0 | G21: 0 | H21: 0 | I21: 0 | J21: 0 | K21: 0 | L21: 0 | M21: 0 | N21: 0 | O21: 100 | P21: 0 | Q21: 0 | R21: 100 | S21: 200 | T21: 0 | U21: 0
A22: 1239651 | B22: PBA-파워- 아세이(BAS47-A) | C22: 0 | D22: 0 | E22: 0 | F22: 0 | G22: 0 | H22: 0 | I22: 0 | J22: 0 | K22: 0 | L22: 100 | M22: 0 | N22: 0 | O22: 450 | P22: 300 | Q22: 100 | R22: 0 | S22: 300 | T22: 0 | U22: 0
A23: 1240180 | B23: PBA-SMPS- 아세이(CHPI-7410N) | C23: 0 | D23: 0 | E23: 0 | F23: 0 | G23: 0 | H23: 0 | I23: 0 | J23: 100 | K23: 0 | L23: 0 | M23: 0 | N23: 0 | O23: 0 | P23: 284 | Q23: 422 | R23: 664 | S23: 664 | T23: 0 | U23: 0
A24: 1240184 | B24: PBA-히터- 아세이(CHPI-7410N) | C24: 0 | D24: 0 | E24: 0 | F24: 0 | G24: 0 | H24: 0 | I24: 0 | J24: 60 | K24: 0 | L24: 0 | M24: 0 | N24: 0 | O24: 0 | P24: 284 | Q24: 422 | R24: 474 | S24: 324 | T24: 0 | U24: 0
A25: 1239988 | B25: PBA-파워- 아세이(CHPI-7430N ) | C25: 300 | D25: 0 | E25: 0 | F25: 0 | G25: 0 | H25: 0 | I25: 0 | J25: 0 | K25: 0 | L25: 0 | M25: 0 | N25: 0 | O25: 0 | P25: 0 | Q25: 0 | R25: 0 | S25: 0 | T25: 0 | U25: 0
A31: 품번 | B31: 품명 | C31: 06/25(수) | D31: 06/26(목) | E31: 06/27(금) | F31: 06/28(토) | G31: 06/29(일) | H31: 06/30(월) | I31: 07/01(화) | J31: 07/02(수) | K31: 07/03(목) | L31: 07/04(금) | M31: 07/05(토) | N31: 07/06(일) | O31: 07/07(월) | P31: 07/08(화) | Q31: 07/09(수) | R31: 07/10(목) | S31: 07/11(금) | T31: 07/12(토) | U31: 07/13(일)
A32: 1237608 | B32: PBA-SMPS- 아세이(PU-300) | C32: 692 | D32: 90 | E32: 0 | F32: 0 | G32: 0 | H32: 0 | I32: 0 | J32: 0 | K32: 0 | L32: 0 | M32: 0 | N32: 0 | O32: 0 | P32: 0 | Q32: 0 | R32: 0 | S32: 0 | T32: 0 | U32: 0
A33: 1232846 | B33: PBA-프론트- 아세이(P-6320L) | C33: 0 | D33: 0 | E33: 0 | F33: 0 | G33: 0 | H33: 0 | I33: 0 | J33: 0 | K33: 0 | L33: 0 | M33: 0 | N33: 0 | O33: 365 | P33: 448 | Q33: 87 | R33: 0 | S33: 0 | T33: 0 | U33: 0
A34: 1232895 | B34: PBA-메인- 아세이(P-6320L) | C34: 0 | D34: 0 | E34: 0 | F34: 0 | G34: 0 | H34: 0 | I34: 0 | J34: 0 | K34: 0 | L34: 0 | M34: 0 | N34: 0 | O34: 365 | P34: 448 | Q34: 87 | R34: 0 | S34: 0 | T34: 0 | U34: 0
A35: 1233384 | B35: 아답터(P-6320L) | C35: 0 | D35: 0 | E35: 0 | F35: 0 | G35: 0 | H35: 0 | I35: 0 | J35: 0 | K35: 0 | L35: 0 | M35: 0 | N35: 0 | O35: 365 | P35: 448 | Q35: 87 | R35: 0 | S35: 0 | T35: 0 | U35: 0
A36: 1232775 | B36: PBA-파워- 아세이(AP-2021A) | C36: 240 | D36: 229 | E36: 0 | F36: 0 | G36: 0 | H36: 119 | I36: 312 | J36: 243 | K36: 312 | L36: 309 | M36: 0 | N36: 0 | O36: 34 | P36: 106 | Q36: 415 | R36: 560 | S36: 243 | T36: 0 | U36: 0
A37: 1238605 | B37: PBA-파워- 아세이(AP-3024H) | C37: 0 | D37: 92 | E37: 0 | F37: 0 | G37: 0 | H37: 74 | I37: 192 | J37: 150 | K37: 189 | L37: 191 | M37: 0 | N37: 0 | O37: 189 | P37: 115 | Q37: 0 | R37: 0 | S37: 0 | T37: 0 | U37: 0
A38: 1230685 | B38: PBA-파워- 아세이(AP-1519B) | C38: 0 | D38: 0 | E38: 0 | F38: 0 | G38: 0 | H38: 0 | I38: 0 | J38: 0 | K38: 0 | L38: 0 | M38: 0 | N38: 0 | O38: 0 | P38: 0 | Q38: 0 | R38: 50 | S38: 250 | T38: 0 | U38: 0
A47: 품번 | B47: 품명 | C47: 06/25(수) | D47: 06/26(목) | E47: 06/27(금) | F47: 06/28(토) | G47: 06/29(일) | H47: 06/30(월) | I47: 07/01(화) | J47: 07/02(수) | K47: 07/03(목) | L47: 07/04(금) | M47: 07/05(토) | N47: 07/06(일) | O47: 07/07(월) | P47: 07/08(화) | Q47: 07/09(수) | R47: 07/10(목) | S47: 07/11(금) | T47: 07/12(토) | U47: 07/13(일)
A48: 1234614 | B48: PBA-메인- 아세이(CHP-261N 일본향) | C48: 0 | D48: 0 | E48: 0 | F48: 0 | G48: 0 | H48: 0 | I48: 324 | J48: 0 | K48: 0 | L48: 0 | M48: 0 | N48: 0 | O48: 0 | P48: 0 | Q48: 0 | R48: 98 | S48: 730 | T48: 0 | U48: 0
A49: 1221967 | B49: PBA-SMPS- 아세이(CHP-06ER, ERP(35W)) | C49: 0 | D49: 0 | E49: 0 | F49: 0 | G49: 0 | H49: 0 | I49: 0 | J49: 0 | K49: 263 | L49: 44 | M49: 0 | N49: 0 | O49: 0 | P49: 0 | Q49: 0 | R49: 0 | S49: 0 | T49: 0 | U49: 0
A50: 1227306 | B50: PBA-파워V2- 아세이(CHPI-620L) | C50: 0 | D50: 0 | E50: 0 | F50: 0 | G50: 0 | H50: 0 | I50: 270 | J50: 383 | K50: 483 | L50: 64 | M50: 0 | N50: 0 | O50: 0 | P50: 0 | Q50: 350 | R50: 300 | S50: 0 | T50: 0 | U50: 0
A51: 1225464 | B51: PBA-파워- 아세이(AP-1516D) | C51: 0 | D51: 0 | E51: 0 | F51: 0 | G51: 0 | H51: 0 | I51: 0 | J51: 0 | K51: 0 | L51: 175 | M51: 0 | N51: 0 | O51: 25 | P51: 0 | Q51: 0 | R51: 0 | S51: 0 | T51: 0 | U51: 0
A52: 1229776 | B52: PBA-필터(CHP-5700R) | C52: 0 | D52: 0 | E52: 0 | F52: 0 | G52: 0 | H52: 0 | I52: 0 | J52: 0 | K52: 210 | L52: 0 | M52: 0 | N52: 0 | O52: 0 | P52: 150 | Q52: 0 | R52: 0 | S52: 0 | T52: 0 | U52: 0
A53: 1231090 | B53: PBA-SMPS(CHP-5700R) | C53: 0 | D53: 0 | E53: 0 | F53: 0 | G53: 0 | H53: 0 | I53: 0 | J53: 0 | K53: 210 | L53: 0 | M53: 0 | N53: 0 | O53: 0 | P53: 150 | Q53: 0 | R53: 0 | S53: 0 | T53: 0 | U53: 0
...

Sheet 0626
A1: 품번 | B1: 품명 | C1: 구분 | D1: 06/26(목) | E1: 06/27(금) | F1: 06/28(토) | G1: 06/29(일) | H1: 06/30(월) | I1: 07/01(화) | J1: 07/02(수) | K1: 07/03(목) | L1: 07/04(금) | M1: 07/05(토) | N1: 07/06(일) | O1: 07/07(월) | P1: 07/08(화) | Q1: 07/09(수) | R1: 07/10(목) | S1: 07/11(금) | T1: 07/12(토) | U1: 07/13(일)
A2: 1229673 | B2: PBA-TOTAL- 아세이(BA20-D) | C2: 합계 | D2: 0 | E2: 0 | F2: 0 | G2: 0 | H2: 0 | I2: 0 | J2: 0 | K2: 0 | L2: 0 | M2: 0 | N2: 0 | O2: 0 | P2: 200 | Q2: 228 | R2: 0 | S2: 172 | T2: 0 | U2: 0
A3: 1230854 | B3: PBA-토탈- 아세이(BA34-A) | C3: 합계 | D3: 0 | E3: 0 | F3: 0 | G3: 0 | H3: 0 | I3: 0 | J3: 0 | K3: 0 | L3: 0 | M3: 0 | N3: 0 | O3: 150 | P3: 0 | Q3: 0 | R3: 0 | S3: 0 | T3: 0 | U3: 0
A4: 1231202 | B4: PBA-파워- 아세이(AP-1019D) | C4: 합계 | D4: 0 | E4: 0 | F4: 0 | G4: 0 | H4: 0 | I4: 0 | J4: 0 | K4: 0 | L4: 0 | M4: 0 | N4: 0 | O4: 0 | P4: 0 | Q4: 0 | R4: 0 | S4: 250 | T4: 0 | U4: 0
A5: 1233492 | B5: PBA-인버터(AD-1221E) | C5: 합계 | D5: 778 | E5: 402 | F5: 0 | G5: 0 | H5: 582 | I5: 778 | J5: 574 | K5: 0 | L5: 0 | M5: 0 | N5: 0 | O5: 0 | P5: 0 | Q5: 0 | R5: 538 | S5: 558 | T5: 0 | U5: 0
A6: 1233498 | B6: PBA-파워- 아세이(AD-1221E) | C6: 합계 | D6: 778 | E6: 402 | F6: 0 | G6: 0 | H6: 582 | I6: 778 | J6: 574 | K6: 0 | L6: 0 | M6: 0 | N6: 0 | O6: 0 | P6: 0 | Q6: 0 | R6: 538 | S6: 558 | T6: 0 | U6: 0
A7: 1233623 | B7: PBA-노이즈필터- 아세이(AD-1221E) | C7: 합계 | D7: 778 | E7: 402 | F7: 0 | G7: 0 | H7: 582 | I7: 778 | J7: 574 | K7: 0 | L7: 0 | M7: 0 | N7: 0 | O7: 0 | P7: 0 | Q7: 0 | R7: 538 | S7: 558 | T7: 0 | U7: 0
A8: 1232693 | B8: PBA-플라즈마파워유닛- 아세이(AP-1520C ) | C8: 합계 | D8: 0 | E8: 0 | F8: 0 | G8: 0 | H8: 0 | I8: 0 | J8: 0 | K8: 776 | L8: 660 | M8: 0 | N8: 0 | O8: 76 | P8: 0 | Q8: 0 | R8: 0 | S8: 0 | T8: 0 | U8: 0
A9: 1233025 | B9: PBA-메인- 아세이(AP-1520C) | C9: 합계 | D9: 0 | E9: 0 | F9: 0 | G9: 0 | H9: 0 | I9: 0 | J9: 0 | K9: 776 | L9: 660 | M9: 0 | N9: 0 | O9: 76 | P9: 0 | Q9: 0 | R9: 0 | S9: 0 | T9: 0 | U9: 0
A10: 1235623 | B10: PBA-SMPS- 아세이(CHP-7211N_WT,일본향) | C10: 합계 | D10: 0 | E10: 0 | F10: 0 | G10: 0 | H10: 0 | I10: 810 | J10: 126 | K10: 0 | L10: 0 | M10: 0 | N10: 0 | O10: 792 | P10: 934 | Q10: 734 | R10: 764 | S10: 0 | T10: 0 | U10: 0
A11: 1237088 | B11: PBA-파워- 아세이(BAS40-A) | C11: 합계 | D11: 898 | E11: 448 | F11: 0 | G11: 0 | H11: 1092 | I11: 1212 | J11: 1130 | K11: 1274 | L11: 756 | M11: 0 | N11: 0 | O11: 86 | P11: 0 | Q11: 0 | R11: 636 | S11: 228 | T11: 0 | U11: 0
A12: 1237765 | B12: PBA-SMPS- 아세이(CHP-7211N,대만향) | C12: 합계 | D12: 0 | E12: 0 | F12: 0 | G12: 0 | H12: 0 | I12: 0 | J12: 200 | K12: 0 | L12: 0 | M12: 0 | N12: 0 | O12: 0 | P12: 0 | Q12: 0 | R12: 0 | S12: 0 | T12: 0 | U12: 0
A13: 1237748 | B13: PBA-SMPS- 아세이(CHP-1201N) | C13: 합계 | D13: 0 | E13: 0 | F13: 0 | G13: 0 | H13: 0 | I13: 0 | J13: 344 | K13: 20 | L13: 0 | M13: 0 | N13: 0 | O13: 0 | P13: 0 | Q13: 0 | R13: 0 | S13: 0 | T13: 0 | U13: 0
... A23: 1240184 | B23: PBA-히터- 아세이(CHPI-7410N) | C23: 합계 | D23: 0 | E23: 0 | F23: 0 | G23: 0 | H23: 0 | I23: 0 | J23: 60 | K23: 0 | L23: 0 | M23: 0 | N23: 0 | O23: 0 | P23: 284 | Q23: 422 | R23: 474 | S23: 324 | T23: 0 | U23: 0
A32: 품번 | B32: 품명 | C32: 구분 | D32: 06/26(목) | E32: 06/27(금) | F32: 06/28(토) | G32: 06/29(일) | H32: 06/30(월) | I32: 07/01(화) | J32: 07/02(수) | K32: 07/03(목) | L32: 07/04(금) | M32: 07/05(토) | N32: 07/06(일) | O32: 07/07(월) | P32: 07/08(화) | Q32: 07/09(수) | R32: 07/10(목) | S32: 07/11(금) | T32: 07/12(토) | U32: 07/13(일)
A33: 1237608 | B33: PBA-SMPS- 아세이(PU-300) | C33: 합계 | D33: 90 | E33: 0 | F33: 0 | G33: 0 | H33: 0 | I33: 0 | J33: 0 | K33: 0 | L33: 0 | M33: 0 | N33: 0 | O33: 0 | P33: 0 | Q33: 0 | R33: 0 | S33: 0 | T33: 0 | U33: 0
A34: 1232846 | B34: PBA-프론트- 아세이(P-6320L) | C34: 합계 | D34: 0 | E34: 0 | F34: 0 | G34: 0 | H34: 0 | I34: 0 | J34: 0 | K34: 0 | L34: 0 | M34: 0 | N34: 0 | O34: 365 | P34: 448 | Q34: 87 | R34: 0 | S34: 0 | T34: 0 | U34: 0
A35: 1232895 | B35: PBA-메인- 아세이(P-6320L) | C35: 합계 | D35: 0 | E35: 0 | F35: 0 | G35: 0 | H35: 0 | I35: 0 | J35: 0 | K35: 0 | L35: 0 | M35: 0 | N35: 0 | O35: 365 | P35: 448 | Q35: 87 | R35: 0 | S35: 0 | T35: 0 | U35: 0
A36: 1233384 | B36: 아답터(P-6320L) | C36: 합계 | D36: 0 | E36: 0 | F36: 0 | G36: 0 | H36: 0 | I36: 0 | J36: 0 | K36: 0 | L36: 0 | M36: 0 | N36: 0 | O36: 365 | P36: 448 | Q36: 87 | R36: 0 | S36: 0 | T36: 0 | U36: 0
A37: 1232775 | B37: PBA-파워- 아세이(AP-2021A) | C37: 합계 | D37: 229 | E37: 0 | F37: 0 | G37: 0 | H37: 119 | I37: 312 | J37: 243 | K37: 312 | L37: 309 | M37: 0 | N37: 0 | O37: 34 | P37: 106 | Q37: 415 | R37: 560 | S37: 243 | T37: 0 | U37: 0
A38: 1238605 | B38: PBA-파워- 아세이(AP-3024H) | C38: 합계 | D38: 92 | E38: 0 | F38: 0 | G38: 0 | H38: 74 | I38: 192 | J38: 150 | K38: 189 | L38: 191 | M38: 0 | N38: 0 | O38: 189 | P38: 115 | Q38: 0 | R38: 0 | S38: 0 | T38: 0 | U38: 0
A39: 1230685 | B39: PBA-파워- 아세이(AP-1519B) | C39: 합계 | D39: 0 | E39: 0 | F39: 0 | G39: 0 | H39: 0 | I39: 0 | J39: 0 | K39: 0 | L39: 0 | M39: 0 | N39: 0 | O39: 0 | P39: 0 | Q39: 0 | R39: 50 | S39: 250 | T39: 0 | U39: 0
A45: 품번 | B45: 품명 | C45: 구분 | D45: 06/26(목) | E45: 06/27(금) | F45: 06/28(토) | G45: 06/29(일) | H45: 06/30(월) | I45: 07/01(화) | J45: 07/02(수) | K45: 07/03(목) | L45: 07/04(금) | M45: 07/05(토) | N45: 07/06(일) | O45: 07/07(월) | P45: 07/08(화) | Q45: 07/09(수) | R45: 07/10(목) | S45: 07/11(금) | T45: 07/12(토) | U45: 07/13(일)
A46: 1234614 | B46: PBA-메인- 아세이(CHP-261N 일본향) | C46: 합계 | D46: 0 | E46: 0 | F46: 0 | G46: 0 | H46: 0 | I46: 324 | J46: 0 | K46: 0 | L46: 0 | M46: 0 | N46: 0 | O46: 0 | P46: 0 | Q46: 0 | R46: 98 | S46: 730 | T46: 0 | U46: 0
A47: 1221967 | B47: PBA-SMPS- 아세이(CHP-06ER, ERP(35W)) | C47: 합계 | D47: 0 | E47: 0 | F47: 0 | G47: 0 | H47: 0 | I47: 0 | J47: 0 | K47: 263 | L47: 44 | M47: 0 | N47: 0 | O47: 0 | P47: 0 | Q47: 0 | R47: 0 | S47: 0 | T47: 0 | U47: 0
A48: 1227306 | B48: PBA-파워V2- 아세이(CHPI-620L) | C48: 합계 | D48: 0 | E48: 0 | F48: 0 | G48: 0 | H48: 0 | I48: 270 | J48: 383 | K48: 483 | L48: 64 | M48: 0 | N48: 0 | O48: 0 | P48: 0 | Q48: 350 | R48: 300 | S48: 0 | T48: 0 | U48: 0
A49: 1225464 | B49: PBA-파워- 아세이(AP-1516D) | C49: 합계 | D49: 0 | E49: 0 | F49: 0 | G49: 0 | H49: 0 | I49: 0 | J49: 0 | K49: 0 | L49: 175 | M49: 0 | N49: 0 | O49: 25 | P49: 0 | Q49: 0 | R49: 0 | S49: 0 | T49: 0 | U49: 0
A50: 1229776 | B50: PBA-필터(CHP-5700R) | C50: 합계 | D50: 0 | E50: 0 | F50: 0 | G50: 0 | H50: 0 | I50: 0 | J50: 0 | K50: 210 | L50: 0 | M50: 0 | N50: 0 | O50: 0 | P50: 150 | Q50: 0 | R50: 0 | S50: 0 | T50: 0 | U50: 0
A51: 1231090 | B51: PBA-SMPS(CHP-5700R) | C51: 합계 | D51: 0 | E51: 0 | F51: 0 | G51: 0 | H51: 0 | I51: 0 | J51: 0 | K51: 210 | L51: 0 | M51: 0 | N51: 0 | O51: 0 | P51: 150 | Q51: 0 | R51: 0 | S51: 0 | T51: 0 | U51: 0
A52: 1229088 | B52: PBA-파워- 아세이(AP-3018B) | C52: 합계 | D52: 0 | E52: 0 | F52: 0 | G52: 0 | H52: 0 | I52: 0 | J52: 0 | K52: 0 | L52: 0 | M52: 0 | N52: 0 | O52: 150 | P52: 0 | Q52: 0 | R52: 0 | S52: 0 | T52: 0 | U52: 0
A53: 1231860 | B53: PBA-SMPS- 아세이(CPSI-8510L) | C53: 합계 | D53: 0 | E53: 0 | F53: 0 | G53: 0 | H53: 0 | I53: 0 | J53: 0 | K53: 0 | L53: 0 | M53: 0 | N53: 0 | O53: 0 | P53: 100 | Q53: 0 | R53: 0 | S53: 0 | T53: 0 | U53: 0
A54: 1231578 | B54: PBA-SMPS- 아세이(CHP-6200N) | C54: 합계 | D54: 200 | E54: 0 | F54: 0 | G54: 0 | H54: 0 | I54: 0 | J54: 0 | K54: 0 | L54: 0 | M54: 0 | N54: 0 | O54: 400 | P54: 0 | Q54: 0 | R54: 0 | S54: 0 | T54: 0 | U54: 0
A55: 1234222 | B55: PBA-파워- 아세이(AP-1520D_JP) | C55: 합계 | D55: 0 | E55: 0 | F55: 0 | G55: 0 | H55: 0 | I55: 0 | J55: 0 | K55: 0 | L55: 0 | M55: 0 | N55: 0 | O55: 0 | P55: 0 | Q55: 0 | R55: 0 | S55: 424 | T55: 0 | U55: 0
A56: 1232528 | B56: PBA-메인- 아세이(CHP-264L) | C56: 합계 | D56: 589 | E56: 429 | F56: 0 | G56: 0 | H56: 600 | I56: 600 | J56: 471 | K56: 2060 | L56: 1085 | M56: 0 | N56: 0 | O56: 1330 | P56: 1330 | Q56: 511 | R56: 600 | S56: 1727 | T56: 0 | U56: 0
A57: 1232553 | B57: PBA-메인- 아세이(CHP-6310 일본향) | C57: 합계 | D57: 0 | E57: 0 | F57: 0 | G57: 0 | H57: 0 | I57: 108 | J57: 0 | K57: 0 | L57: 0 | M57: 0 | N57: 0 | O57: 0 | P57: 0 | Q57: 0 | R57: 0 | S57: 0 | T57: 0 | U57: 0
A58: 1232846 | B58: PBA-프론트- 아세이(P-6320L) | C58: 합계 | D58: 146 | E58: 46 | F58: 0 | G58: 0 | H58: 0 | I58: 0 | J58: 0 | K58: 0 | L58: 0 | M58: 0 | N58: 0 | O58: 0 | P58: 0 | Q58: 0 | R58: 0 | S58: 0 | T58: 0 | U58: 0
A59: 1229050 | B59: PBA-파워V2(CHPI-620L)- 아세이(CHPI-620L) | C59: 합계 | D59: 0 | E59: 0 | F59: 0 | G59: 0 | H59: 0 | I59: 0 | J59: 0 | K59: 0 | M59: 0 | N59: 0 | O59: 0 | P59: 0 | Q59: 0 | R59: 120 | S59: 0 | T59: 0 | U59: 0
A60: 1235097 | B60: PBA-파워(CHPI-5810L) | C60: 합계 | D60: 343 | E60: 38 | F60: 0 | G60: 0 | H60: 0 | I60: 0 | J60: 0 | K60: 0 | L60: 0 | M60: 0 | N60: 0 | O60: 0 | P60: 400 | Q60: 200 | R60: 0 | S60: 0 | T60: 0 | U60: 0
A61: 1232775 | B61: PBA-파워- 아세이(AP-2021A) | C61: 합계 | D61: 0 | E61: 0 | F61: 0 | G61: 0 | H61: 0 | I61: 90 | J61: 0 | K61: 0 | L61: 0 | M61: 0 | N61: 0 | O61: 0 | P61: 0 | Q61: 0 | R61: 0 | S61: 0 | T61: 0 | U61: 0
A62: 1235845 | B62: PBA-메인 CHP 아세이(CHP-6310 유럽향) | C62: 합계 | D62: 0 | E62: 477 | F62: 0 | G62: 0 | H62: 622 | I62: 101 | J62: 0 | K62: 0 | L62: 0 | M62: 0 | N62: 0 | O62: 0 | P62: 0 | Q62: 0 | R62: 0 | S62: 0 | T62: 0 | U62: 0
...

Sheet 0627
A1: 품번 | B1: 품명 | C1: 06/27(금) | D1: 06/28(토) | E1: 06/29(일) | F1: 06/30(월) | G1: 07/01(화) | H1: 07/02(수) | I1: 07/03(목) | J1: 07/04(금) | K1: 07/05(토) | L1: 07/06(일) | M1: 07/07(월) | N1: 07/08(화) | O1: 07/09(수) | P1: 07/10(목) | Q1: 07/11(금) | R1: 07/12(토) | S1: 07/13(일)
A2: 1229673 | B2: PBA-TOTAL- 아세이(BA20-D) | C2: 0 | D2: 0 | E2: 0 | F2: 0 | G2: 0 | H2: 0 | I2: 0 | J2: 0 | K2: 0 | L2: 0 | M2: 0 | N2: 200 | O2: 228 | P2: 0 | Q2: 172 | R2: 0 | S2: 0
A3: 1230854 | B3: PBA-토탈- 아세이(BA34-A) | C3: 0 | D3: 0 | E3: 0 | F3: 0 | G3: 0 | H3: 0 | I3: 0 | J3: 0 | K3: 0 | L3: 0 | M3: 150 | N3: 0 | O3: 0 | P3: 0 | Q3: 0 | R3: 0 | S3: 0
A4: 1231202 | B4: PBA-파워- 아세이(AP-1019D) | C4: 0 | D4: 0 | E4: 0 | F4: 0 | G4: 0 | H4: 0 | I4: 0 | J4: 0 | K4: 0 | L4: 0 | M4: 0 | N4: 0 | O4: 0 | P4: 0 | Q4: 250 | R4: 0 | S4: 0
A5: 1233492 | B5: PBA-인버터(AD-1221E) | C5: 402 | D5: 0 | E5: 0 | F5: 582 | G5: 778 | H5: 574 | I5: 0 | J5: 0 | K5: 0 | L5: 0 | M5: 0 | N5: 0 | O5: 0 | P5: 538 | Q5: 558 | R5: 0 | S5: 0
A6: 1233498 | B6: PBA-파워- 아세이(AD-1221E) | C6: 402 | D6: 0 | E6: 0 | F6: 582 | G6: 778 | H6: 574 | I6: 0 | J6: 0 | K6: 0 | L6: 0 | M6: 0 | N6: 0 | O6: 0 | P6: 538 | Q6: 558 | R6: 0 | S6: 0
A7: 1233623 | B7: PBA-노이즈필터- 아세이(AD-1221E) | C7: 402 | D7: 0 | E7: 0 | F7: 582 | G7: 778 | H7: 574 | I7: 0 | J7: 0 | K7: 0 | L7: 0 | M7: 0 | N7: 0 | O7: 0 | P7: 538 | Q7: 558 | R7: 0 | S7: 0
A8: 1232693 | B8: PBA-플라즈마파워유닛- 아세이(AP-1520C ) | C8: 0 | D8: 0 | E8: 0 | F8: 0 | G8: 0 | H8: 0 | I8: 776 | J8: 660 | K8: 0 | L8: 0 | M8: 76 | N8: 0 | O8: 0 | P8: 0 | Q8: 0 | R8: 0 | S8: 0
A9: 1233025 | B9: PBA-메인- 아세이(AP-1520C) | C9: 0 | D9: 0 | E9: 0 | F9: 0 | G9: 0 | H9: 0 | I9: 776 | J9: 660 | K9: 0 | L9: 0 | M9: 76 | N9: 0 | O9: 0 | P9: 0 | Q9: 0 | R9: 0 | S9: 0
A10: 1235623 | B10: PBA-SMPS- 아세이(CHP-7211N_WT,일본향) | C10: 0 | D10: 0 | E10: 0 | F10: 0 | G10: 810 | H10: 126 | I10: 0 | J10: 0 | K10: 0 | L10: 0 | M10: 792 | N10: 934 | O10: 734 | P10: 764 | Q10: 0 | R10: 0 | S10: 0
A11: 1237088 | B11: PBA-파워- 아세이(BAS40-A) | C11: 448 | D11: 0 | E11: 0 | F11: 1092 | G11: 1212 | H11: 1130 | I11: 1274 | J11: 756 | K11: 0 | L11: 0 | M11: 86 | N11: 0 | O11: 0 | P11: 636 | Q11: 228 | R11: 0 | S11: 0
A12: 1237765 | B12: PBA-SMPS- 아세이(CHP-7211N,대만향) | C12: 0 | D12: 0 | E12: 0 | F12: 0 | G12: 0 | H12: 200 | I12: 0 | J12: 0 | K12: 0 | L12: 0 | M12: 0 | N12: 0 | O12: 0 | P12: 0 | Q12: 0 | R12: 0 | S12: 0
A13: 1237748 | B13: PBA-SMPS- 아세이(CHP-1201N) | C13: 0 | D13: 0 | E13: 0 | F13: 0 | G13: 0 | H13: 344 | I13: 20 | J13: 0 | K13: 0 | L13: 0 | M13: 0 | N13: 0 | O13: 0 | P13: 0 | Q13: 0 | R13: 0 | S13: 0
... A22: 1240184 | B22: PBA-히터- 아세이(CHPI-7410N) | C22: 0 | D22: 0 | E22: 0 | F22: 0 | G22: 0 | H22: 60 | I22: 0 | J22: 0 | K22: 0 | L22: 0 | M22: 0 | N22: 284 | O22: 422 | P22: 474 | Q22: 324 | R22: 0 | S22: 0
A32: 품번 | B32: 품명 | C32: 06/27(금) | D32: 06/28(토) | E32: 06/29(일) | F32: 06/30(월) | G32: 07/01(화) | H32: 07/02(수) | I32: 07/03(목) | J32: 07/04(금) | K32: 07/05(토) | L32: 07/06(일) | M32: 07/07(월) | N32: 07/08(화) | O32: 07/09(수) | P32: 07/10(목) | Q32: 07/11(금) | R32: 07/12(토) | S32: 07/13(일)
A33: 1232846 | B33: PBA-프론트- 아세이(P-6320L) | C33: 0 | D33: 0 | E33: 0 | F33: 0 | G33: 0 | H33: 0 | I33: 0 | J33: 0 | K33: 0 | L33: 0 | M33: 365 | N33: 448 | O33: 87 | P33: 0 | Q33: 0 | R33: 0 | S33: 0
A34: 1232895 | B34: PBA-메인- 아세이(P-6320L) | C34: 0 | D34: 0 | E34: 0 | F34: 0 | G34: 0 | H34: 0 | I34: 0 | J34: 0 | K34: 0 | L34: 0 | M34: 365 | N34: 448 | O34: 87 | P34: 0 | Q34: 0 | R34: 0 | S34: 0
A35: 1233384 | B35: 아답터(P-6320L) | C35: 0 | D35: 0 | E35: 0 | F35: 0 | G35: 0 | H35: 0 | I35: 0 | J35: 0 | K35: 0 | L35: 0 | M35: 365 | N35: 448 | O35: 87 | P35: 0 | Q35: 0 | R35: 0 | S35: 0
A36: 1232775 | B36: PBA-파워- 아세이(AP-2021A) | C36: 0 | D36: 0 | E36: 0 | F36: 119 | G36: 312 | H36: 243 | I36: 312 | J36: 309 | K36: 0 | L36: 0 | M36: 34 | N36: 106 | O36: 415 | P36: 560 | Q36: 243 | R36: 0 | S36: 0
A37: 1238605 | B37: PBA-파워- 아세이(AP-3024H) | C37: 0 | D37: 0 | E37: 0 | F37: 74 | G37: 192 | H37: 150 | I37: 189 | J37: 191 | K37: 0 | L37: 0 | M37: 189 | N37: 115 | O37: 0 | P37: 0 | Q37: 0 | R37: 0 | S37: 0
A38: 1230685 | B38: PBA-파워- 아세이(AP-1519B) | C38: 0 | D38: 0 | E38: 0 | F38: 0 | G38: 0 | H38: 0 | I38: 0 | J38: 0 | K38: 0 | L38: 0 | M38: 0 | N38: 0 | O38: 0 | P38: 50 | Q38: 250 | R38: 0 | S38: 0
A46: 품번 | B46: 품명 | C46: 06/27(금) | D46: 06/28(토) | E46: 06/29(일) | F46: 06/30(월) | G46: 07/01(화) | H46: 07/02(수) | I46: 07/03(목) | J46: 07/04(금) | K46: 07/05(토) | L46: 07/06(일) | M46: 07/07(월) | N46: 07/08(화) | O46: 07/09(수) | P46: 07/10(목) | Q46: 07/11(금) | R46: 07/12(토) | S46: 07/13(일)
A47: 1234614 | B47: PBA-메인- 아세이(CHP-261N 일본향) | C47: 0 | D47: 0 | E47: 0 | F47: 0 | G47: 324 | H47: 0 | I47: 0 | J47: 0 | K47: 0 | L47: 0 | M47: 0 | N47: 0 | O47: 0 | P47: 98 | Q47: 730 | R47: 0 | S47: 0
A48: 1221967 | B48: PBA-SMPS- 아세이(CHP-06ER, ERP(35W)) | C48: 0 | D48: 0 | E48: 0 | F48: 0 | G48: 0 | H48: 0 | I48: 263 | J48: 44 | K48: 0 | L48: 0 | M48: 0 | N48: 0 | O48: 0 | P48: 0 | Q48: 0 | R48: 0 | S48: 0
A49: 1227306 | B49: PBA-파워V2- 아세이(CHPI-620L) | C49: 0 | D49: 0 | E49: 0 | F49: 0 | G49: 270 | H49: 383 | I49: 483 | J49: 64 | K49: 0 | L49: 0 | M49: 0 | N49: 0 | O49: 350 | P49: 300 | Q49: 0 | R49: 0 | S49: 0 | T49: 1
A50: 1225464 | B50: PBA-파워- 아세이(AP-1516D) | C50: 0 | D50: 0 | E50: 0 | F50: 0 | G50: 0 | H50: 0 | I50: 0 | J50: 175 | K50: 0 | L50: 0 | M50: 25 | N50: 0 | O50: 0 | P50: 0 | Q50: 0 | R50: 0 | S50: 0
A51: 1229776 | B51: PBA-필터(CHP-5700R) | C51: 0 | D51: 0 | E51: 0 | F51: 0 | G51: 0 | H51: 0 | I51: 210 | J51: 0 | K51: 0 | L51: 0 | M51: 0 | N51: 150 | O51: 0 | P51: 0 | Q51: 0 | R51: 0 | S51: 0
A52: 1231090 | B52: PBA-SMPS(CHP-5700R) | C52: 0 | D52: 0 | E52: 0 | F52: 0 | G52: 0 | H52: 0 | I52: 210 | J52: 0 | K52: 0 | L52: 0 | M52: 0 | N52: 150 | O52: 0 | P52: 0 | Q52: 0 | R52: 0 | S52: 0
A53: 1229088 | B53: PBA-파워- 아세이(AP-3018B) | C53: 0 | D53: 0 | E53: 0 | F53: 0 | G53: 0 | H53: 0 | I53: 0 | J53: 0 | K53: 0 | L53: 0 | M53: 150 | N53: 0 | O53: 0 | P53: 0 | Q53: 0 | R53: 0 | S53: 0
A54: 1231860 | B54: PBA-SMPS- 아세이(CPSI-8510L) | C54: 0 | D54: 0 | E54: 0 | F54: 0 | G54: 0 | H54: 0 | I54: 0 | J54: 0 | K54: 0 | L54: 0 | M54: 0 | N54: 100 | O54: 0 | P54: 0 | Q54: 0 | R54: 0 | S54: 0
A55: 1231578 | B55: PBA-SMPS- 아세이(CHP-6200N) | C55: 0 | D55: 0 | E55: 0 | F55: 0 | G55: 0 | H55: 0 | I55: 0 | J55: 0 | K55: 0 | L55: 0 | M55: 400 | N55: 0 | O55: 0 | Q55: 0 | R55: 0 | S55: 0
A56: 1234222 | B56: PBA-파워- 아세이(AP-1520D_JP) | C56: 0 | D56: 0 | E56: 0 | F56: 0 | G56: 0 | H56: 0 | I56: 0 | J56: 0 | K56: 0 | L56: 0 | M56: 0 | N56: 0 | O56: 0 | P56: 0 | Q56: 424 | R56: 0 | S56: 0
A57: 1232528 | B57: PBA-메인- 아세이(CHP-264L) | C57: 471 | D57: 0 | E57: 0 | F57: 600 | G57: 600 | H57: 471 | I57: 2060 | J57: 1085 | K57: 0 | L57: 0 | M57: 1330 | N57: 1330 | O57: 511 | P57: 600 | Q57: 1685 | R57: 0 | S57: 0
A58: 1232553 | B58: PBA-메인- 아세이(CHP-6310 일본향) | C58: 0 | D58: 0 | E58: 0 | F58: 0 | G58: 108 | H58: 0 | I58: 0 | J58: 0 | K58: 0 | L58: 0 | M58: 0 | N58: 0 | O58: 0 | P58: 0 | Q58: 0 | R58: 0 | S58: 0
A59: 1232846 | B59: PBA-프론트- 아세이(P-6320L) | C59: 46 | D59: 0 | E59: 0 | F59: 0 | G59: 0 | H59: 0 | I59: 0 | J59: 0 | K59: 0 | L59: 0 | M59: 0 | N59: 0 | O59: 0 | P59: 0 | Q59: 0 | R59: 0 | S59: 0
A60: 1229050 | B60: PBA-파워V2(CHPI-620L)- 아세이(CHPI-620L) | C60: 0 | D60: 0 | E60: 0 | F60: 0 | G60: 0 | H60: 0 | I60: 0 | J60: 0 | K60: 0 | L60: 0 | M60: 0 | N60: 0 | O60: 0 | P60: 120 | Q60: 0 | R60: 0 | S60: 0
A61: 1235097 | B61: PBA-파워(CHPI-5810L) | C61: 38 | D61: 0 | E61: 0 | F61: 0 | G61: 0 | H61: 0 | I61: 0 | J61: 0 | K61: 0 | L61: 0 | M61: 0 | N61: 400 | O61: 200 | P61: 0 | Q61: 0 | R61: 0 | S61: 0
A62: 1232775 | B62: PBA-파워- 아세이(AP-2021A) | C62: 0 | D62: 0 | E62: 0 | F62: 0 | G62: 90 | H62: 0 | I62: 0 | J62: 0 | K62: 0 | L62: 0 | M62: 0 | N62: 0 | O62: 0 | P62: 0 | Q62: 0 | R62: 0 | S62: 0
A63: 1235845 | B63: PBA-메인 CHP 아세이(CHP-6310 유럽향) | C63: 477 | D63: 0 | E63: 0 | F63: 622 | G63: 101 | H63: 0 | I63: 0 | J63: 0 | K63: 0 | L63: 0 | M63: 0 | N63: 0 | O63: 0 | P63: 0 | Q63: 0 | R63: 0 | S63: 0
A64: 1236930 | B64: PBA-SMPS- 아세이(CHPI-7520L) | D64: 0 | E64: 0 | F64: 336 | G64: 336 | H64: 159 | I64: 0 | J64: 0 | K64: 0 | L64: 0 | M64: 0 | N64: 150 | O64: 249 | P64: 324 | Q64: 330 | R64: 0 | S64: 0
...

Sheet 0630
A1: 품번 | B1: 품명 | C1: 06/30(월) | D1: 07/01(화) | E1: 07/02(수) | F1: 07/03(목) | G1: 07/04(금) | H1: 07/05(토) | I1: 07/06(일) | J1: 07/07(월) | K1: 07/08(화) | L1: 07/09(수) | M1: 07/10(목) | N1: 07/11(금) | O1: 07/12(토) | P1: 07/13(일)
A2: 1229673 | B2: PBA-TOTAL- 아세이(BA20-D) | C2: 0 | D2: 0 | E2: 0 | F2: 0 | G2: 0 | H2: 0 | I2: 0 | J2: 0 | K2: 200 | L2: 228 | M2: 0 | N2: 172 | O2: 0 | P2: 0
A3: 1230854 | B3: PBA-토탈- 아세이(BA34-A) | C3: 0 | D3: 0 | E3: 0 | F3: 0 | G3: 0 | H3: 0 | I3: 0 | J3: 150 | K3: 0 | L3: 0 | M3: 0 | N3: 0 | O3: 0 | P3: 0
A4: 1231202 | B4: PBA-파워- 아세이(AP-1019D) | C4: 0 | D4: 0 | E4: 0 | F4: 0 | G4: 0 | H4: 0 | I4: 0 | J4: 0 | K4: 0 | L4: 0 | M4: 0 | N4: 250 | O4: 0 | P4: 0
A5: 1233492 | B5: PBA-인버터(AD-1221E) | C5: 582 | D5: 778 | E5: 574 | F5: 0 | G5: 0 | H5: 0 | I5: 0 | J5: 0 | K5: 0 | L5: 0 | M5: 538 | N5: 558 | O5: 0 | P5: 0
A6: 1233498 | B6: PBA-파워- 아세이(AD-1221E) | C6: 582 | D6: 778 | E6: 574 | F6: 0 | G6: 0 | H6: 0 | I6: 0 | J6: 0 | K6: 0 | L6: 0 | M6: 538 | N6: 558 | O6: 0 | P6: 0
A7: 1233623 | B7: PBA-노이즈필터- 아세이(AD-1221E) | C7: 582 | D7: 778 | E7: 574 | F7: 0 | G7: 0 | H7: 0 | I7: 0 | J7: 0 | K7: 0 | L7: 0 | M7: 538 | N7: 558 | O7: 0 | P7: 0
A8: 1232693 | B8: PBA-플라즈마파워유닛- 아세이(AP-1520C ) | C8: 0 | D8: 0 | E8: 0 | F8: 776 | G8: 840 | H8: 0 | I8: 0 | J8: 76 | K8: 0 | L8: 0 | M8: 0 | N8: 0 | O8: 0 | P8: 0
A9: 1233025 | B9: PBA-메인- 아세이(AP-1520C) | C9: 0 | D9: 0 | E9: 0 | F9: 776 | G9: 840 | H9: 0 | I9: 0 | J9: 76 | K9: 0 | L9: 0 | M9: 0 | N9: 0 | O9: 0 | P9: 0
A10: 1235623 | B10: PBA-SMPS- 아세이(CHP-7211N_WT,일본향) | C10: 0 | D10: 810 | E10: 126 | F10: 0 | G10: 0 | H10: 0 | I10: 0 | J10: 784 | K10: 934 | L10: 734 | M10: 734 | N10: 30 | O10: 0 | P10: 0
A11: 1237088 | B11: PBA-파워- 아세이(BAS40-A) | C11: 1092 | D11: 1212 | E11: 1130 | F11: 1274 | G11: 1076 | H11: 0 | I11: 0 | J11: 86 | K11: 0 | L11: 0 | M11: 314 | N11: 228 | O11: 0 | P11: 0
A12: 1237765 | B12: PBA-SMPS- 아세이(CHP-7211N,대만향) | C12: 0 | D12: 0 | E12: 200 | F12: 0 | G12: 0 | H12: 0 | I12: 0 | J12: 0 | K12: 0 | L12: 0 | M12: 0 | N12: 0 | O12: 0 | P12: 0
A13: 1237748 | B13: PBA-SMPS- 아세이(CHP-1201N) | C13: 0 | D13: 0 | E13: 344 | F13: 20 | G13: 0 | H13: 0 | I13: 0 | J13: 0 | K13: 0 | L13: 0 | M13: 0 | N13: 0 | O13: 0 | P13: 0
... A22: 1240184 | B22: PBA-히터- 아세이(CHPI-7410N) | C22: 0 | D22: 0 | E22: 60 | F22: 0 | G22: 0 | H22: 0 | I22: 0 | J22: 0 | K22: 284 | L22: 422 | M22: 384 | N22: 324 | O22: 0 | P22: 0
A28: 품번 | B28: 품명 | C28: 06/30(월) | D28: 07/01(화) | E28: 07/02(수) | F28: 07/03(목) | G28: 07/04(금) | H28: 07/05(토) | I28: 07/06(일) | J28: 07/07(월) | K28: 07/08(화) | L28: 07/09(수) | M28: 07/10(목) | N28: 07/11(금) | O28: 07/12(토) | P28: 07/13(일)
A29: 1232846 | B29: PBA-프론트- 아세이(P-6320L) | C29: 0 | D29: 0 | E29: 0 | F29: 0 | G29: 0 | H29: 0 | I29: 0 | J29: 365 | K29: 448 | L29: 87 | M29: 0 | N29: 0 | O29: 0 | P29: 0
A30: 1232895 | B30: PBA-메인- 아세이(P-6320L) | C30: 0 | D30: 0 | E30: 0 | F30: 0 | G30: 0 | H30: 0 | I30: 0 | J30: 365 | K30: 448 | L30: 87 | M30: 0 | N30: 0 | O30: 0 | P30: 0
A31: 1233384 | B31: 아답터(P-6320L) | C31: 0 | D31: 0 | E31: 0 | F31: 0 | G31: 0 | H31: 0 | I31: 0 | J31: 365 | K31: 448 | L31: 87 | M31: 0 | N31: 0 | O31: 0 | P31: 0
A32: 1232775 | B32: PBA-파워- 아세이(AP-2021A) | C32: 119 | D32: 312 | E32: 243 | F32: 312 | G32: 309 | H32: 0 | I32: 0 | J32: 34 | K32: 106 | L32: 415 | M32: 560 | N32: 243 | O32: 0 | P32: 0
A33: 1238605 | B33: PBA-파워- 아세이(AP-3024H) | C33: 74 | D33: 192 | E33: 150 | F33: 189 | G33: 191 | H33: 0 | I33: 0 | J33: 189 | K33: 115 | L33: 0 | M33: 0 | N33: 0 | O33: 0 | P33: 0
A34: 1230685 | B34: PBA-파워- 아세이(AP-1519B) | C34: 0 | D34: 0 | E34: 0 | F34: 0 | G34: 0 | H34: 0 | I34: 0 | J34: 0 | K34: 0 | L34: 0 | M34: 50 | N34: 250 | O34: 0 | P34: 0
A41: 품번 | B41: 품명 | C41: 06/30(월) | D41: 07/01(화) | E41: 07/02(수) | F41: 07/03(목) | G41: 07/04(금) | H41: 07/05(토) | I41: 07/06(일) | J41: 07/07(월) | K41: 07/08(화) | L41: 07/09(수) | M41: 07/10(목) | N41: 07/11(금) | O41: 07/12(토) | P41: 07/13(일)
A42: 1234614 | B42: PBA-메인- 아세이(CHP-261N 일본향) | C42: 0 | D42: 324 | E42: 0 | F42: 0 | G42: 0 | H42: 0 | I42: 0 | J42: 0 | K42: 0 | L42: 0 | M42: 98 | N42: 730 | O42: 0 | P42: 0
A43: 1221967 | B43: PBA-SMPS- 아세이(CHP-06ER, ERP(35W)) | C43: 0 | D43: 0 | E43: 0 | F43: 263 | G43: 44 | H43: 0 | I43: 0 | J43: 0 | K43: 0 | L43: 0 | M43: 0 | N43: 0 | O43: 0 | P43: 0
A44: 1227306 | B44: PBA-파워V2- 아세이(CHPI-620L) | C44: 0 | D44: 270 | E44: 383 | F44: 483 | G44: 64 | H44: 0 | I44: 0 | J44: 0 | K44: 0 | L44: 350 | M44: 300 | N44: 0 | O44: 0 | P44: 0
A45: 1225464 | B45: PBA-파워- 아세이(AP-1516D) | C45: 0 | D45: 0 | E45: 0 | F45: 0 | G45: 175 | H45: 0 | I45: 0 | J45: 25 | K45: 0 | L45: 0 | M45: 0 | N45: 0 | O45: 0 | P45: 0
A46: 1229776 | B46: PBA-필터(CHP-5700R) | C46: 0 | D46: 0 | E46: 0 | F46: 210 | G46: 0 | H46: 0 | I46: 0 | J46: 0 | K46: 150 | L46: 0 | M46: 0 | N46: 0 | O46: 0 | P46: 0
A47: 1231090 | B47: PBA-SMPS(CHP-5700R) | C47: 0 | D47: 0 | E47: 0 | F47: 210 | G47: 0 | H47: 0 | I47: 0 | J47: 0 | K47: 150 | L47: 0 | M47: 0 | N47: 0 | O47: 0 | P47: 0
A48: 1229088 | B48: PBA-파워- 아세이(AP-3018B) | C48: 0 | D48: 0 | E48: 0 | F48: 0 | G48: 0 | H48: 0 | I48: 0 | J48: 150 | K48: 0 | L48: 0 | M48: 0 | N48: 0 | O48: 0 | P48: 0
A49: 1231860 | B49: PBA-SMPS- 아세이(CPSI-8510L) | C49: 0 | D49: 0 | E49: 0 | F49: 0 | G49: 0 | H49: 0 | I49: 0 | J49: 0 | K49: 100 | L49: 0 | M49: 0 | N49: 0 | O49: 0 | P49: 0
A50: 1231578 | B50: PBA-SMPS- 아세이(CHP-6200N) | C50: 0 | D50: 0 | E50: 0 | F50: 0 | G50: 0 | H50: 0 | I50: 0 | J50: 400 | K50: 0 | L50: 0 | M50: 0 | N50: 0 | O50: 0 | P50: 0
A51: 1234222 | B51: PBA-파워- 아세이(AP-1520D_JP) | C51: 0 | D51: 0 | E51: 0 | F51: 0 | G51: 0 | H51: 0 | I51: 0 | J51: 0 | K51: 0 | L51: 0 | M51: 0 | N51: 425 | O51: 0 | P51: 0
A52: 1232528 | B52: PBA-메인- 아세이(CHP-264L) | C52: 600 | D52: 600 | E52: 471 | F52: 2060 | G52: 1085 | H52: 0 | I52: 0 | J52: 1330 | K52: 1330 | L52: 511 | M52: 600 | N52: 1685 | O52: 0 | P52: 0
A53: 1232553 | B53: PBA-메인- 아세이(CHP-6310 일본향) | C53: 0 | D53: 108 | E53: 0 | F53: 0 | G53: 0 | H53: 0 | I53: 0 | J53: 0 | K53: 0 | L53: 0 | M53: 0 | N53: 0 | O53: 0 | P53: 0
... A64: 1238092 | B64: PBA-SMPS- 아세이(CHP-3140N_BG,싱가포르향) | C64: 0 | D64: 0 | E64: 0 | F64: 11 | G64: 0 | H64: 0 | I64: 0 | J64: 0 | K64: 0 | L64: 0 | M64: 0 | N64: 0 | O64: 0 | P64: 0

Sheet 0701
A1: 품번 | B1: 품명 | C1: 구분 | D1: 07/01(화) | E1: 07/02(수) | F1: 07/03(목) | G1: 07/04(금) | H1: 07/05(토) | I1: 07/06(일) | J1: 07/07(월) | K1: 07/08(화) | L1: 07/09(수) | M1: 07/10(목) | N1: 07/11(금) | O1: 07/12(토) | P1: 07/13(일) | Q1: 07/14(월) | R1: 07/15(화) | S1: 07/16(수) | T1: 07/17(목) | U1: 07/18(금) | V1: 07/19(토) | W1: 07/20(일)
A2: 1229673 | B2: PBA-TOTAL- 아세이(BA20-D) | C2: 합계 | D2: 0 | E2: 0 | F2: 0 | G2: 0 | H2: 0 | I2: 0 | J2: 0 | K2: 200 | L2: 228 | M2: 0 | N2: 172 | O2: 0 | P2: 0 | Q2: 100 | R2: 100 | S2: 100 | T2: 0 | U2: 0 | V2: 0 | W2: 0
A3: 1230854 | B3: PBA-토탈- 아세이(BA34-A) | C3: 합계 | D3: 0 | E3: 0 | F3: 0 | G3: 0 | H3: 0 | I3: 0 | J3: 150 | K3: 0 | L3: 0 | M3: 0 | N3: 0 | O3: 0 | P3: 0 | Q3: 0 | R3: 0 | S3: 0 | T3: 0 | U3: 0 | V3: 0 | W3: 0
A4: 1231202 | B4: PBA-파워- 아세이(AP-1019D) | C4: 합계 | D4: 0 | E4: 0 | F4: 0 | G4: 0 | H4: 0 | I4: 0 | J4: 0 | K4: 0 | L4: 0 | M4: 0 | N4: 250 | O4: 0 | P4: 0 | Q4: 50 | R4: 0 | S4: 0 | T4: 0 | U4: 0 | V4: 0 | W4: 0
A5: 1233492 | B5: PBA-인버터(AD-1221E) | C5: 합계 | D5: 778 | E5: 574 | F5: 0 | G5: 0 | H5: 0 | I5: 0 | J5: 0 | K5: 0 | L5: 0 | M5: 538 | N5: 558 | O5: 0 | P5: 0 | Q5: 704 | R5: 778 | S5: 168 | T5: 0 | U5: 0 | V5: 0 | W5: 0
A6: 1233498 | B6: PBA-파워- 아세이(AD-1221E) | C6: 합계 | D6: 778 | E6: 574 | F6: 0 | G6: 0 | H6: 0 | I6: 0 | J6: 0 | K6: 0 | L6: 0 | M6: 538 | N6: 558 | O6: 0 | P6: 0 | Q6: 704 | R6: 778 | S6: 168 | T6: 0 | U6: 0 | V6: 0 | W6: 0
A7: 1233623 | B7: PBA-노이즈필터- 아세이(AD-1221E) | C7: 합계 | D7: 778 | E7: 574 | F7: 0 | G7: 0 | H7: 0 | I7: 0 | J7: 0 | K7: 0 | L7: 0 | M7: 538 | N7: 558 | O7: 0 | P7: 0 | Q7: 704 | R7: 778 | S7: 168 | T7: 0 | U7: 0 | V7: 0 | W7: 0
A8: 1232693 | B8: PBA-플라즈마파워유닛- 아세이(AP-1520C ) | C8: 합계 | D8: 0 | E8: 0 | F8: 776 | G8: 840 | H8: 0 | I8: 0 | J8: 76 | K8: 0 | L8: 0 | M8: 0 | N8: 0 | O8: 0 | P8: 0 | Q8: 0 | R8: 0 | S8: 0 | T8: 0 | U8: 0 | V8: 0 | W8: 0
A9: 1233025 | B9: PBA-메인- 아세이(AP-1520C) | C9: 합계 | D9: 0 | E9: 0 | F9: 776 | G9: 840 | H9: 0 | I9: 0 | J9: 76 | K9: 0 | L9: 0 | M9: 0 | N9: 0 | O9: 0 | P9: 0 | Q9: 0 | R9: 0 | S9: 0 | T9: 0 | U9: 0 | V9: 0 | W9: 0
A10: 1235623 | B10: PBA-SMPS- 아세이(CHP-7211N_WT,일본향) | C10: 합계 | D10: 810 | E10: 126 | F10: 0 | G10: 0 | H10: 0 | I10: 0 | J10: 792 | K10: 934 | L10: 734 | M10: 734 | N10: 30 | O10: 0 | P10: 0 | Q10: 0 | R10: 0 | S10: 0 | T10: 0 | U10: 0 | V10: 0 | W10: 0
A11: 1237088 | B11: PBA-파워- 아세이(BAS40-A) | C11: 합계 | D11: 1212 | E11: 1130 | F11: 1274 | G11: 1076 | H11: 0 | I11: 0 | J11: 124 | K11: 0 | L11: 0 | M11: 314 | N11: 0 | O11: 0 | P11: 0 | Q11: 582 | R11: 850 | S11: 220 | T11: 576 | U11: 430 | V11: 0 | W11: 0
A12: 1237765 | B12: PBA-SMPS- 아세이(CHP-7211N,대만향) | C12: 합계 | D12: 0 | E12: 200 | F12: 0 | G12: 0 | H12: 0 | I12: 0 | J12: 0 | K12: 0 | L12: 0 | M12: 0 | N12: 0 | O12: 0 | P12: 0 | Q12: 0 | R12: 0 | S12: 0 | T12: 0 | U12: 0 | V12: 0 | W12: 0
A13: 1237748 | B13: PBA-SMPS- 아세이(CHP-1201N) | C13: 합계 | D13: 0 | E13: 344 | F13: 20 | G13: 0 | H13: 0 | I13: 0 | J13: 0 | K13: 0 | L13: 0 | M13: 0 | N13: 0 | O13: 0 | P13: 0 | Q13: 0 | R13: 0 | S13: 0 | T13: 0 | U13: 0 | V13: 0 | W13: 0
... A23: 1240184 | B23: PBA-히터- 아세이(CHPI-7410N) | C23: 합계 | D23: 0 | E23: 60 | F23: 0 | G23: 0 | H23: 0 | I23: 0 | J23: 0 | K23: 316 | L23: 468 | M23: 402 | N23: 390 | O23: 0 | P23: 0 | Q23: 736 | R23: 382 | S23: 452 | T23: 736 | U23: 548 | V23: 0 | W23: 0
A32: 품번 | B32: 품명 | C32: 구분 | D32: 07/01(화) | E32: 07/02(수) | F32: 07/03(목) | G32: 07/04(금) | H32: 07/05(토) | I32: 07/06(일) | J32: 07/07(월) | K32: 07/08(화) | L32: 07/09(수) | M32: 07/10(목) | N32: 07/11(금) | O32: 07/12(토) | P32: 07/13(일) | Q32: 07/14(월) | R32: 07/15(화) | S32: 07/16(수) | T32: 07/17(목) | U32: 07/18(금) | V32: 07/19(토) | W32: 07/20(일)
A33: 1219539 | B33: 아답터(P-300R/P-230R, 말련향, 파워넷) | C33: 합계 | D33: 0 | E33: 0 | F33: 0 | G33: 0 | H33: 0 | I33: 0 | J33: 0 | K33: 0 | L33: 0 | M33: 0 | N33: 0 | O33: 0 | P33: 0 | Q33: 0 | R33: 224 | S33: 216 | T33: 0 | U33: 0 | V33: 0 | W33: 0
A34: 1232846 | B34: PBA-프론트- 아세이(P-6320L) | C34: 합계 | D34: 0 | E34: 0 | F34: 0 | G34: 0 | H34: 0 | I34: 0 | J34: 365 | K34: 448 | L34: 87 | M34: 0 | N34: 0 | O34: 0 | P34: 0 | Q34: 0 | R34: 0 | S34: 0 | T34: 0 | U34: 120 | V34: 0 | W34: 0
A35: 1232895 | B35: PBA-메인- 아세이(P-6320L) | C35: 합계 | D35: 0 | E35: 0 | F35: 0 | G35: 0 | H35: 0 | I35: 0 | J35: 365 | K35: 448 | L35: 87 | M35: 0 | N35: 0 | O35: 0 | P35: 0 | Q35: 0 | R35: 0 | S35: 0 | T35: 0 | U35: 120 | V35: 0 | W35: 0
A36: 1233384 | B36: 아답터(P-6320L) | C36: 합계 | D36: 0 | E36: 0 | F36: 0 | G36: 0 | H36: 0 | I36: 0 | J36: 365 | K36: 448 | L36: 87 | M36: 0 | N36: 0 | O36: 0 | P36: 0 | Q36: 0 | R36: 0 | S36: 0 | T36: 0 | U36: 120 | V36: 0 | W36: 0
A37: 1232775 | B37: PBA-파워- 아세이(AP-2021A) | C37: 합계 | D37: 312 | E37: 243 | F37: 312 | G37: 309 | H37: 0 | I37: 0 | J37: 34 | K37: 106 | L37: 415 | M37: 537 | N37: 192 | O37: 0 | P37: 0 | Q37: 0 | R37: 105 | S37: 229 | T37: 619 | U37: 397 | V37: 0 | W37: 0
A38: 1238605 | B38: PBA-파워- 아세이(AP-3024H) | C38: 합계 | D38: 192 | E38: 150 | F38: 189 | G38: 191 | H38: 0 | I38: 0 | J38: 189 | K38: 115 | L38: 0 | M38: 0 | N38: 0 | O38: 0 | P38: 0 | Q38: 0 | R38: 0 | S38: 0 | T38: 0 | U38: 0 | V38: 0 | W38: 0
A39: 1230685 | B39: PBA-파워- 아세이(AP-1519B) | C39: 합계 | D39: 0 | E39: 0 | F39: 0 | G39: 0 | H39: 0 | I39: 0 | J39: 0 | K39: 0 | L39: 0 | M39: 0 | N39: 39 | O39: 0 | P39: 0 | Q39: 420 | R39: 41 | S39: 0 | T39: 0 | U39: 0 | V39: 0 | W39: 0
A48: 품번 | B48: 품명 | C48: 구분 | D48: 07/01(화) | E48: 07/02(수) | F48: 07/03(목) | G48: 07/04(금) | H48: 07/05(토) | I48: 07/06(일) | J48: 07/07(월) | K48: 07/08(화) | L48: 07/09(수) | M48: 07/10(목) | N48: 07/11(금) | O48: 07/12(토) | P48: 07/13(일) | Q48: 07/14(월) | R48: 07/15(화) | S48: 07/16(수) | T48: 07/17(목) | U48: 07/18(금) | V48: 07/19(토) | W48: 07/20(일)
A49: 1234614 | B49: PBA-메인- 아세이(CHP-261N 일본향) | C49: 합계 | D49: 324 | E49: 0 | F49: 0 | G49: 0 | H49: 0 | I49: 0 | J49: 0 | K49: 0 | L49: 0 | M49: 98 | N49: 730 | O49: 0 | P49: 0 | Q49: 272 | R49: 0 | S49: 0 | T49: 0 | U49: 0 | V49: 0 | W49: 0
A50: 1220847 | B50: PBA-SMPS(CHP-670, ERP(35W)) | C50: 합계 | D50: 0 | E50: 0 | F50: 0 | G50: 0 | H50: 0 | I50: 0 | J50: 0 | K50: 0 | L50: 0 | M50: 0 | N50: 0 | O50: 0 | P50: 0 | Q50: 0 | R50: 0 | S50: 780 | T50: 500 | U50: 500 | V50: 0 | W50: 0
A51: 1221967 | B51: PBA-SMPS- 아세이(CHP-06ER, ERP(35W)) | C51: 합계 | D51: 0 | E51: 0 | F51: 263 | G51: 44 | H51: 0 | I51: 0 | J51: 0 | K51: 0 | L51: 0 | M51: 0 | N51: 0 | O51: 0 | P51: 0 | Q51: 0 | R51: 0 | S51: 265 | T51: 0 | U51: 0 | V51: 0 | W51: 0
A52: 1227306 | B52: PBA-파워V2- 아세이(CHPI-620L) | C52: 합계 | D52: 270 | E52: 383 | F52: 483 | G52: 64 | H52: 0 | I52: 0 | J52: 0 | K52: 0 | L52: 350 | M52: 450 | N52: 0 | O52: 0 | P52: 0 | Q52: 1000 | R52: 0 | S52: 0 | T52: 0 | U52: 0 | V52: 0 | W52: 0
A53: 1227359 | B53: PBA-파워- 아세이(CHPI-620L) | C53: 합계 | D53: 0 | E53: 0 | F53: 0 | G53: 0 | H53: 0 | I53: 0 | J53: 0 | K53: 0 | L53: 0 | M53: 20 | N53: 0 | O53: 0 | P53: 0 | Q53: 0 | R53: 0 | S53: 0 | T53: 0 | U53: 0 | V53: 0 | W53: 0
A54: 1231090 | B54: PBA-SMPS(CHP-5700R) | C54: 합계 | D54: 0 | E54: 0 | F54: 210 | G54: 0 | H54: 0 | I54: 0 | J54: 0 | K54: 150 | L54: 0 | M54: 0 | N54: 0 | O54: 0 | P54: 0 | Q54: 0 | R54: 150 | S54: 0 | T54: 0 | U54: 0 | V54: 0 | W54: 0
A55: 1229776 | B55: PBA-필터(CHP-5700R) | C55: 합계 | D55: 0 | E55: 0 | F55: 210 | G55: 0 | H55: 0 | I55: 0 | J55: 0 | K55: 150 | L55: 0 | M55: 0 | N55: 0 | O55: 0 | P55: 0 | Q55: 0 | R55: 150 | S55: 0 | T55: 0 | U55: 0 | V55: 0 | W55: 0
A56: 1225464 | B56: PBA-파워- 아세이(AP-1516D) | C56: 합계 | D56: 0 | E56: 0 | F56: 0 | G56: 175 | H56: 0 | I56: 0 | J56: 25 | K56: 0 | L56: 0 | M56: 0 | N56: 0 | O56: 0 | P56: 0 | Q56: 1312 | R56: 1512 | S56: 0 | T56: 0 | U56: 0 | V56: 0 | W56: 0
A57: 1229088 | B57: PBA-파워- 아세이(AP-3018B) | C57: 합계 | D57: 0 | E57: 0 | F57: 0 | G57: 0 | H57: 0 | I57: 0 | J57: 150 | K57: 0 | L57: 0 | M57: 0 | N57: 0 | O57: 0 | P57: 0 | Q57: 0 | R57: 0 | S57: 0 | T57: 0 | U57: 0 | V57: 0 | W57: 0
A58: 1231860 | B58: PBA-SMPS- 아세이(CPSI-8510L) | C58: 합계 | D58: 0 | E58: 0 | F58: 0 | G58: 0 | H58: 0 | I58: 0 | J58: 0 | K58: 100 | L58: 0 | M58: 0 | N58: 0 | O58: 0 | P58: 0 | Q58: 0 | R58: 0 | S58: 0 | T58: 0 | U58: 0 | V58: 0 | W58: 0
A59: 1231578 | B59: PBA-SMPS- 아세이(CHP-6200N) | C59: 합계 | D59: 0 | E59: 0 | F59: 0 | G59: 0 | H59: 0 | I59: 0 | J59: 0 | K59: 0 | L59: 400 | M59: 0 | N59: 0 | O59: 0 | P59: 0 | Q59: 0 | R59: 0 | S59: 0 | T59: 0 | U59: 0 | V59: 0 | W59: 0
A60: 1234222 | B60: PBA-파워- 아세이(AP-1520D_JP) | C60: 합계 | D60: 0 | E60: 0 | F60: 0 | G60: 0 | H60: 0 | I60: 0 | J60: 0 | K60: 0 | L60: 0 | M60: 378 | N60: 402 | O60: 0 | P60: 0 | Q60: 0 | R60: 0 | S60: 0 | T60: 0 | U60: 0 | V60: 0 | W60: 0
... A84: 1238092 | B84: PBA-SMPS- 아세이(CHP-3140N_BG,싱가포르향) | C84: 합계 | D84: 0 | E84: 0 | F84: 11 | G84: 0 | H84: 0 | I84: 0 | J84: 0 | K84: 0 | L84: 0 | M84: 0 | N84: 0 | O84: 0 | P84: 0 | Q84: 0 | R84: 0 | S84: 0 | T84: 0 | U84: 70 | V84: 0 | W84: 0

Sheet 0702 RTPF
A1: 품번 | B1: 품명 | C1: L/T(D) | D1: 구분 | E1: 07/06(일) | F1: 07/07(월) | G1: 07/08(화) | H1: 07/09(수) | I1: 07/10(목) | J1: 07/11(금) | K1: 07/12(토) | L1: 07/13(일) | M1: 07/14(월) | N1: 07/15(화) | O1: 07/16(수) | P1: 07/17(목) | Q1: 07/18(금) | R1: 07/19(토) | S1: 30W | T1: 31W | U1: 32W | V1: 33W | W1: 34W | X1: 35W | Y1: 36W | Z1: 37W | AA1: 38W | AB1: 39W
A2: 1226384 | B2: PBA-- 아세이(S1400-EW) | C2: 42 | D2: RTP/RTF | E2: 0 | F2: 0 | G2: 0 | H2: 0 | I2: 0 | J2: 0 | K2: 0 | L2: 0 | M2: 0 | N2: 0 | O2: 0 | P2: 0 | Q2: 0 | R2: 0 | S2: 0 | T2: 860 | U2: 1600 | V2: 0 | W2: 0 | X2: 300 | Y2: 0 | Z2: 0 | AA2: 0 | AB2: 600
D3: 응답수량 | E3: 0 | F3: 0 | G3: 0 | H3: 0 | I3: 0 | J3: 0 | K3: 0 | L3: 0 | M3: 0 | N3: 0 | O3: 0 | P3: 0 | Q3: 0 | R3: 0 | S3: 0 | T3: 860 | U3: 1600 | V3: 0 | W3: 0 | X3: 300 | Y3: 0 | Z3: 0 | AA3: 0 | AB3: 600
D4: Date&Qty 변경 | E4: 0 | F4: 0 | G4: 0 | H4: 0 | I4: 0 | J4: 0 | K4: 0 | L4: 0 | M4: 0 | N4: 0 | O4: 0 | P4: 0 | Q4: 0 | R4: 0 | S4: 0 | T4: 0 | U4: 0 | V4: 0 | W4: 0 | X4: 0 | Y4: 0 | Z4: 0 | AA4: 0 | AB4: 0
A5: 1226388 | B5: PBA-SMPS- 아세이(S1400-EW) | C5: 42 | D5: RTP/RTF | E5: 0 | F5: 0 | G5: 0 | H5: 0 | I5: 0 | J5: 0 | K5: 0 | L5: 0 | M5: 0 | N5: 0 | O5: 0 | P5: 0 | Q5: 0 | R5: 0 | S5: 0 | T5: 860 | U5: 1600 | V5: 0 | W5: 0 | X5: 300 | Y5: 0 | Z5: 0 | AA5: 0 | AB5: 600
D6: 응답수량 | E6: 0 | F6: 0 | G6: 0 | H6: 0 | I6: 0 | J6: 0 | K6: 0 | L6: 0 | M6: 0 | N6: 0 | O6: 0 | P6: 0 | Q6: 0 | R6: 0 | S6: 0 | T6: 860 | U6: 1600 | V6: 0 | W6: 0 | X6: 300 | Y6: 0 | Z6: 0 | AA6: 0 | AB6: 600
D7: Date&Qty 변경 | E7: 0 | F7: 0 | G7: 0 | H7: 0 | I7: 0 | J7: 0 | K7: 0 | L7: 0 | M7: 0 | N7: 0 | O7: 0 | P7: 0 | Q7: 0 | R7: 0 | S7: 0 | T7: 0 | U7: 0 | V7: 0 | W7: 0 | X7: 0 | Y7: 0 | Z7: 0 | AA7: 0 | AB7: 0
A8: 1229673 | B8: PBA-TOTAL- 아세이(BA20-D) | C8: 42 | D8: RTP/RTF | E8: 0 | F8: 0 | G8: 200 | H8: 228 | I8: 0 | J8: 172 | K8: 0 | L8: 0 | M8: 100 | N8: 100 | O8: 100 | P8: 0 | Q8: 0 | R8: 0 | S8: 0 | T8: 0 | U8: 600 | V8: 0 | W8: 200 | X8: 0 | Y8: 0 | Z8: 500 | AA8: 500 | AB8: 0
D9: 응답수량 | E9: 0 | F9: 0 | G9: 200 | H9: 228 | I9: 0 | J9: 172 | K9: 0 | L9: 0 | M9: 100 | N9: 100 | O9: 100 | P9: 0 | Q9: 0 | R9: 0 | S9: 0 | T9: 0 | U9: 600 | V9: 0 | W9: 200 | X9: 0 | Y9: 0 | Z9: 500 | AA9: 500 | AB9: 0
D10: Date&Qty 변경 | E10: 0 | F10: 0 | G10: 0 | H10: 0 | I10: 0 | J10: 0 | K10: 0 | L10: 0 | M10: 0 | N10: 0 | O10: 0 | P10: 0 | Q10: 0 | R10: 0 | S10: 0 | T10: 0 | U10: 0 | V10: 0 | W10: 0 | X10: 0 | Y10: 0 | Z10: 0 | AA10: 0 | AB10: 0
A11: 1230692 | B11: PBA-SMPS- 아세이(CHP-5710L) | C11: 42 | D11: RTP/RTF | E11: 0 | F11: 0 | G11: 0 | H11: 0 | I11: 0 | J11: 0 | K11: 0 | L11: 0 | M11: 0 | N11: 0 | O11: 0 | P11: 0 | Q11: 0 | R11: 0 | S11: 1840 | T11: 0 | U11: 3100 | V11: 2500 | W11: 0 | X11: 0 | Y11: 0 | Z11: 1500 | AA11: 1400 | AB11: 0
D12: 응답수량 | E12: 0 | F12: 0 | G12: 0 | H12: 0 | I12: 0 | J12: 0 | K12: 0 | L12: 0 | M12: 0 | N12: 0 | O12: 0 | P12: 0 | Q12: 0 | R12: 0 | S12: 1840 | T12: 0 | U12: 3100 | V12: 2500 | W12: 0 | X12: 0 | Y12: 0 | Z12: 1500 | AA12: 1400 | AB12: 0
D13: Date&Qty 변경 | E13: 0 | F13: 0 | G13: 0 | H13: 0 | I13: 0 | J13: 0 | K13: 0 | L13: 0 | M13: 0 | N13: 0 | O13: 0 | P13: 0 | Q13: 0 | R13: 0 | S13: 0 | T13: 0 | U13: 0 | V13: 0 | W13: 0 | X13: 0 | Y13: 0 | Z13: 0 | AA13: 0 | AB13: 0
A14: 1230696 | B14: PBA-SMPS- 아세이(CHP-5710R) | C14: 42 | D14: RTP/RTF | E14: 0 | F14: 0 | G14: 0 | H14: 0 | I14: 0 | J14: 0 | K14: 0 | L14: 0 | M14: 0 | N14: 0 | O14: 0 | P14: 0 | Q14: 0 | R14: 0 | S14: 168 | T14: 0 | U14: 0 | V14: 0 | W14: 0 | X14: 0 | Y14: 500 | Z14: 0 | AA14: 0 | AB14: 0
D15: 응답수량 | E15: 0 | F15: 0 | G15: 0 | H15: 0 | I15: 0 | J15: 0 | K15: 0 | L15: 0 | M15: 0 | N15: 0 | O15: 0 | P15: 0 | Q15: 0 | R15: 0 | S15: 168 | T15: 0 | U15: 0 | V15: 0 | W15: 0 | X15: 0 | Y15: 500 | Z15: 0 | AA15: 0 | AB15: 0
D16: Date&Qty 변경 | E16: 0 | F16: 0 | G16: 0 | H16: 0 | I16: 0 | J16: 0 | K16: 0 | L16: 0 | M16: 0 | N16: 0 | O16: 0 | P16: 0 | Q16: 0 | R16: 0 | S16: 0 | T16: 0 | U16: 0 | V16: 0 | W16: 0 | X16: 0 | Y16: 0 | Z16: 0 | AA16: 0 | AB16: 0
A17: 1230854 | B17: PBA-토탈- 아세이(BA34-A) | C17: 42 | D17: RTP/RTF | E17: 0 | F17: 150 | G17: 0 | H17: 0 | I17: 0 | J17: 0 | K17: 0 | L17: 0 | M17: 0 | N17: 0 | O17: 0 | P17: 0 | Q17: 0 | R17: 0 | S17: 0 | T17: 0 | U17: 0 | V17: 250 | W17: 0 | X17: 0 | Y17: 0 | Z17: 200 | AA17: 0 | AB17: 0
D18: 응답수량 | E18: 0 | F18: 150 | G18: 0 | H18: 0 | I18: 0 | J18: 0 | K18: 0 | L18: 0 | M18: 0 | N18: 0 | O18: 0 | P18: 0 | Q18: 0 | R18: 0 | S18: 0 | T18: 0 | U18: 0 | V18: 250 | W18: 0 | X18: 0 | Y18: 0 | Z18: 200 | AA18: 0 | AB18: 0
D19: Date&Qty 변경 | E19: 0 | F19: 0 | G19: 0 | H19: 0 | I19: 0 | J19: 0 | K19: 0 | L19: 0 | M19: 0 | N19: 0 | O19: 0 | P19: 0 | Q19: 0 | R19: 0 | S19: 0 | T19: 0 | U19: 0 | V19: 0 | W19: 0 | X19: 0 | Y19: 0 | Z19: 0 | AA19: 0 | AB19: 0
A20: 1231202 | B20: PBA-파워- 아세이(AP-1019D) | C20: 42 | D20: RTP/RTF | E20: 0 | F20: 0 | G20: 0 | H20: 0 | I20: 0 | J20: 250 | K20: 0 | L20: 0 | M20: 50 | N20: 0 | O20: 0 | P20: 0 | Q20: 0 | R20: 0 | S20: 0 | T20: 0 | U20: 0 | V20: 0 | W20: 0 | X20: 0 | Y20: 0 | Z20: 0 | AA20: 250 | AB20: 0
D21: 응답수량 | E21: 0 | F21: 0 | G21: 0 | H21: 0 | I21: 0 | J21: 250 | K21: 0 | L21: 0 | M21: 50 | N21: 0 | O21: 0 | P21: 0 | Q21: 0 | R21: 0 | S21: 0 | T21: 0 | U21: 0 | V21: 0 | W21: 0 | X21: 0 | Y21: 0 | Z21: 0 | AA21: 250 | AB21: 0
D22: Date&Qty 변경 | E22: 0 | F22: 0 | G22: 0 | H22: 0 | I22: 0 | J22: 0 | K22: 0 | L22: 0 | M22: 0 | N22: 0 | O22: 0 | P22: 0 | Q22: 0 | R22: 0 | S22: 0 | T22: 0 | U22: 0 | V22: 0 | W22: 0 | X22: 0 | Y22: 0 | Z22: 0 | AA22: 0 | AB22: 0
A23: 1231898 | B23: PBA-컨트롤- 아세이(BA36-A) | C23: 42 | D23: RTP/RTF | E23: 0 | F23: 0 | G23: 740 | H23: 580 | I23: 480 | J23: 512 | K23: 0 | L23: 0 | M23: 0 | N23: 0 | O23: 400 | P23: 400 | Q23: 400 | R23: 0 | S23: 0 | T23: 0 | U23: 0 | V23: 0 | W23: 0 | X23: 0 | Y23: 0 | Z23: 0 | AA23: 0 | AB23: 0
D24: 응답수량 | E24: 0 | F24: 0 | G24: 740 | H24: 580 | I24: 480 | J24: 512 | K24: 0 | L24: 0 | M24: 0 | N24: 0 | O24: 400 | P24: 400 | Q24: 400 | R24: 0 | S24: 0 | T24: 0 | U24: 0 | V24: 0 | W24: 0 | X24: 0 | Y24: 0 | Z24: 0 | AA24: 0 | AB24: 0
D25: Date&Qty 변경 | E25: 0 | F25: 0 | G25: 0 | H25: 0 | I25: 0 | J25: 0 | K25: 0 | L25: 0 | M25: 0 | N25: 0 | O25: 0 | P25: 0 | Q25: 0 | R25: 0 | S25: 0 | T25: 0 | U25: 0 | V25: 0 | W25: 0 | X25: 0 | Y25: 0 | Z25: 0 | AA25: 0 | AB25: 0
A26: 1232693 | B26: PBA-플라즈마파워유닛- 아세이(AP-1520C ) | C26: 21 | D26: RTP/RTF | E26: 0 | F26: 76 | G26: 0 | H26: 0 | I26: 0 | J26: 0 | K26: 0 | L26: 0 | M26: 0 | N26: 0 | O26: 0 | P26: 0 | Q26: 0 | R26: 0 | S26: 0 | T26: 198 | U26: 1491 | V26: 0 | W26: 0 | X26: 0 | Y26: 630 | Z26: 1008 | AA26: 0 | AB26: 0
D27: 응답수량 | E27: 0 | F27: 76 | G27: 0 | H27: 0 | I27: 0 | J27: 0 | K27: 0 | L27: 0 | M27: 0 | N27: 0 | O27: 0 | P27: 0 | Q27: 0 | R27: 0 | S27: 0 | T27: 198 | U27: 1491 | V27: 0 | W27: 0 | X27: 0 | Y27: 630 | Z27: 1008 | AA27: 0 | AB27: 0
D28: Date&Qty 변경 | E28: 0 | F28: 0 | G28: 0 | H28: 0 | I28: 0 | J28: 0 | K28: 0 | L28: 0 | M28: 0 | N28: 0 | O28: 0 | P28: 0 | Q28: 0 | R28: 0 | S28: 0 | T28: 0 | U28: 0 | V28: 0 | W28: 0 | X28: 0 | Y28: 0 | Z28: 0 | AA28: 0 | AB28: 0
A29: 1233025 | B29: PBA-메인- 아세이(AP-1520C) | C29: 21 | D29: RTP/RTF | E29: 0 | F29: 76 | G29: 0 | H29: 0 | I29: 0 | J29: 0 | K29: 0 | L29: 0 | M29: 0 | N29: 0 | O29: 0 | P29: 0 | Q29: 0 | R29: 0 | S29: 0 | T29: 198 | U29: 1491 | V29: 0 | W29: 0 | X29: 0 | Y29: 630 | Z29: 1008 | AA29: 0 | AB29: 0
D30: 응답수량 | E30: 0 | F30: 76 | G30: 0 | H30: 0 | I30: 0 | J30: 0 | K30: 0 | L30: 0 | M30: 0 | N30: 0 | O30: 0 | P30: 0 | Q30: 0 | R30: 0 | S30: 0 | T30: 198 | U30: 1491 | V30: 0 | W30: 0 | X30: 0 | Y30: 630 | Z30: 1008 | AA30: 0 | AB30: 0
D31: Date&Qty 변경 | E31: 0 | F31: 0 | G31: 0 | H31: 0 | I31: 0 | J31: 0 | K31: 0 | L31: 0 | M31: 0 | N31: 0 | O31: 0 | P31: 0 | Q31: 0 | R31: 0 | S31: 0 | T31: 0 | U31: 0 | V31: 0 | W31: 0 | X31: 0 | Y31: 0 | Z31: 0 | AA31: 0 | AB31: 0
A32: 1233492 | B32: PBA-인버터(AD-1221E) | C32: 21 | D32: RTP/RTF | E32: 0 | F32: 0 | G32: 0 | H32: 0 | I32: 538 | J32: 558 | K32: 0 | L32: 0 | M32: 704 | N32: 778 | O32: 168 | P32: 0 | Q32: 0 | R32: 0 | S32: 1330 | T32: 0 | U32: 1500 | V32: 1300 | W32: 1000 | X32: 0 | Y32: 500 | Z32: 900 | AA32: 700 | AB32: 0
D33: 응답수량 | E33: 0 | F33: 0 | G33: 0 | H33: 0 | I33: 538 | J33: 558 | K33: 0 | L33: 0 | M33: 704 | N33: 778 | O33: 168 | P33: 0 | Q33: 0 | R33: 0 | S33: 1330 | T33: 0 | U33: 1500 | V33: 1300 | W33: 1000 | X33: 0 | Y33: 500 | Z33: 900 | AA33: 700 | AB33: 0
D34: Date&Qty 변경 | E34: 0 | F34: 0 | G34: 0 | H34: 0 | I34: 0 | J34: 0 | K34: 0 | L34: 0 | M34: 0 | N34: 0 | O34: 0 | P34: 0 | Q34: 0 | R34: 0 | S34: 0 | T34: 0 | U34: 0 | V34: 0 | W34: 0 | X34: 0 | Y34: 0 | Z34: 0 | AA34: 0 | AB34: 0
A35: 1233498 | B35: PBA-파워- 아세이(AD-1221E) | C35: 21 | D35: RTP/RTF | E35: 0 | F35: 0 | G35: 0 | H35: 0 | I35: 538 | J35: 558 | K35: 0 | L35: 0 | M35: 704 | N35: 778 | O35: 168 | P35: 0 | Q35: 0 | R35: 0 | S35: 1330 | T35: 0 | U35: 1500 | V35: 1300 | W35: 1000 | X35: 0 | Y35: 500 | Z35: 900 | AA35: 700 | AB35: 0
D36: 응답수량 | E36: 0 | F36: 0 | G36: 0 | H36: 0 | I36: 538 | J36: 558 | K36: 0 | L36: 0 | M36: 704 | N36: 778 | O36: 168 | P36: 0 | Q36: 0 | R36: 0 | S36: 1330 | T36: 0 | U36: 1500 | V36: 1300 | W36: 1000 | X36: 0 | Y36: 500 | Z36: 900 | AA36: 700 | AB36: 0
D37: Date&Qty 변경 | E37: 0 | F37: 0 | G37: 0 | H37: 0 | I37: 0 | J37: 0 | K37: 0 | L37: 0 | M37: 0 | N37: 0 | O37: 0 | P37: 0 | Q37: 0 | R37: 0 | S37: 0 | T37: 0 | U37: 0 | V37: 0 | W37: 0 | X37: 0 | Y37: 0 | Z37: 0 | AA37: 0 | AB37: 0
